/home/agazade/.conda/envs/main/lib/python3.7/site-packages/tensorflow/python/framework/dtypes.py:516: FutureWarning: Passing (type, 1) or '1type' as a synonym of type is deprecated; in a future version of numpy, it will be understood as (type, (1,)) / '(1,)type'.
  _np_qint8 = np.dtype([("qint8", np.int8, 1)])
/home/agazade/.conda/envs/main/lib/python3.7/site-packages/tensorflow/python/framework/dtypes.py:517: FutureWarning: Passing (type, 1) or '1type' as a synonym of type is deprecated; in a future version of numpy, it will be understood as (type, (1,)) / '(1,)type'.
  _np_quint8 = np.dtype([("quint8", np.uint8, 1)])
/home/agazade/.conda/envs/main/lib/python3.7/site-packages/tensorflow/python/framework/dtypes.py:518: FutureWarning: Passing (type, 1) or '1type' as a synonym of type is deprecated; in a future version of numpy, it will be understood as (type, (1,)) / '(1,)type'.
  _np_qint16 = np.dtype([("qint16", np.int16, 1)])
/home/agazade/.conda/envs/main/lib/python3.7/site-packages/tensorflow/python/framework/dtypes.py:519: FutureWarning: Passing (type, 1) or '1type' as a synonym of type is deprecated; in a future version of numpy, it will be understood as (type, (1,)) / '(1,)type'.
  _np_quint16 = np.dtype([("quint16", np.uint16, 1)])
/home/agazade/.conda/envs/main/lib/python3.7/site-packages/tensorflow/python/framework/dtypes.py:520: FutureWarning: Passing (type, 1) or '1type' as a synonym of type is deprecated; in a future version of numpy, it will be understood as (type, (1,)) / '(1,)type'.
  _np_qint32 = np.dtype([("qint32", np.int32, 1)])
/home/agazade/.conda/envs/main/lib/python3.7/site-packages/tensorflow/python/framework/dtypes.py:525: FutureWarning: Passing (type, 1) or '1type' as a synonym of type is deprecated; in a future version of numpy, it will be understood as (type, (1,)) / '(1,)type'.
  np_resource = np.dtype([("resource", np.ubyte, 1)])
/home/agazade/.conda/envs/main/lib/python3.7/site-packages/tensorboard/compat/tensorflow_stub/dtypes.py:541: FutureWarning: Passing (type, 1) or '1type' as a synonym of type is deprecated; in a future version of numpy, it will be understood as (type, (1,)) / '(1,)type'.
  _np_qint8 = np.dtype([("qint8", np.int8, 1)])
/home/agazade/.conda/envs/main/lib/python3.7/site-packages/tensorboard/compat/tensorflow_stub/dtypes.py:542: FutureWarning: Passing (type, 1) or '1type' as a synonym of type is deprecated; in a future version of numpy, it will be understood as (type, (1,)) / '(1,)type'.
  _np_quint8 = np.dtype([("quint8", np.uint8, 1)])
/home/agazade/.conda/envs/main/lib/python3.7/site-packages/tensorboard/compat/tensorflow_stub/dtypes.py:543: FutureWarning: Passing (type, 1) or '1type' as a synonym of type is deprecated; in a future version of numpy, it will be understood as (type, (1,)) / '(1,)type'.
  _np_qint16 = np.dtype([("qint16", np.int16, 1)])
/home/agazade/.conda/envs/main/lib/python3.7/site-packages/tensorboard/compat/tensorflow_stub/dtypes.py:544: FutureWarning: Passing (type, 1) or '1type' as a synonym of type is deprecated; in a future version of numpy, it will be understood as (type, (1,)) / '(1,)type'.
  _np_quint16 = np.dtype([("quint16", np.uint16, 1)])
/home/agazade/.conda/envs/main/lib/python3.7/site-packages/tensorboard/compat/tensorflow_stub/dtypes.py:545: FutureWarning: Passing (type, 1) or '1type' as a synonym of type is deprecated; in a future version of numpy, it will be understood as (type, (1,)) / '(1,)type'.
  _np_qint32 = np.dtype([("qint32", np.int32, 1)])
/home/agazade/.conda/envs/main/lib/python3.7/site-packages/tensorboard/compat/tensorflow_stub/dtypes.py:550: FutureWarning: Passing (type, 1) or '1type' as a synonym of type is deprecated; in a future version of numpy, it will be understood as (type, (1,)) / '(1,)type'.
  np_resource = np.dtype([("resource", np.ubyte, 1)])
WARNING:tensorflow:From /opt/agazade/data_science/training/code/mobile_detection/ssd_mobilenet/ssd_mobilenet/slim/nets/mobilenet/mobilenet.py:399: The name tf.nn.avg_pool is deprecated. Please use tf.nn.avg_pool2d instead.

WARNING:tensorflow:From ssd_mobilenet/object_detection/legacy/eval.py:57: The name tf.logging.set_verbosity is deprecated. Please use tf.compat.v1.logging.set_verbosity instead.

WARNING:tensorflow:From ssd_mobilenet/object_detection/legacy/eval.py:57: The name tf.logging.INFO is deprecated. Please use tf.compat.v1.logging.INFO instead.

WARNING:tensorflow:From ssd_mobilenet/object_detection/legacy/eval.py:143: The name tf.app.run is deprecated. Please use tf.compat.v1.app.run instead.

WARNING:tensorflow:From /home/agazade/.conda/envs/main/lib/python3.7/site-packages/absl/app.py:250: main (from __main__) is deprecated and will be removed in a future version.
Instructions for updating:
Use object_detection/model_main.py.
W0312 16:57:11.987717 139762821543680 deprecation.py:323] From /home/agazade/.conda/envs/main/lib/python3.7/site-packages/absl/app.py:250: main (from __main__) is deprecated and will be removed in a future version.
Instructions for updating:
Use object_detection/model_main.py.
WARNING:tensorflow:From ssd_mobilenet/object_detection/legacy/eval.py:88: The name tf.gfile.MakeDirs is deprecated. Please use tf.io.gfile.makedirs instead.

W0312 16:57:11.987820 139762821543680 deprecation_wrapper.py:119] From ssd_mobilenet/object_detection/legacy/eval.py:88: The name tf.gfile.MakeDirs is deprecated. Please use tf.io.gfile.makedirs instead.

WARNING:tensorflow:From /opt/agazade/data_science/training/code/mobile_detection/ssd_mobilenet/ssd_mobilenet/object_detection/utils/config_util.py:102: The name tf.gfile.GFile is deprecated. Please use tf.io.gfile.GFile instead.

W0312 16:57:11.988012 139762821543680 deprecation_wrapper.py:119] From /opt/agazade/data_science/training/code/mobile_detection/ssd_mobilenet/ssd_mobilenet/object_detection/utils/config_util.py:102: The name tf.gfile.GFile is deprecated. Please use tf.io.gfile.GFile instead.

WARNING:tensorflow:From ssd_mobilenet/object_detection/legacy/eval.py:92: The name tf.gfile.Copy is deprecated. Please use tf.io.gfile.copy instead.

W0312 16:57:11.990589 139762821543680 deprecation_wrapper.py:119] From ssd_mobilenet/object_detection/legacy/eval.py:92: The name tf.gfile.Copy is deprecated. Please use tf.io.gfile.copy instead.

WARNING:tensorflow:From /opt/agazade/data_science/training/code/mobile_detection/ssd_mobilenet/ssd_mobilenet/object_detection/data_decoders/tf_example_decoder.py:182: The name tf.FixedLenFeature is deprecated. Please use tf.io.FixedLenFeature instead.

W0312 16:57:11.991985 139762821543680 deprecation_wrapper.py:119] From /opt/agazade/data_science/training/code/mobile_detection/ssd_mobilenet/ssd_mobilenet/object_detection/data_decoders/tf_example_decoder.py:182: The name tf.FixedLenFeature is deprecated. Please use tf.io.FixedLenFeature instead.

WARNING:tensorflow:From /opt/agazade/data_science/training/code/mobile_detection/ssd_mobilenet/ssd_mobilenet/object_detection/data_decoders/tf_example_decoder.py:197: The name tf.VarLenFeature is deprecated. Please use tf.io.VarLenFeature instead.

W0312 16:57:11.992092 139762821543680 deprecation_wrapper.py:119] From /opt/agazade/data_science/training/code/mobile_detection/ssd_mobilenet/ssd_mobilenet/object_detection/data_decoders/tf_example_decoder.py:197: The name tf.VarLenFeature is deprecated. Please use tf.io.VarLenFeature instead.

WARNING:tensorflow:From /opt/agazade/data_science/training/code/mobile_detection/ssd_mobilenet/ssd_mobilenet/object_detection/builders/dataset_builder.py:64: The name tf.gfile.Glob is deprecated. Please use tf.io.gfile.glob instead.

W0312 16:57:12.000059 139762821543680 deprecation_wrapper.py:119] From /opt/agazade/data_science/training/code/mobile_detection/ssd_mobilenet/ssd_mobilenet/object_detection/builders/dataset_builder.py:64: The name tf.gfile.Glob is deprecated. Please use tf.io.gfile.glob instead.

WARNING:tensorflow:From /opt/agazade/data_science/training/code/mobile_detection/ssd_mobilenet/ssd_mobilenet/object_detection/builders/dataset_builder.py:71: The name tf.logging.warning is deprecated. Please use tf.compat.v1.logging.warning instead.

W0312 16:57:12.000882 139762821543680 deprecation_wrapper.py:119] From /opt/agazade/data_science/training/code/mobile_detection/ssd_mobilenet/ssd_mobilenet/object_detection/builders/dataset_builder.py:71: The name tf.logging.warning is deprecated. Please use tf.compat.v1.logging.warning instead.

WARNING:tensorflow:num_readers has been reduced to 1 to match input file shards.
W0312 16:57:12.000955 139762821543680 dataset_builder.py:72] num_readers has been reduced to 1 to match input file shards.
WARNING:tensorflow:From /opt/agazade/data_science/training/code/mobile_detection/ssd_mobilenet/ssd_mobilenet/object_detection/builders/dataset_builder.py:86: parallel_interleave (from tensorflow.contrib.data.python.ops.interleave_ops) is deprecated and will be removed in a future version.
Instructions for updating:
Use `tf.data.experimental.parallel_interleave(...)`.
W0312 16:57:12.002801 139762821543680 deprecation.py:323] From /opt/agazade/data_science/training/code/mobile_detection/ssd_mobilenet/ssd_mobilenet/object_detection/builders/dataset_builder.py:86: parallel_interleave (from tensorflow.contrib.data.python.ops.interleave_ops) is deprecated and will be removed in a future version.
Instructions for updating:
Use `tf.data.experimental.parallel_interleave(...)`.
WARNING:tensorflow:From /home/agazade/.conda/envs/main/lib/python3.7/site-packages/tensorflow/contrib/data/python/ops/interleave_ops.py:77: parallel_interleave (from tensorflow.python.data.experimental.ops.interleave_ops) is deprecated and will be removed in a future version.
Instructions for updating:
Use `tf.data.Dataset.interleave(map_func, cycle_length, block_length, num_parallel_calls=tf.data.experimental.AUTOTUNE)` instead. If sloppy execution is desired, use `tf.data.Options.experimental_determinstic`.
W0312 16:57:12.002874 139762821543680 deprecation.py:323] From /home/agazade/.conda/envs/main/lib/python3.7/site-packages/tensorflow/contrib/data/python/ops/interleave_ops.py:77: parallel_interleave (from tensorflow.python.data.experimental.ops.interleave_ops) is deprecated and will be removed in a future version.
Instructions for updating:
Use `tf.data.Dataset.interleave(map_func, cycle_length, block_length, num_parallel_calls=tf.data.experimental.AUTOTUNE)` instead. If sloppy execution is desired, use `tf.data.Options.experimental_determinstic`.
WARNING:tensorflow:From /opt/agazade/data_science/training/code/mobile_detection/ssd_mobilenet/ssd_mobilenet/object_detection/builders/dataset_builder.py:155: DatasetV1.map_with_legacy_function (from tensorflow.python.data.ops.dataset_ops) is deprecated and will be removed in a future version.
Instructions for updating:
Use `tf.data.Dataset.map()
W0312 16:57:12.015866 139762821543680 deprecation.py:323] From /opt/agazade/data_science/training/code/mobile_detection/ssd_mobilenet/ssd_mobilenet/object_detection/builders/dataset_builder.py:155: DatasetV1.map_with_legacy_function (from tensorflow.python.data.ops.dataset_ops) is deprecated and will be removed in a future version.
Instructions for updating:
Use `tf.data.Dataset.map()
WARNING:tensorflow:From /opt/agazade/data_science/training/code/mobile_detection/ssd_mobilenet/ssd_mobilenet/object_detection/builders/dataset_builder.py:43: DatasetV1.make_initializable_iterator (from tensorflow.python.data.ops.dataset_ops) is deprecated and will be removed in a future version.
Instructions for updating:
Use `for ... in dataset:` to iterate over a dataset. If using `tf.estimator`, return the `Dataset` object directly from your input function. As a last resort, you can use `tf.compat.v1.data.make_initializable_iterator(dataset)`.
W0312 16:57:12.123399 139762821543680 deprecation.py:323] From /opt/agazade/data_science/training/code/mobile_detection/ssd_mobilenet/ssd_mobilenet/object_detection/builders/dataset_builder.py:43: DatasetV1.make_initializable_iterator (from tensorflow.python.data.ops.dataset_ops) is deprecated and will be removed in a future version.
Instructions for updating:
Use `for ... in dataset:` to iterate over a dataset. If using `tf.estimator`, return the `Dataset` object directly from your input function. As a last resort, you can use `tf.compat.v1.data.make_initializable_iterator(dataset)`.
WARNING:tensorflow:From /opt/agazade/data_science/training/code/mobile_detection/ssd_mobilenet/ssd_mobilenet/object_detection/builders/dataset_builder.py:44: The name tf.add_to_collection is deprecated. Please use tf.compat.v1.add_to_collection instead.

W0312 16:57:12.175737 139762821543680 deprecation_wrapper.py:119] From /opt/agazade/data_science/training/code/mobile_detection/ssd_mobilenet/ssd_mobilenet/object_detection/builders/dataset_builder.py:44: The name tf.add_to_collection is deprecated. Please use tf.compat.v1.add_to_collection instead.

WARNING:tensorflow:From /opt/agazade/data_science/training/code/mobile_detection/ssd_mobilenet/ssd_mobilenet/object_detection/builders/dataset_builder.py:44: The name tf.GraphKeys is deprecated. Please use tf.compat.v1.GraphKeys instead.

W0312 16:57:12.175867 139762821543680 deprecation_wrapper.py:119] From /opt/agazade/data_science/training/code/mobile_detection/ssd_mobilenet/ssd_mobilenet/object_detection/builders/dataset_builder.py:44: The name tf.GraphKeys is deprecated. Please use tf.compat.v1.GraphKeys instead.

WARNING:tensorflow:From /opt/agazade/data_science/training/code/mobile_detection/ssd_mobilenet/ssd_mobilenet/object_detection/core/prefetcher.py:51: The name tf.PaddingFIFOQueue is deprecated. Please use tf.queue.PaddingFIFOQueue instead.

W0312 16:57:12.176964 139762821543680 deprecation_wrapper.py:119] From /opt/agazade/data_science/training/code/mobile_detection/ssd_mobilenet/ssd_mobilenet/object_detection/core/prefetcher.py:51: The name tf.PaddingFIFOQueue is deprecated. Please use tf.queue.PaddingFIFOQueue instead.

WARNING:tensorflow:From /opt/agazade/data_science/training/code/mobile_detection/ssd_mobilenet/ssd_mobilenet/object_detection/core/prefetcher.py:57: QueueRunner.__init__ (from tensorflow.python.training.queue_runner_impl) is deprecated and will be removed in a future version.
Instructions for updating:
To construct input pipelines, use the `tf.data` module.
W0312 16:57:12.178204 139762821543680 deprecation.py:323] From /opt/agazade/data_science/training/code/mobile_detection/ssd_mobilenet/ssd_mobilenet/object_detection/core/prefetcher.py:57: QueueRunner.__init__ (from tensorflow.python.training.queue_runner_impl) is deprecated and will be removed in a future version.
Instructions for updating:
To construct input pipelines, use the `tf.data` module.
WARNING:tensorflow:From /opt/agazade/data_science/training/code/mobile_detection/ssd_mobilenet/ssd_mobilenet/object_detection/core/prefetcher.py:57: add_queue_runner (from tensorflow.python.training.queue_runner_impl) is deprecated and will be removed in a future version.
Instructions for updating:
To construct input pipelines, use the `tf.data` module.
W0312 16:57:12.178788 139762821543680 deprecation.py:323] From /opt/agazade/data_science/training/code/mobile_detection/ssd_mobilenet/ssd_mobilenet/object_detection/core/prefetcher.py:57: add_queue_runner (from tensorflow.python.training.queue_runner_impl) is deprecated and will be removed in a future version.
Instructions for updating:
To construct input pipelines, use the `tf.data` module.
WARNING:tensorflow:From /opt/agazade/data_science/training/code/mobile_detection/ssd_mobilenet/ssd_mobilenet/object_detection/core/prefetcher.py:58: The name tf.summary.scalar is deprecated. Please use tf.compat.v1.summary.scalar instead.

W0312 16:57:12.178871 139762821543680 deprecation_wrapper.py:119] From /opt/agazade/data_science/training/code/mobile_detection/ssd_mobilenet/ssd_mobilenet/object_detection/core/prefetcher.py:58: The name tf.summary.scalar is deprecated. Please use tf.compat.v1.summary.scalar instead.

WARNING:tensorflow:From /opt/agazade/data_science/training/code/mobile_detection/ssd_mobilenet/ssd_mobilenet/object_detection/core/preprocessor.py:2937: The name tf.image.resize_images is deprecated. Please use tf.image.resize instead.

W0312 16:57:12.182892 139762821543680 deprecation_wrapper.py:119] From /opt/agazade/data_science/training/code/mobile_detection/ssd_mobilenet/ssd_mobilenet/object_detection/core/preprocessor.py:2937: The name tf.image.resize_images is deprecated. Please use tf.image.resize instead.

WARNING:tensorflow:Entity <bound method Conv.call of <tensorflow.python.layers.convolutional.Conv2D object at 0x7f1cae711e90>> could not be transformed and will be executed as-is. Please report this to the AutgoGraph team. When filing the bug, set the verbosity to 10 (on Linux, `export AUTOGRAPH_VERBOSITY=10`) and attach the full output. Cause: converting <bound method Conv.call of <tensorflow.python.layers.convolutional.Conv2D object at 0x7f1cae711e90>>: AssertionError: Bad argument number for Name: 3, expecting 4
W0312 16:57:12.256443 139762821543680 ag_logging.py:145] Entity <bound method Conv.call of <tensorflow.python.layers.convolutional.Conv2D object at 0x7f1cae711e90>> could not be transformed and will be executed as-is. Please report this to the AutgoGraph team. When filing the bug, set the verbosity to 10 (on Linux, `export AUTOGRAPH_VERBOSITY=10`) and attach the full output. Cause: converting <bound method Conv.call of <tensorflow.python.layers.convolutional.Conv2D object at 0x7f1cae711e90>>: AssertionError: Bad argument number for Name: 3, expecting 4
WARNING:tensorflow:Entity <bound method Conv.call of <tensorflow.python.layers.convolutional.Conv2D object at 0x7f1caf4714d0>> could not be transformed and will be executed as-is. Please report this to the AutgoGraph team. When filing the bug, set the verbosity to 10 (on Linux, `export AUTOGRAPH_VERBOSITY=10`) and attach the full output. Cause: converting <bound method Conv.call of <tensorflow.python.layers.convolutional.Conv2D object at 0x7f1caf4714d0>>: AssertionError: Bad argument number for Name: 3, expecting 4
W0312 16:57:12.434341 139762821543680 ag_logging.py:145] Entity <bound method Conv.call of <tensorflow.python.layers.convolutional.Conv2D object at 0x7f1caf4714d0>> could not be transformed and will be executed as-is. Please report this to the AutgoGraph team. When filing the bug, set the verbosity to 10 (on Linux, `export AUTOGRAPH_VERBOSITY=10`) and attach the full output. Cause: converting <bound method Conv.call of <tensorflow.python.layers.convolutional.Conv2D object at 0x7f1caf4714d0>>: AssertionError: Bad argument number for Name: 3, expecting 4
WARNING:tensorflow:Entity <bound method Conv.call of <tensorflow.python.layers.convolutional.Conv2D object at 0x7f1cae851c10>> could not be transformed and will be executed as-is. Please report this to the AutgoGraph team. When filing the bug, set the verbosity to 10 (on Linux, `export AUTOGRAPH_VERBOSITY=10`) and attach the full output. Cause: converting <bound method Conv.call of <tensorflow.python.layers.convolutional.Conv2D object at 0x7f1cae851c10>>: AssertionError: Bad argument number for Name: 3, expecting 4
W0312 16:57:12.550953 139762821543680 ag_logging.py:145] Entity <bound method Conv.call of <tensorflow.python.layers.convolutional.Conv2D object at 0x7f1cae851c10>> could not be transformed and will be executed as-is. Please report this to the AutgoGraph team. When filing the bug, set the verbosity to 10 (on Linux, `export AUTOGRAPH_VERBOSITY=10`) and attach the full output. Cause: converting <bound method Conv.call of <tensorflow.python.layers.convolutional.Conv2D object at 0x7f1cae851c10>>: AssertionError: Bad argument number for Name: 3, expecting 4
WARNING:tensorflow:Entity <bound method Conv.call of <tensorflow.python.layers.convolutional.Conv2D object at 0x7f1cae6d2fd0>> could not be transformed and will be executed as-is. Please report this to the AutgoGraph team. When filing the bug, set the verbosity to 10 (on Linux, `export AUTOGRAPH_VERBOSITY=10`) and attach the full output. Cause: converting <bound method Conv.call of <tensorflow.python.layers.convolutional.Conv2D object at 0x7f1cae6d2fd0>>: AssertionError: Bad argument number for Name: 3, expecting 4
W0312 16:57:12.715086 139762821543680 ag_logging.py:145] Entity <bound method Conv.call of <tensorflow.python.layers.convolutional.Conv2D object at 0x7f1cae6d2fd0>> could not be transformed and will be executed as-is. Please report this to the AutgoGraph team. When filing the bug, set the verbosity to 10 (on Linux, `export AUTOGRAPH_VERBOSITY=10`) and attach the full output. Cause: converting <bound method Conv.call of <tensorflow.python.layers.convolutional.Conv2D object at 0x7f1cae6d2fd0>>: AssertionError: Bad argument number for Name: 3, expecting 4
WARNING:tensorflow:Entity <bound method Conv.call of <tensorflow.python.layers.convolutional.Conv2D object at 0x7f1cae7db4d0>> could not be transformed and will be executed as-is. Please report this to the AutgoGraph team. When filing the bug, set the verbosity to 10 (on Linux, `export AUTOGRAPH_VERBOSITY=10`) and attach the full output. Cause: converting <bound method Conv.call of <tensorflow.python.layers.convolutional.Conv2D object at 0x7f1cae7db4d0>>: AssertionError: Bad argument number for Name: 3, expecting 4
W0312 16:57:12.843053 139762821543680 ag_logging.py:145] Entity <bound method Conv.call of <tensorflow.python.layers.convolutional.Conv2D object at 0x7f1cae7db4d0>> could not be transformed and will be executed as-is. Please report this to the AutgoGraph team. When filing the bug, set the verbosity to 10 (on Linux, `export AUTOGRAPH_VERBOSITY=10`) and attach the full output. Cause: converting <bound method Conv.call of <tensorflow.python.layers.convolutional.Conv2D object at 0x7f1cae7db4d0>>: AssertionError: Bad argument number for Name: 3, expecting 4
WARNING:tensorflow:Entity <bound method Conv.call of <tensorflow.python.layers.convolutional.Conv2D object at 0x7f1cae7db4d0>> could not be transformed and will be executed as-is. Please report this to the AutgoGraph team. When filing the bug, set the verbosity to 10 (on Linux, `export AUTOGRAPH_VERBOSITY=10`) and attach the full output. Cause: converting <bound method Conv.call of <tensorflow.python.layers.convolutional.Conv2D object at 0x7f1cae7db4d0>>: AssertionError: Bad argument number for Name: 3, expecting 4
W0312 16:57:13.004549 139762821543680 ag_logging.py:145] Entity <bound method Conv.call of <tensorflow.python.layers.convolutional.Conv2D object at 0x7f1cae7db4d0>> could not be transformed and will be executed as-is. Please report this to the AutgoGraph team. When filing the bug, set the verbosity to 10 (on Linux, `export AUTOGRAPH_VERBOSITY=10`) and attach the full output. Cause: converting <bound method Conv.call of <tensorflow.python.layers.convolutional.Conv2D object at 0x7f1cae7db4d0>>: AssertionError: Bad argument number for Name: 3, expecting 4
WARNING:tensorflow:Entity <bound method Conv.call of <tensorflow.python.layers.convolutional.Conv2D object at 0x7f1cae5dc610>> could not be transformed and will be executed as-is. Please report this to the AutgoGraph team. When filing the bug, set the verbosity to 10 (on Linux, `export AUTOGRAPH_VERBOSITY=10`) and attach the full output. Cause: converting <bound method Conv.call of <tensorflow.python.layers.convolutional.Conv2D object at 0x7f1cae5dc610>>: AssertionError: Bad argument number for Name: 3, expecting 4
W0312 16:57:13.141406 139762821543680 ag_logging.py:145] Entity <bound method Conv.call of <tensorflow.python.layers.convolutional.Conv2D object at 0x7f1cae5dc610>> could not be transformed and will be executed as-is. Please report this to the AutgoGraph team. When filing the bug, set the verbosity to 10 (on Linux, `export AUTOGRAPH_VERBOSITY=10`) and attach the full output. Cause: converting <bound method Conv.call of <tensorflow.python.layers.convolutional.Conv2D object at 0x7f1cae5dc610>>: AssertionError: Bad argument number for Name: 3, expecting 4
WARNING:tensorflow:Entity <bound method Conv.call of <tensorflow.python.layers.convolutional.Conv2D object at 0x7f1cae529890>> could not be transformed and will be executed as-is. Please report this to the AutgoGraph team. When filing the bug, set the verbosity to 10 (on Linux, `export AUTOGRAPH_VERBOSITY=10`) and attach the full output. Cause: converting <bound method Conv.call of <tensorflow.python.layers.convolutional.Conv2D object at 0x7f1cae529890>>: AssertionError: Bad argument number for Name: 3, expecting 4
W0312 16:57:13.306063 139762821543680 ag_logging.py:145] Entity <bound method Conv.call of <tensorflow.python.layers.convolutional.Conv2D object at 0x7f1cae529890>> could not be transformed and will be executed as-is. Please report this to the AutgoGraph team. When filing the bug, set the verbosity to 10 (on Linux, `export AUTOGRAPH_VERBOSITY=10`) and attach the full output. Cause: converting <bound method Conv.call of <tensorflow.python.layers.convolutional.Conv2D object at 0x7f1cae529890>>: AssertionError: Bad argument number for Name: 3, expecting 4
WARNING:tensorflow:Entity <bound method Conv.call of <tensorflow.python.layers.convolutional.Conv2D object at 0x7f1cae746210>> could not be transformed and will be executed as-is. Please report this to the AutgoGraph team. When filing the bug, set the verbosity to 10 (on Linux, `export AUTOGRAPH_VERBOSITY=10`) and attach the full output. Cause: converting <bound method Conv.call of <tensorflow.python.layers.convolutional.Conv2D object at 0x7f1cae746210>>: AssertionError: Bad argument number for Name: 3, expecting 4
W0312 16:57:13.392243 139762821543680 ag_logging.py:145] Entity <bound method Conv.call of <tensorflow.python.layers.convolutional.Conv2D object at 0x7f1cae746210>> could not be transformed and will be executed as-is. Please report this to the AutgoGraph team. When filing the bug, set the verbosity to 10 (on Linux, `export AUTOGRAPH_VERBOSITY=10`) and attach the full output. Cause: converting <bound method Conv.call of <tensorflow.python.layers.convolutional.Conv2D object at 0x7f1cae746210>>: AssertionError: Bad argument number for Name: 3, expecting 4
WARNING:tensorflow:Entity <bound method Conv.call of <tensorflow.python.layers.convolutional.Conv2D object at 0x7f1cae621510>> could not be transformed and will be executed as-is. Please report this to the AutgoGraph team. When filing the bug, set the verbosity to 10 (on Linux, `export AUTOGRAPH_VERBOSITY=10`) and attach the full output. Cause: converting <bound method Conv.call of <tensorflow.python.layers.convolutional.Conv2D object at 0x7f1cae621510>>: AssertionError: Bad argument number for Name: 3, expecting 4
W0312 16:57:13.441025 139762821543680 ag_logging.py:145] Entity <bound method Conv.call of <tensorflow.python.layers.convolutional.Conv2D object at 0x7f1cae621510>> could not be transformed and will be executed as-is. Please report this to the AutgoGraph team. When filing the bug, set the verbosity to 10 (on Linux, `export AUTOGRAPH_VERBOSITY=10`) and attach the full output. Cause: converting <bound method Conv.call of <tensorflow.python.layers.convolutional.Conv2D object at 0x7f1cae621510>>: AssertionError: Bad argument number for Name: 3, expecting 4
WARNING:tensorflow:Entity <bound method Conv.call of <tensorflow.python.layers.convolutional.Conv2D object at 0x7f1cae52e2d0>> could not be transformed and will be executed as-is. Please report this to the AutgoGraph team. When filing the bug, set the verbosity to 10 (on Linux, `export AUTOGRAPH_VERBOSITY=10`) and attach the full output. Cause: converting <bound method Conv.call of <tensorflow.python.layers.convolutional.Conv2D object at 0x7f1cae52e2d0>>: AssertionError: Bad argument number for Name: 3, expecting 4
W0312 16:57:13.497916 139762821543680 ag_logging.py:145] Entity <bound method Conv.call of <tensorflow.python.layers.convolutional.Conv2D object at 0x7f1cae52e2d0>> could not be transformed and will be executed as-is. Please report this to the AutgoGraph team. When filing the bug, set the verbosity to 10 (on Linux, `export AUTOGRAPH_VERBOSITY=10`) and attach the full output. Cause: converting <bound method Conv.call of <tensorflow.python.layers.convolutional.Conv2D object at 0x7f1cae52e2d0>>: AssertionError: Bad argument number for Name: 3, expecting 4
WARNING:tensorflow:Entity <bound method Conv.call of <tensorflow.python.layers.convolutional.Conv2D object at 0x7f1cae3c6ed0>> could not be transformed and will be executed as-is. Please report this to the AutgoGraph team. When filing the bug, set the verbosity to 10 (on Linux, `export AUTOGRAPH_VERBOSITY=10`) and attach the full output. Cause: converting <bound method Conv.call of <tensorflow.python.layers.convolutional.Conv2D object at 0x7f1cae3c6ed0>>: AssertionError: Bad argument number for Name: 3, expecting 4
W0312 16:57:13.575153 139762821543680 ag_logging.py:145] Entity <bound method Conv.call of <tensorflow.python.layers.convolutional.Conv2D object at 0x7f1cae3c6ed0>> could not be transformed and will be executed as-is. Please report this to the AutgoGraph team. When filing the bug, set the verbosity to 10 (on Linux, `export AUTOGRAPH_VERBOSITY=10`) and attach the full output. Cause: converting <bound method Conv.call of <tensorflow.python.layers.convolutional.Conv2D object at 0x7f1cae3c6ed0>>: AssertionError: Bad argument number for Name: 3, expecting 4
WARNING:tensorflow:Entity <bound method Conv.call of <tensorflow.python.layers.convolutional.Conv2D object at 0x7f1cae3e1b50>> could not be transformed and will be executed as-is. Please report this to the AutgoGraph team. When filing the bug, set the verbosity to 10 (on Linux, `export AUTOGRAPH_VERBOSITY=10`) and attach the full output. Cause: converting <bound method Conv.call of <tensorflow.python.layers.convolutional.Conv2D object at 0x7f1cae3e1b50>>: AssertionError: Bad argument number for Name: 3, expecting 4
W0312 16:57:13.625111 139762821543680 ag_logging.py:145] Entity <bound method Conv.call of <tensorflow.python.layers.convolutional.Conv2D object at 0x7f1cae3e1b50>> could not be transformed and will be executed as-is. Please report this to the AutgoGraph team. When filing the bug, set the verbosity to 10 (on Linux, `export AUTOGRAPH_VERBOSITY=10`) and attach the full output. Cause: converting <bound method Conv.call of <tensorflow.python.layers.convolutional.Conv2D object at 0x7f1cae3e1b50>>: AssertionError: Bad argument number for Name: 3, expecting 4
WARNING:tensorflow:Entity <bound method Conv.call of <tensorflow.python.layers.convolutional.Conv2D object at 0x7f1cae540690>> could not be transformed and will be executed as-is. Please report this to the AutgoGraph team. When filing the bug, set the verbosity to 10 (on Linux, `export AUTOGRAPH_VERBOSITY=10`) and attach the full output. Cause: converting <bound method Conv.call of <tensorflow.python.layers.convolutional.Conv2D object at 0x7f1cae540690>>: AssertionError: Bad argument number for Name: 3, expecting 4
W0312 16:57:13.673883 139762821543680 ag_logging.py:145] Entity <bound method Conv.call of <tensorflow.python.layers.convolutional.Conv2D object at 0x7f1cae540690>> could not be transformed and will be executed as-is. Please report this to the AutgoGraph team. When filing the bug, set the verbosity to 10 (on Linux, `export AUTOGRAPH_VERBOSITY=10`) and attach the full output. Cause: converting <bound method Conv.call of <tensorflow.python.layers.convolutional.Conv2D object at 0x7f1cae540690>>: AssertionError: Bad argument number for Name: 3, expecting 4
WARNING:tensorflow:Entity <bound method Conv.call of <tensorflow.python.layers.convolutional.Conv2D object at 0x7f1cae2a6b90>> could not be transformed and will be executed as-is. Please report this to the AutgoGraph team. When filing the bug, set the verbosity to 10 (on Linux, `export AUTOGRAPH_VERBOSITY=10`) and attach the full output. Cause: converting <bound method Conv.call of <tensorflow.python.layers.convolutional.Conv2D object at 0x7f1cae2a6b90>>: AssertionError: Bad argument number for Name: 3, expecting 4
W0312 16:57:13.731007 139762821543680 ag_logging.py:145] Entity <bound method Conv.call of <tensorflow.python.layers.convolutional.Conv2D object at 0x7f1cae2a6b90>> could not be transformed and will be executed as-is. Please report this to the AutgoGraph team. When filing the bug, set the verbosity to 10 (on Linux, `export AUTOGRAPH_VERBOSITY=10`) and attach the full output. Cause: converting <bound method Conv.call of <tensorflow.python.layers.convolutional.Conv2D object at 0x7f1cae2a6b90>>: AssertionError: Bad argument number for Name: 3, expecting 4
WARNING:tensorflow:Entity <bound method Conv.call of <tensorflow.python.layers.convolutional.Conv2D object at 0x7f1cae31dc10>> could not be transformed and will be executed as-is. Please report this to the AutgoGraph team. When filing the bug, set the verbosity to 10 (on Linux, `export AUTOGRAPH_VERBOSITY=10`) and attach the full output. Cause: converting <bound method Conv.call of <tensorflow.python.layers.convolutional.Conv2D object at 0x7f1cae31dc10>>: AssertionError: Bad argument number for Name: 3, expecting 4
W0312 16:57:13.808235 139762821543680 ag_logging.py:145] Entity <bound method Conv.call of <tensorflow.python.layers.convolutional.Conv2D object at 0x7f1cae31dc10>> could not be transformed and will be executed as-is. Please report this to the AutgoGraph team. When filing the bug, set the verbosity to 10 (on Linux, `export AUTOGRAPH_VERBOSITY=10`) and attach the full output. Cause: converting <bound method Conv.call of <tensorflow.python.layers.convolutional.Conv2D object at 0x7f1cae31dc10>>: AssertionError: Bad argument number for Name: 3, expecting 4
WARNING:tensorflow:Entity <bound method Conv.call of <tensorflow.python.layers.convolutional.Conv2D object at 0x7f1cae2c6710>> could not be transformed and will be executed as-is. Please report this to the AutgoGraph team. When filing the bug, set the verbosity to 10 (on Linux, `export AUTOGRAPH_VERBOSITY=10`) and attach the full output. Cause: converting <bound method Conv.call of <tensorflow.python.layers.convolutional.Conv2D object at 0x7f1cae2c6710>>: AssertionError: Bad argument number for Name: 3, expecting 4
W0312 16:57:13.908469 139762821543680 ag_logging.py:145] Entity <bound method Conv.call of <tensorflow.python.layers.convolutional.Conv2D object at 0x7f1cae2c6710>> could not be transformed and will be executed as-is. Please report this to the AutgoGraph team. When filing the bug, set the verbosity to 10 (on Linux, `export AUTOGRAPH_VERBOSITY=10`) and attach the full output. Cause: converting <bound method Conv.call of <tensorflow.python.layers.convolutional.Conv2D object at 0x7f1cae2c6710>>: AssertionError: Bad argument number for Name: 3, expecting 4
WARNING:tensorflow:Entity <bound method Conv.call of <tensorflow.python.layers.convolutional.Conv2D object at 0x7f1cae2afe90>> could not be transformed and will be executed as-is. Please report this to the AutgoGraph team. When filing the bug, set the verbosity to 10 (on Linux, `export AUTOGRAPH_VERBOSITY=10`) and attach the full output. Cause: converting <bound method Conv.call of <tensorflow.python.layers.convolutional.Conv2D object at 0x7f1cae2afe90>>: AssertionError: Bad argument number for Name: 3, expecting 4
W0312 16:57:14.014934 139762821543680 ag_logging.py:145] Entity <bound method Conv.call of <tensorflow.python.layers.convolutional.Conv2D object at 0x7f1cae2afe90>> could not be transformed and will be executed as-is. Please report this to the AutgoGraph team. When filing the bug, set the verbosity to 10 (on Linux, `export AUTOGRAPH_VERBOSITY=10`) and attach the full output. Cause: converting <bound method Conv.call of <tensorflow.python.layers.convolutional.Conv2D object at 0x7f1cae2afe90>>: AssertionError: Bad argument number for Name: 3, expecting 4
WARNING:tensorflow:Entity <bound method Conv.call of <tensorflow.python.layers.convolutional.Conv2D object at 0x7f1cae2c6910>> could not be transformed and will be executed as-is. Please report this to the AutgoGraph team. When filing the bug, set the verbosity to 10 (on Linux, `export AUTOGRAPH_VERBOSITY=10`) and attach the full output. Cause: converting <bound method Conv.call of <tensorflow.python.layers.convolutional.Conv2D object at 0x7f1cae2c6910>>: AssertionError: Bad argument number for Name: 3, expecting 4
W0312 16:57:14.148578 139762821543680 ag_logging.py:145] Entity <bound method Conv.call of <tensorflow.python.layers.convolutional.Conv2D object at 0x7f1cae2c6910>> could not be transformed and will be executed as-is. Please report this to the AutgoGraph team. When filing the bug, set the verbosity to 10 (on Linux, `export AUTOGRAPH_VERBOSITY=10`) and attach the full output. Cause: converting <bound method Conv.call of <tensorflow.python.layers.convolutional.Conv2D object at 0x7f1cae2c6910>>: AssertionError: Bad argument number for Name: 3, expecting 4
WARNING:tensorflow:Entity <bound method Conv.call of <tensorflow.python.layers.convolutional.Conv2D object at 0x7f1cae289a90>> could not be transformed and will be executed as-is. Please report this to the AutgoGraph team. When filing the bug, set the verbosity to 10 (on Linux, `export AUTOGRAPH_VERBOSITY=10`) and attach the full output. Cause: converting <bound method Conv.call of <tensorflow.python.layers.convolutional.Conv2D object at 0x7f1cae289a90>>: AssertionError: Bad argument number for Name: 3, expecting 4
W0312 16:57:14.308761 139762821543680 ag_logging.py:145] Entity <bound method Conv.call of <tensorflow.python.layers.convolutional.Conv2D object at 0x7f1cae289a90>> could not be transformed and will be executed as-is. Please report this to the AutgoGraph team. When filing the bug, set the verbosity to 10 (on Linux, `export AUTOGRAPH_VERBOSITY=10`) and attach the full output. Cause: converting <bound method Conv.call of <tensorflow.python.layers.convolutional.Conv2D object at 0x7f1cae289a90>>: AssertionError: Bad argument number for Name: 3, expecting 4
WARNING:tensorflow:Entity <bound method Conv.call of <tensorflow.python.layers.convolutional.Conv2D object at 0x7f1cae1410d0>> could not be transformed and will be executed as-is. Please report this to the AutgoGraph team. When filing the bug, set the verbosity to 10 (on Linux, `export AUTOGRAPH_VERBOSITY=10`) and attach the full output. Cause: converting <bound method Conv.call of <tensorflow.python.layers.convolutional.Conv2D object at 0x7f1cae1410d0>>: AssertionError: Bad argument number for Name: 3, expecting 4
W0312 16:57:14.435602 139762821543680 ag_logging.py:145] Entity <bound method Conv.call of <tensorflow.python.layers.convolutional.Conv2D object at 0x7f1cae1410d0>> could not be transformed and will be executed as-is. Please report this to the AutgoGraph team. When filing the bug, set the verbosity to 10 (on Linux, `export AUTOGRAPH_VERBOSITY=10`) and attach the full output. Cause: converting <bound method Conv.call of <tensorflow.python.layers.convolutional.Conv2D object at 0x7f1cae1410d0>>: AssertionError: Bad argument number for Name: 3, expecting 4
WARNING:tensorflow:Entity <bound method Conv.call of <tensorflow.python.layers.convolutional.Conv2D object at 0x7f1cae076550>> could not be transformed and will be executed as-is. Please report this to the AutgoGraph team. When filing the bug, set the verbosity to 10 (on Linux, `export AUTOGRAPH_VERBOSITY=10`) and attach the full output. Cause: converting <bound method Conv.call of <tensorflow.python.layers.convolutional.Conv2D object at 0x7f1cae076550>>: AssertionError: Bad argument number for Name: 3, expecting 4
W0312 16:57:14.901314 139762821543680 ag_logging.py:145] Entity <bound method Conv.call of <tensorflow.python.layers.convolutional.Conv2D object at 0x7f1cae076550>> could not be transformed and will be executed as-is. Please report this to the AutgoGraph team. When filing the bug, set the verbosity to 10 (on Linux, `export AUTOGRAPH_VERBOSITY=10`) and attach the full output. Cause: converting <bound method Conv.call of <tensorflow.python.layers.convolutional.Conv2D object at 0x7f1cae076550>>: AssertionError: Bad argument number for Name: 3, expecting 4
WARNING:tensorflow:Entity <bound method Conv.call of <tensorflow.python.layers.convolutional.Conv2D object at 0x7f1cae70e310>> could not be transformed and will be executed as-is. Please report this to the AutgoGraph team. When filing the bug, set the verbosity to 10 (on Linux, `export AUTOGRAPH_VERBOSITY=10`) and attach the full output. Cause: converting <bound method Conv.call of <tensorflow.python.layers.convolutional.Conv2D object at 0x7f1cae70e310>>: AssertionError: Bad argument number for Name: 3, expecting 4
W0312 16:57:15.025765 139762821543680 ag_logging.py:145] Entity <bound method Conv.call of <tensorflow.python.layers.convolutional.Conv2D object at 0x7f1cae70e310>> could not be transformed and will be executed as-is. Please report this to the AutgoGraph team. When filing the bug, set the verbosity to 10 (on Linux, `export AUTOGRAPH_VERBOSITY=10`) and attach the full output. Cause: converting <bound method Conv.call of <tensorflow.python.layers.convolutional.Conv2D object at 0x7f1cae70e310>>: AssertionError: Bad argument number for Name: 3, expecting 4
WARNING:tensorflow:Entity <bound method Conv.call of <tensorflow.python.layers.convolutional.Conv2D object at 0x7f1cae1486d0>> could not be transformed and will be executed as-is. Please report this to the AutgoGraph team. When filing the bug, set the verbosity to 10 (on Linux, `export AUTOGRAPH_VERBOSITY=10`) and attach the full output. Cause: converting <bound method Conv.call of <tensorflow.python.layers.convolutional.Conv2D object at 0x7f1cae1486d0>>: AssertionError: Bad argument number for Name: 3, expecting 4
W0312 16:57:15.102758 139762821543680 ag_logging.py:145] Entity <bound method Conv.call of <tensorflow.python.layers.convolutional.Conv2D object at 0x7f1cae1486d0>> could not be transformed and will be executed as-is. Please report this to the AutgoGraph team. When filing the bug, set the verbosity to 10 (on Linux, `export AUTOGRAPH_VERBOSITY=10`) and attach the full output. Cause: converting <bound method Conv.call of <tensorflow.python.layers.convolutional.Conv2D object at 0x7f1cae1486d0>>: AssertionError: Bad argument number for Name: 3, expecting 4
WARNING:tensorflow:Entity <bound method Conv.call of <tensorflow.python.layers.convolutional.Conv2D object at 0x7f1cadfa7490>> could not be transformed and will be executed as-is. Please report this to the AutgoGraph team. When filing the bug, set the verbosity to 10 (on Linux, `export AUTOGRAPH_VERBOSITY=10`) and attach the full output. Cause: converting <bound method Conv.call of <tensorflow.python.layers.convolutional.Conv2D object at 0x7f1cadfa7490>>: AssertionError: Bad argument number for Name: 3, expecting 4
W0312 16:57:15.159408 139762821543680 ag_logging.py:145] Entity <bound method Conv.call of <tensorflow.python.layers.convolutional.Conv2D object at 0x7f1cadfa7490>> could not be transformed and will be executed as-is. Please report this to the AutgoGraph team. When filing the bug, set the verbosity to 10 (on Linux, `export AUTOGRAPH_VERBOSITY=10`) and attach the full output. Cause: converting <bound method Conv.call of <tensorflow.python.layers.convolutional.Conv2D object at 0x7f1cadfa7490>>: AssertionError: Bad argument number for Name: 3, expecting 4
WARNING:tensorflow:Entity <bound method Conv.call of <tensorflow.python.layers.convolutional.Conv2D object at 0x7f1cade99f10>> could not be transformed and will be executed as-is. Please report this to the AutgoGraph team. When filing the bug, set the verbosity to 10 (on Linux, `export AUTOGRAPH_VERBOSITY=10`) and attach the full output. Cause: converting <bound method Conv.call of <tensorflow.python.layers.convolutional.Conv2D object at 0x7f1cade99f10>>: AssertionError: Bad argument number for Name: 3, expecting 4
W0312 16:57:15.236789 139762821543680 ag_logging.py:145] Entity <bound method Conv.call of <tensorflow.python.layers.convolutional.Conv2D object at 0x7f1cade99f10>> could not be transformed and will be executed as-is. Please report this to the AutgoGraph team. When filing the bug, set the verbosity to 10 (on Linux, `export AUTOGRAPH_VERBOSITY=10`) and attach the full output. Cause: converting <bound method Conv.call of <tensorflow.python.layers.convolutional.Conv2D object at 0x7f1cade99f10>>: AssertionError: Bad argument number for Name: 3, expecting 4
WARNING:tensorflow:Entity <bound method Conv.call of <tensorflow.python.layers.convolutional.Conv2D object at 0x7f1caddcd690>> could not be transformed and will be executed as-is. Please report this to the AutgoGraph team. When filing the bug, set the verbosity to 10 (on Linux, `export AUTOGRAPH_VERBOSITY=10`) and attach the full output. Cause: converting <bound method Conv.call of <tensorflow.python.layers.convolutional.Conv2D object at 0x7f1caddcd690>>: AssertionError: Bad argument number for Name: 3, expecting 4
W0312 16:57:15.294069 139762821543680 ag_logging.py:145] Entity <bound method Conv.call of <tensorflow.python.layers.convolutional.Conv2D object at 0x7f1caddcd690>> could not be transformed and will be executed as-is. Please report this to the AutgoGraph team. When filing the bug, set the verbosity to 10 (on Linux, `export AUTOGRAPH_VERBOSITY=10`) and attach the full output. Cause: converting <bound method Conv.call of <tensorflow.python.layers.convolutional.Conv2D object at 0x7f1caddcd690>>: AssertionError: Bad argument number for Name: 3, expecting 4
WARNING:tensorflow:Entity <bound method Conv.call of <tensorflow.python.layers.convolutional.Conv2D object at 0x7f1cadcbda10>> could not be transformed and will be executed as-is. Please report this to the AutgoGraph team. When filing the bug, set the verbosity to 10 (on Linux, `export AUTOGRAPH_VERBOSITY=10`) and attach the full output. Cause: converting <bound method Conv.call of <tensorflow.python.layers.convolutional.Conv2D object at 0x7f1cadcbda10>>: AssertionError: Bad argument number for Name: 3, expecting 4
W0312 16:57:15.373661 139762821543680 ag_logging.py:145] Entity <bound method Conv.call of <tensorflow.python.layers.convolutional.Conv2D object at 0x7f1cadcbda10>> could not be transformed and will be executed as-is. Please report this to the AutgoGraph team. When filing the bug, set the verbosity to 10 (on Linux, `export AUTOGRAPH_VERBOSITY=10`) and attach the full output. Cause: converting <bound method Conv.call of <tensorflow.python.layers.convolutional.Conv2D object at 0x7f1cadcbda10>>: AssertionError: Bad argument number for Name: 3, expecting 4
WARNING:tensorflow:Entity <bound method Conv.call of <tensorflow.python.layers.convolutional.Conv2D object at 0x7f1cadc2a610>> could not be transformed and will be executed as-is. Please report this to the AutgoGraph team. When filing the bug, set the verbosity to 10 (on Linux, `export AUTOGRAPH_VERBOSITY=10`) and attach the full output. Cause: converting <bound method Conv.call of <tensorflow.python.layers.convolutional.Conv2D object at 0x7f1cadc2a610>>: AssertionError: Bad argument number for Name: 3, expecting 4
W0312 16:57:15.438313 139762821543680 ag_logging.py:145] Entity <bound method Conv.call of <tensorflow.python.layers.convolutional.Conv2D object at 0x7f1cadc2a610>> could not be transformed and will be executed as-is. Please report this to the AutgoGraph team. When filing the bug, set the verbosity to 10 (on Linux, `export AUTOGRAPH_VERBOSITY=10`) and attach the full output. Cause: converting <bound method Conv.call of <tensorflow.python.layers.convolutional.Conv2D object at 0x7f1cadc2a610>>: AssertionError: Bad argument number for Name: 3, expecting 4
WARNING:tensorflow:Entity <bound method Conv.call of <tensorflow.python.layers.convolutional.Conv2D object at 0x7f1cadd8d110>> could not be transformed and will be executed as-is. Please report this to the AutgoGraph team. When filing the bug, set the verbosity to 10 (on Linux, `export AUTOGRAPH_VERBOSITY=10`) and attach the full output. Cause: converting <bound method Conv.call of <tensorflow.python.layers.convolutional.Conv2D object at 0x7f1cadd8d110>>: AssertionError: Bad argument number for Name: 3, expecting 4
W0312 16:57:15.546442 139762821543680 ag_logging.py:145] Entity <bound method Conv.call of <tensorflow.python.layers.convolutional.Conv2D object at 0x7f1cadd8d110>> could not be transformed and will be executed as-is. Please report this to the AutgoGraph team. When filing the bug, set the verbosity to 10 (on Linux, `export AUTOGRAPH_VERBOSITY=10`) and attach the full output. Cause: converting <bound method Conv.call of <tensorflow.python.layers.convolutional.Conv2D object at 0x7f1cadd8d110>>: AssertionError: Bad argument number for Name: 3, expecting 4
WARNING:tensorflow:Entity <bound method Conv.call of <tensorflow.python.layers.convolutional.Conv2D object at 0x7f1cae727190>> could not be transformed and will be executed as-is. Please report this to the AutgoGraph team. When filing the bug, set the verbosity to 10 (on Linux, `export AUTOGRAPH_VERBOSITY=10`) and attach the full output. Cause: converting <bound method Conv.call of <tensorflow.python.layers.convolutional.Conv2D object at 0x7f1cae727190>>: AssertionError: Bad argument number for Name: 3, expecting 4
W0312 16:57:15.676513 139762821543680 ag_logging.py:145] Entity <bound method Conv.call of <tensorflow.python.layers.convolutional.Conv2D object at 0x7f1cae727190>> could not be transformed and will be executed as-is. Please report this to the AutgoGraph team. When filing the bug, set the verbosity to 10 (on Linux, `export AUTOGRAPH_VERBOSITY=10`) and attach the full output. Cause: converting <bound method Conv.call of <tensorflow.python.layers.convolutional.Conv2D object at 0x7f1cae727190>>: AssertionError: Bad argument number for Name: 3, expecting 4
WARNING:tensorflow:Entity <bound method Conv.call of <tensorflow.python.layers.convolutional.Conv2D object at 0x7f1cadb58c90>> could not be transformed and will be executed as-is. Please report this to the AutgoGraph team. When filing the bug, set the verbosity to 10 (on Linux, `export AUTOGRAPH_VERBOSITY=10`) and attach the full output. Cause: converting <bound method Conv.call of <tensorflow.python.layers.convolutional.Conv2D object at 0x7f1cadb58c90>>: AssertionError: Bad argument number for Name: 3, expecting 4
W0312 16:57:15.857763 139762821543680 ag_logging.py:145] Entity <bound method Conv.call of <tensorflow.python.layers.convolutional.Conv2D object at 0x7f1cadb58c90>> could not be transformed and will be executed as-is. Please report this to the AutgoGraph team. When filing the bug, set the verbosity to 10 (on Linux, `export AUTOGRAPH_VERBOSITY=10`) and attach the full output. Cause: converting <bound method Conv.call of <tensorflow.python.layers.convolutional.Conv2D object at 0x7f1cadb58c90>>: AssertionError: Bad argument number for Name: 3, expecting 4
WARNING:tensorflow:Entity <bound method Conv.call of <tensorflow.python.layers.convolutional.Conv2D object at 0x7f1cadae6610>> could not be transformed and will be executed as-is. Please report this to the AutgoGraph team. When filing the bug, set the verbosity to 10 (on Linux, `export AUTOGRAPH_VERBOSITY=10`) and attach the full output. Cause: converting <bound method Conv.call of <tensorflow.python.layers.convolutional.Conv2D object at 0x7f1cadae6610>>: AssertionError: Bad argument number for Name: 3, expecting 4
W0312 16:57:15.981574 139762821543680 ag_logging.py:145] Entity <bound method Conv.call of <tensorflow.python.layers.convolutional.Conv2D object at 0x7f1cadae6610>> could not be transformed and will be executed as-is. Please report this to the AutgoGraph team. When filing the bug, set the verbosity to 10 (on Linux, `export AUTOGRAPH_VERBOSITY=10`) and attach the full output. Cause: converting <bound method Conv.call of <tensorflow.python.layers.convolutional.Conv2D object at 0x7f1cadae6610>>: AssertionError: Bad argument number for Name: 3, expecting 4
WARNING:tensorflow:Entity <bound method Conv.call of <tensorflow.python.layers.convolutional.Conv2D object at 0x7f1caddae5d0>> could not be transformed and will be executed as-is. Please report this to the AutgoGraph team. When filing the bug, set the verbosity to 10 (on Linux, `export AUTOGRAPH_VERBOSITY=10`) and attach the full output. Cause: converting <bound method Conv.call of <tensorflow.python.layers.convolutional.Conv2D object at 0x7f1caddae5d0>>: AssertionError: Bad argument number for Name: 3, expecting 4
W0312 16:57:16.078081 139762821543680 ag_logging.py:145] Entity <bound method Conv.call of <tensorflow.python.layers.convolutional.Conv2D object at 0x7f1caddae5d0>> could not be transformed and will be executed as-is. Please report this to the AutgoGraph team. When filing the bug, set the verbosity to 10 (on Linux, `export AUTOGRAPH_VERBOSITY=10`) and attach the full output. Cause: converting <bound method Conv.call of <tensorflow.python.layers.convolutional.Conv2D object at 0x7f1caddae5d0>>: AssertionError: Bad argument number for Name: 3, expecting 4
WARNING:tensorflow:Entity <bound method Conv.call of <tensorflow.python.layers.convolutional.Conv2D object at 0x7f1cadae3b50>> could not be transformed and will be executed as-is. Please report this to the AutgoGraph team. When filing the bug, set the verbosity to 10 (on Linux, `export AUTOGRAPH_VERBOSITY=10`) and attach the full output. Cause: converting <bound method Conv.call of <tensorflow.python.layers.convolutional.Conv2D object at 0x7f1cadae3b50>>: AssertionError: Bad argument number for Name: 3, expecting 4
W0312 16:57:16.199776 139762821543680 ag_logging.py:145] Entity <bound method Conv.call of <tensorflow.python.layers.convolutional.Conv2D object at 0x7f1cadae3b50>> could not be transformed and will be executed as-is. Please report this to the AutgoGraph team. When filing the bug, set the verbosity to 10 (on Linux, `export AUTOGRAPH_VERBOSITY=10`) and attach the full output. Cause: converting <bound method Conv.call of <tensorflow.python.layers.convolutional.Conv2D object at 0x7f1cadae3b50>>: AssertionError: Bad argument number for Name: 3, expecting 4
WARNING:tensorflow:Entity <bound method Conv.call of <tensorflow.python.layers.convolutional.Conv2D object at 0x7f1cada4e110>> could not be transformed and will be executed as-is. Please report this to the AutgoGraph team. When filing the bug, set the verbosity to 10 (on Linux, `export AUTOGRAPH_VERBOSITY=10`) and attach the full output. Cause: converting <bound method Conv.call of <tensorflow.python.layers.convolutional.Conv2D object at 0x7f1cada4e110>>: AssertionError: Bad argument number for Name: 3, expecting 4
W0312 16:57:16.366286 139762821543680 ag_logging.py:145] Entity <bound method Conv.call of <tensorflow.python.layers.convolutional.Conv2D object at 0x7f1cada4e110>> could not be transformed and will be executed as-is. Please report this to the AutgoGraph team. When filing the bug, set the verbosity to 10 (on Linux, `export AUTOGRAPH_VERBOSITY=10`) and attach the full output. Cause: converting <bound method Conv.call of <tensorflow.python.layers.convolutional.Conv2D object at 0x7f1cada4e110>>: AssertionError: Bad argument number for Name: 3, expecting 4
WARNING:tensorflow:Entity <bound method Conv.call of <tensorflow.python.layers.convolutional.Conv2D object at 0x7f1cad9fd890>> could not be transformed and will be executed as-is. Please report this to the AutgoGraph team. When filing the bug, set the verbosity to 10 (on Linux, `export AUTOGRAPH_VERBOSITY=10`) and attach the full output. Cause: converting <bound method Conv.call of <tensorflow.python.layers.convolutional.Conv2D object at 0x7f1cad9fd890>>: AssertionError: Bad argument number for Name: 3, expecting 4
W0312 16:57:16.480826 139762821543680 ag_logging.py:145] Entity <bound method Conv.call of <tensorflow.python.layers.convolutional.Conv2D object at 0x7f1cad9fd890>> could not be transformed and will be executed as-is. Please report this to the AutgoGraph team. When filing the bug, set the verbosity to 10 (on Linux, `export AUTOGRAPH_VERBOSITY=10`) and attach the full output. Cause: converting <bound method Conv.call of <tensorflow.python.layers.convolutional.Conv2D object at 0x7f1cad9fd890>>: AssertionError: Bad argument number for Name: 3, expecting 4
WARNING:tensorflow:Entity <bound method Conv.call of <tensorflow.python.layers.convolutional.Conv2D object at 0x7f1cad9e8ad0>> could not be transformed and will be executed as-is. Please report this to the AutgoGraph team. When filing the bug, set the verbosity to 10 (on Linux, `export AUTOGRAPH_VERBOSITY=10`) and attach the full output. Cause: converting <bound method Conv.call of <tensorflow.python.layers.convolutional.Conv2D object at 0x7f1cad9e8ad0>>: AssertionError: Bad argument number for Name: 3, expecting 4
W0312 16:57:16.562232 139762821543680 ag_logging.py:145] Entity <bound method Conv.call of <tensorflow.python.layers.convolutional.Conv2D object at 0x7f1cad9e8ad0>> could not be transformed and will be executed as-is. Please report this to the AutgoGraph team. When filing the bug, set the verbosity to 10 (on Linux, `export AUTOGRAPH_VERBOSITY=10`) and attach the full output. Cause: converting <bound method Conv.call of <tensorflow.python.layers.convolutional.Conv2D object at 0x7f1cad9e8ad0>>: AssertionError: Bad argument number for Name: 3, expecting 4
WARNING:tensorflow:Entity <bound method Conv.call of <tensorflow.python.layers.convolutional.Conv2D object at 0x7f1cad9276d0>> could not be transformed and will be executed as-is. Please report this to the AutgoGraph team. When filing the bug, set the verbosity to 10 (on Linux, `export AUTOGRAPH_VERBOSITY=10`) and attach the full output. Cause: converting <bound method Conv.call of <tensorflow.python.layers.convolutional.Conv2D object at 0x7f1cad9276d0>>: AssertionError: Bad argument number for Name: 3, expecting 4
W0312 16:57:16.620409 139762821543680 ag_logging.py:145] Entity <bound method Conv.call of <tensorflow.python.layers.convolutional.Conv2D object at 0x7f1cad9276d0>> could not be transformed and will be executed as-is. Please report this to the AutgoGraph team. When filing the bug, set the verbosity to 10 (on Linux, `export AUTOGRAPH_VERBOSITY=10`) and attach the full output. Cause: converting <bound method Conv.call of <tensorflow.python.layers.convolutional.Conv2D object at 0x7f1cad9276d0>>: AssertionError: Bad argument number for Name: 3, expecting 4
WARNING:tensorflow:Entity <bound method Conv.call of <tensorflow.python.layers.convolutional.Conv2D object at 0x7f1cad879b50>> could not be transformed and will be executed as-is. Please report this to the AutgoGraph team. When filing the bug, set the verbosity to 10 (on Linux, `export AUTOGRAPH_VERBOSITY=10`) and attach the full output. Cause: converting <bound method Conv.call of <tensorflow.python.layers.convolutional.Conv2D object at 0x7f1cad879b50>>: AssertionError: Bad argument number for Name: 3, expecting 4
W0312 16:57:16.700653 139762821543680 ag_logging.py:145] Entity <bound method Conv.call of <tensorflow.python.layers.convolutional.Conv2D object at 0x7f1cad879b50>> could not be transformed and will be executed as-is. Please report this to the AutgoGraph team. When filing the bug, set the verbosity to 10 (on Linux, `export AUTOGRAPH_VERBOSITY=10`) and attach the full output. Cause: converting <bound method Conv.call of <tensorflow.python.layers.convolutional.Conv2D object at 0x7f1cad879b50>>: AssertionError: Bad argument number for Name: 3, expecting 4
WARNING:tensorflow:Entity <bound method Conv.call of <tensorflow.python.layers.convolutional.Conv2D object at 0x7f1cae714e10>> could not be transformed and will be executed as-is. Please report this to the AutgoGraph team. When filing the bug, set the verbosity to 10 (on Linux, `export AUTOGRAPH_VERBOSITY=10`) and attach the full output. Cause: converting <bound method Conv.call of <tensorflow.python.layers.convolutional.Conv2D object at 0x7f1cae714e10>>: AssertionError: Bad argument number for Name: 3, expecting 4
W0312 16:57:16.749480 139762821543680 ag_logging.py:145] Entity <bound method Conv.call of <tensorflow.python.layers.convolutional.Conv2D object at 0x7f1cae714e10>> could not be transformed and will be executed as-is. Please report this to the AutgoGraph team. When filing the bug, set the verbosity to 10 (on Linux, `export AUTOGRAPH_VERBOSITY=10`) and attach the full output. Cause: converting <bound method Conv.call of <tensorflow.python.layers.convolutional.Conv2D object at 0x7f1cae714e10>>: AssertionError: Bad argument number for Name: 3, expecting 4
WARNING:tensorflow:Entity <bound method Conv.call of <tensorflow.python.layers.convolutional.Conv2D object at 0x7f1cad881c10>> could not be transformed and will be executed as-is. Please report this to the AutgoGraph team. When filing the bug, set the verbosity to 10 (on Linux, `export AUTOGRAPH_VERBOSITY=10`) and attach the full output. Cause: converting <bound method Conv.call of <tensorflow.python.layers.convolutional.Conv2D object at 0x7f1cad881c10>>: AssertionError: Bad argument number for Name: 3, expecting 4
W0312 16:57:16.797945 139762821543680 ag_logging.py:145] Entity <bound method Conv.call of <tensorflow.python.layers.convolutional.Conv2D object at 0x7f1cad881c10>> could not be transformed and will be executed as-is. Please report this to the AutgoGraph team. When filing the bug, set the verbosity to 10 (on Linux, `export AUTOGRAPH_VERBOSITY=10`) and attach the full output. Cause: converting <bound method Conv.call of <tensorflow.python.layers.convolutional.Conv2D object at 0x7f1cad881c10>>: AssertionError: Bad argument number for Name: 3, expecting 4
WARNING:tensorflow:Entity <bound method Conv.call of <tensorflow.python.layers.convolutional.Conv2D object at 0x7f1cad6d6dd0>> could not be transformed and will be executed as-is. Please report this to the AutgoGraph team. When filing the bug, set the verbosity to 10 (on Linux, `export AUTOGRAPH_VERBOSITY=10`) and attach the full output. Cause: converting <bound method Conv.call of <tensorflow.python.layers.convolutional.Conv2D object at 0x7f1cad6d6dd0>>: AssertionError: Bad argument number for Name: 3, expecting 4
W0312 16:57:16.858241 139762821543680 ag_logging.py:145] Entity <bound method Conv.call of <tensorflow.python.layers.convolutional.Conv2D object at 0x7f1cad6d6dd0>> could not be transformed and will be executed as-is. Please report this to the AutgoGraph team. When filing the bug, set the verbosity to 10 (on Linux, `export AUTOGRAPH_VERBOSITY=10`) and attach the full output. Cause: converting <bound method Conv.call of <tensorflow.python.layers.convolutional.Conv2D object at 0x7f1cad6d6dd0>>: AssertionError: Bad argument number for Name: 3, expecting 4
WARNING:tensorflow:Entity <bound method Conv.call of <tensorflow.python.layers.convolutional.Conv2D object at 0x7f1cad656d50>> could not be transformed and will be executed as-is. Please report this to the AutgoGraph team. When filing the bug, set the verbosity to 10 (on Linux, `export AUTOGRAPH_VERBOSITY=10`) and attach the full output. Cause: converting <bound method Conv.call of <tensorflow.python.layers.convolutional.Conv2D object at 0x7f1cad656d50>>: AssertionError: Bad argument number for Name: 3, expecting 4
W0312 16:57:16.938512 139762821543680 ag_logging.py:145] Entity <bound method Conv.call of <tensorflow.python.layers.convolutional.Conv2D object at 0x7f1cad656d50>> could not be transformed and will be executed as-is. Please report this to the AutgoGraph team. When filing the bug, set the verbosity to 10 (on Linux, `export AUTOGRAPH_VERBOSITY=10`) and attach the full output. Cause: converting <bound method Conv.call of <tensorflow.python.layers.convolutional.Conv2D object at 0x7f1cad656d50>>: AssertionError: Bad argument number for Name: 3, expecting 4
WARNING:tensorflow:Entity <bound method Conv.call of <tensorflow.python.layers.convolutional.Conv2D object at 0x7f1cad6dd0d0>> could not be transformed and will be executed as-is. Please report this to the AutgoGraph team. When filing the bug, set the verbosity to 10 (on Linux, `export AUTOGRAPH_VERBOSITY=10`) and attach the full output. Cause: converting <bound method Conv.call of <tensorflow.python.layers.convolutional.Conv2D object at 0x7f1cad6dd0d0>>: AssertionError: Bad argument number for Name: 3, expecting 4
W0312 16:57:16.987977 139762821543680 ag_logging.py:145] Entity <bound method Conv.call of <tensorflow.python.layers.convolutional.Conv2D object at 0x7f1cad6dd0d0>> could not be transformed and will be executed as-is. Please report this to the AutgoGraph team. When filing the bug, set the verbosity to 10 (on Linux, `export AUTOGRAPH_VERBOSITY=10`) and attach the full output. Cause: converting <bound method Conv.call of <tensorflow.python.layers.convolutional.Conv2D object at 0x7f1cad6dd0d0>>: AssertionError: Bad argument number for Name: 3, expecting 4
WARNING:tensorflow:Entity <bound method Conv.call of <tensorflow.python.layers.convolutional.Conv2D object at 0x7f1cad6d6c10>> could not be transformed and will be executed as-is. Please report this to the AutgoGraph team. When filing the bug, set the verbosity to 10 (on Linux, `export AUTOGRAPH_VERBOSITY=10`) and attach the full output. Cause: converting <bound method Conv.call of <tensorflow.python.layers.convolutional.Conv2D object at 0x7f1cad6d6c10>>: AssertionError: Bad argument number for Name: 3, expecting 4
W0312 16:57:17.167971 139762821543680 ag_logging.py:145] Entity <bound method Conv.call of <tensorflow.python.layers.convolutional.Conv2D object at 0x7f1cad6d6c10>> could not be transformed and will be executed as-is. Please report this to the AutgoGraph team. When filing the bug, set the verbosity to 10 (on Linux, `export AUTOGRAPH_VERBOSITY=10`) and attach the full output. Cause: converting <bound method Conv.call of <tensorflow.python.layers.convolutional.Conv2D object at 0x7f1cad6d6c10>>: AssertionError: Bad argument number for Name: 3, expecting 4
WARNING:tensorflow:Entity <bound method Conv.call of <tensorflow.python.layers.convolutional.Conv2D object at 0x7f1cad9b7150>> could not be transformed and will be executed as-is. Please report this to the AutgoGraph team. When filing the bug, set the verbosity to 10 (on Linux, `export AUTOGRAPH_VERBOSITY=10`) and attach the full output. Cause: converting <bound method Conv.call of <tensorflow.python.layers.convolutional.Conv2D object at 0x7f1cad9b7150>>: AssertionError: Bad argument number for Name: 3, expecting 4
W0312 16:57:17.704068 139762821543680 ag_logging.py:145] Entity <bound method Conv.call of <tensorflow.python.layers.convolutional.Conv2D object at 0x7f1cad9b7150>> could not be transformed and will be executed as-is. Please report this to the AutgoGraph team. When filing the bug, set the verbosity to 10 (on Linux, `export AUTOGRAPH_VERBOSITY=10`) and attach the full output. Cause: converting <bound method Conv.call of <tensorflow.python.layers.convolutional.Conv2D object at 0x7f1cad9b7150>>: AssertionError: Bad argument number for Name: 3, expecting 4
WARNING:tensorflow:Entity <bound method Conv.call of <tensorflow.python.layers.convolutional.Conv2D object at 0x7f1cae69c890>> could not be transformed and will be executed as-is. Please report this to the AutgoGraph team. When filing the bug, set the verbosity to 10 (on Linux, `export AUTOGRAPH_VERBOSITY=10`) and attach the full output. Cause: converting <bound method Conv.call of <tensorflow.python.layers.convolutional.Conv2D object at 0x7f1cae69c890>>: AssertionError: Bad argument number for Name: 3, expecting 4
W0312 16:57:17.903863 139762821543680 ag_logging.py:145] Entity <bound method Conv.call of <tensorflow.python.layers.convolutional.Conv2D object at 0x7f1cae69c890>> could not be transformed and will be executed as-is. Please report this to the AutgoGraph team. When filing the bug, set the verbosity to 10 (on Linux, `export AUTOGRAPH_VERBOSITY=10`) and attach the full output. Cause: converting <bound method Conv.call of <tensorflow.python.layers.convolutional.Conv2D object at 0x7f1cae69c890>>: AssertionError: Bad argument number for Name: 3, expecting 4
WARNING:tensorflow:Entity <bound method Conv.call of <tensorflow.python.layers.convolutional.Conv2D object at 0x7f1cae7112d0>> could not be transformed and will be executed as-is. Please report this to the AutgoGraph team. When filing the bug, set the verbosity to 10 (on Linux, `export AUTOGRAPH_VERBOSITY=10`) and attach the full output. Cause: converting <bound method Conv.call of <tensorflow.python.layers.convolutional.Conv2D object at 0x7f1cae7112d0>>: AssertionError: Bad argument number for Name: 3, expecting 4
W0312 16:57:18.071569 139762821543680 ag_logging.py:145] Entity <bound method Conv.call of <tensorflow.python.layers.convolutional.Conv2D object at 0x7f1cae7112d0>> could not be transformed and will be executed as-is. Please report this to the AutgoGraph team. When filing the bug, set the verbosity to 10 (on Linux, `export AUTOGRAPH_VERBOSITY=10`) and attach the full output. Cause: converting <bound method Conv.call of <tensorflow.python.layers.convolutional.Conv2D object at 0x7f1cae7112d0>>: AssertionError: Bad argument number for Name: 3, expecting 4
WARNING:tensorflow:Entity <bound method Conv.call of <tensorflow.python.layers.convolutional.Conv2D object at 0x7f1cad6f5310>> could not be transformed and will be executed as-is. Please report this to the AutgoGraph team. When filing the bug, set the verbosity to 10 (on Linux, `export AUTOGRAPH_VERBOSITY=10`) and attach the full output. Cause: converting <bound method Conv.call of <tensorflow.python.layers.convolutional.Conv2D object at 0x7f1cad6f5310>>: AssertionError: Bad argument number for Name: 3, expecting 4
W0312 16:57:18.181427 139762821543680 ag_logging.py:145] Entity <bound method Conv.call of <tensorflow.python.layers.convolutional.Conv2D object at 0x7f1cad6f5310>> could not be transformed and will be executed as-is. Please report this to the AutgoGraph team. When filing the bug, set the verbosity to 10 (on Linux, `export AUTOGRAPH_VERBOSITY=10`) and attach the full output. Cause: converting <bound method Conv.call of <tensorflow.python.layers.convolutional.Conv2D object at 0x7f1cad6f5310>>: AssertionError: Bad argument number for Name: 3, expecting 4
WARNING:tensorflow:Entity <bound method Conv.call of <tensorflow.python.layers.convolutional.Conv2D object at 0x7f1cad484790>> could not be transformed and will be executed as-is. Please report this to the AutgoGraph team. When filing the bug, set the verbosity to 10 (on Linux, `export AUTOGRAPH_VERBOSITY=10`) and attach the full output. Cause: converting <bound method Conv.call of <tensorflow.python.layers.convolutional.Conv2D object at 0x7f1cad484790>>: AssertionError: Bad argument number for Name: 3, expecting 4
W0312 16:57:18.286680 139762821543680 ag_logging.py:145] Entity <bound method Conv.call of <tensorflow.python.layers.convolutional.Conv2D object at 0x7f1cad484790>> could not be transformed and will be executed as-is. Please report this to the AutgoGraph team. When filing the bug, set the verbosity to 10 (on Linux, `export AUTOGRAPH_VERBOSITY=10`) and attach the full output. Cause: converting <bound method Conv.call of <tensorflow.python.layers.convolutional.Conv2D object at 0x7f1cad484790>>: AssertionError: Bad argument number for Name: 3, expecting 4
WARNING:tensorflow:Entity <bound method Conv.call of <tensorflow.python.layers.convolutional.Conv2D object at 0x7f1cad6f5890>> could not be transformed and will be executed as-is. Please report this to the AutgoGraph team. When filing the bug, set the verbosity to 10 (on Linux, `export AUTOGRAPH_VERBOSITY=10`) and attach the full output. Cause: converting <bound method Conv.call of <tensorflow.python.layers.convolutional.Conv2D object at 0x7f1cad6f5890>>: AssertionError: Bad argument number for Name: 3, expecting 4
W0312 16:57:18.341696 139762821543680 ag_logging.py:145] Entity <bound method Conv.call of <tensorflow.python.layers.convolutional.Conv2D object at 0x7f1cad6f5890>> could not be transformed and will be executed as-is. Please report this to the AutgoGraph team. When filing the bug, set the verbosity to 10 (on Linux, `export AUTOGRAPH_VERBOSITY=10`) and attach the full output. Cause: converting <bound method Conv.call of <tensorflow.python.layers.convolutional.Conv2D object at 0x7f1cad6f5890>>: AssertionError: Bad argument number for Name: 3, expecting 4
WARNING:tensorflow:Entity <bound method Conv.call of <tensorflow.python.layers.convolutional.Conv2D object at 0x7f1cae5a3bd0>> could not be transformed and will be executed as-is. Please report this to the AutgoGraph team. When filing the bug, set the verbosity to 10 (on Linux, `export AUTOGRAPH_VERBOSITY=10`) and attach the full output. Cause: converting <bound method Conv.call of <tensorflow.python.layers.convolutional.Conv2D object at 0x7f1cae5a3bd0>>: AssertionError: Bad argument number for Name: 3, expecting 4
W0312 16:57:18.414317 139762821543680 ag_logging.py:145] Entity <bound method Conv.call of <tensorflow.python.layers.convolutional.Conv2D object at 0x7f1cae5a3bd0>> could not be transformed and will be executed as-is. Please report this to the AutgoGraph team. When filing the bug, set the verbosity to 10 (on Linux, `export AUTOGRAPH_VERBOSITY=10`) and attach the full output. Cause: converting <bound method Conv.call of <tensorflow.python.layers.convolutional.Conv2D object at 0x7f1cae5a3bd0>>: AssertionError: Bad argument number for Name: 3, expecting 4
WARNING:tensorflow:Entity <bound method Conv.call of <tensorflow.python.layers.convolutional.Conv2D object at 0x7f1cae2a61d0>> could not be transformed and will be executed as-is. Please report this to the AutgoGraph team. When filing the bug, set the verbosity to 10 (on Linux, `export AUTOGRAPH_VERBOSITY=10`) and attach the full output. Cause: converting <bound method Conv.call of <tensorflow.python.layers.convolutional.Conv2D object at 0x7f1cae2a61d0>>: AssertionError: Bad argument number for Name: 3, expecting 4
W0312 16:57:18.469997 139762821543680 ag_logging.py:145] Entity <bound method Conv.call of <tensorflow.python.layers.convolutional.Conv2D object at 0x7f1cae2a61d0>> could not be transformed and will be executed as-is. Please report this to the AutgoGraph team. When filing the bug, set the verbosity to 10 (on Linux, `export AUTOGRAPH_VERBOSITY=10`) and attach the full output. Cause: converting <bound method Conv.call of <tensorflow.python.layers.convolutional.Conv2D object at 0x7f1cae2a61d0>>: AssertionError: Bad argument number for Name: 3, expecting 4
WARNING:tensorflow:Entity <bound method Conv.call of <tensorflow.python.layers.convolutional.Conv2D object at 0x7f1cad2db6d0>> could not be transformed and will be executed as-is. Please report this to the AutgoGraph team. When filing the bug, set the verbosity to 10 (on Linux, `export AUTOGRAPH_VERBOSITY=10`) and attach the full output. Cause: converting <bound method Conv.call of <tensorflow.python.layers.convolutional.Conv2D object at 0x7f1cad2db6d0>>: AssertionError: Bad argument number for Name: 3, expecting 4
W0312 16:57:18.542774 139762821543680 ag_logging.py:145] Entity <bound method Conv.call of <tensorflow.python.layers.convolutional.Conv2D object at 0x7f1cad2db6d0>> could not be transformed and will be executed as-is. Please report this to the AutgoGraph team. When filing the bug, set the verbosity to 10 (on Linux, `export AUTOGRAPH_VERBOSITY=10`) and attach the full output. Cause: converting <bound method Conv.call of <tensorflow.python.layers.convolutional.Conv2D object at 0x7f1cad2db6d0>>: AssertionError: Bad argument number for Name: 3, expecting 4
WARNING:tensorflow:From /opt/agazade/data_science/training/code/mobile_detection/ssd_mobilenet/ssd_mobilenet/object_detection/predictors/convolutional_box_predictor.py:150: The name tf.logging.info is deprecated. Please use tf.compat.v1.logging.info instead.

W0312 16:57:19.251252 139762821543680 deprecation_wrapper.py:119] From /opt/agazade/data_science/training/code/mobile_detection/ssd_mobilenet/ssd_mobilenet/object_detection/predictors/convolutional_box_predictor.py:150: The name tf.logging.info is deprecated. Please use tf.compat.v1.logging.info instead.

INFO:tensorflow:depth of additional conv before box predictor: 0
I0312 16:57:19.251655 139762821543680 convolutional_box_predictor.py:151] depth of additional conv before box predictor: 0
WARNING:tensorflow:Entity <bound method Conv.call of <tensorflow.python.layers.convolutional.Conv2D object at 0x7f1cacc89250>> could not be transformed and will be executed as-is. Please report this to the AutgoGraph team. When filing the bug, set the verbosity to 10 (on Linux, `export AUTOGRAPH_VERBOSITY=10`) and attach the full output. Cause: converting <bound method Conv.call of <tensorflow.python.layers.convolutional.Conv2D object at 0x7f1cacc89250>>: AssertionError: Bad argument number for Name: 3, expecting 4
W0312 16:57:19.386898 139762821543680 ag_logging.py:145] Entity <bound method Conv.call of <tensorflow.python.layers.convolutional.Conv2D object at 0x7f1cacc89250>> could not be transformed and will be executed as-is. Please report this to the AutgoGraph team. When filing the bug, set the verbosity to 10 (on Linux, `export AUTOGRAPH_VERBOSITY=10`) and attach the full output. Cause: converting <bound method Conv.call of <tensorflow.python.layers.convolutional.Conv2D object at 0x7f1cacc89250>>: AssertionError: Bad argument number for Name: 3, expecting 4
WARNING:tensorflow:Entity <bound method Conv.call of <tensorflow.python.layers.convolutional.Conv2D object at 0x7f1cacc89250>> could not be transformed and will be executed as-is. Please report this to the AutgoGraph team. When filing the bug, set the verbosity to 10 (on Linux, `export AUTOGRAPH_VERBOSITY=10`) and attach the full output. Cause: converting <bound method Conv.call of <tensorflow.python.layers.convolutional.Conv2D object at 0x7f1cacc89250>>: AssertionError: Bad argument number for Name: 3, expecting 4
W0312 16:57:19.520512 139762821543680 ag_logging.py:145] Entity <bound method Conv.call of <tensorflow.python.layers.convolutional.Conv2D object at 0x7f1cacc89250>> could not be transformed and will be executed as-is. Please report this to the AutgoGraph team. When filing the bug, set the verbosity to 10 (on Linux, `export AUTOGRAPH_VERBOSITY=10`) and attach the full output. Cause: converting <bound method Conv.call of <tensorflow.python.layers.convolutional.Conv2D object at 0x7f1cacc89250>>: AssertionError: Bad argument number for Name: 3, expecting 4
INFO:tensorflow:depth of additional conv before box predictor: 0
I0312 16:57:19.528858 139762821543680 convolutional_box_predictor.py:151] depth of additional conv before box predictor: 0
WARNING:tensorflow:Entity <bound method Conv.call of <tensorflow.python.layers.convolutional.Conv2D object at 0x7f1cacbd4250>> could not be transformed and will be executed as-is. Please report this to the AutgoGraph team. When filing the bug, set the verbosity to 10 (on Linux, `export AUTOGRAPH_VERBOSITY=10`) and attach the full output. Cause: converting <bound method Conv.call of <tensorflow.python.layers.convolutional.Conv2D object at 0x7f1cacbd4250>>: AssertionError: Bad argument number for Name: 3, expecting 4
W0312 16:57:19.694839 139762821543680 ag_logging.py:145] Entity <bound method Conv.call of <tensorflow.python.layers.convolutional.Conv2D object at 0x7f1cacbd4250>> could not be transformed and will be executed as-is. Please report this to the AutgoGraph team. When filing the bug, set the verbosity to 10 (on Linux, `export AUTOGRAPH_VERBOSITY=10`) and attach the full output. Cause: converting <bound method Conv.call of <tensorflow.python.layers.convolutional.Conv2D object at 0x7f1cacbd4250>>: AssertionError: Bad argument number for Name: 3, expecting 4
WARNING:tensorflow:Entity <bound method Conv.call of <tensorflow.python.layers.convolutional.Conv2D object at 0x7f1cacba1dd0>> could not be transformed and will be executed as-is. Please report this to the AutgoGraph team. When filing the bug, set the verbosity to 10 (on Linux, `export AUTOGRAPH_VERBOSITY=10`) and attach the full output. Cause: converting <bound method Conv.call of <tensorflow.python.layers.convolutional.Conv2D object at 0x7f1cacba1dd0>>: AssertionError: Bad argument number for Name: 3, expecting 4
W0312 16:57:19.854045 139762821543680 ag_logging.py:145] Entity <bound method Conv.call of <tensorflow.python.layers.convolutional.Conv2D object at 0x7f1cacba1dd0>> could not be transformed and will be executed as-is. Please report this to the AutgoGraph team. When filing the bug, set the verbosity to 10 (on Linux, `export AUTOGRAPH_VERBOSITY=10`) and attach the full output. Cause: converting <bound method Conv.call of <tensorflow.python.layers.convolutional.Conv2D object at 0x7f1cacba1dd0>>: AssertionError: Bad argument number for Name: 3, expecting 4
INFO:tensorflow:depth of additional conv before box predictor: 0
I0312 16:57:19.862627 139762821543680 convolutional_box_predictor.py:151] depth of additional conv before box predictor: 0
WARNING:tensorflow:Entity <bound method Conv.call of <tensorflow.python.layers.convolutional.Conv2D object at 0x7f1cacafc150>> could not be transformed and will be executed as-is. Please report this to the AutgoGraph team. When filing the bug, set the verbosity to 10 (on Linux, `export AUTOGRAPH_VERBOSITY=10`) and attach the full output. Cause: converting <bound method Conv.call of <tensorflow.python.layers.convolutional.Conv2D object at 0x7f1cacafc150>>: AssertionError: Bad argument number for Name: 3, expecting 4
W0312 16:57:19.993486 139762821543680 ag_logging.py:145] Entity <bound method Conv.call of <tensorflow.python.layers.convolutional.Conv2D object at 0x7f1cacafc150>> could not be transformed and will be executed as-is. Please report this to the AutgoGraph team. When filing the bug, set the verbosity to 10 (on Linux, `export AUTOGRAPH_VERBOSITY=10`) and attach the full output. Cause: converting <bound method Conv.call of <tensorflow.python.layers.convolutional.Conv2D object at 0x7f1cacafc150>>: AssertionError: Bad argument number for Name: 3, expecting 4
WARNING:tensorflow:Entity <bound method Conv.call of <tensorflow.python.layers.convolutional.Conv2D object at 0x7f1cae079790>> could not be transformed and will be executed as-is. Please report this to the AutgoGraph team. When filing the bug, set the verbosity to 10 (on Linux, `export AUTOGRAPH_VERBOSITY=10`) and attach the full output. Cause: converting <bound method Conv.call of <tensorflow.python.layers.convolutional.Conv2D object at 0x7f1cae079790>>: AssertionError: Bad argument number for Name: 3, expecting 4
W0312 16:57:20.059551 139762821543680 ag_logging.py:145] Entity <bound method Conv.call of <tensorflow.python.layers.convolutional.Conv2D object at 0x7f1cae079790>> could not be transformed and will be executed as-is. Please report this to the AutgoGraph team. When filing the bug, set the verbosity to 10 (on Linux, `export AUTOGRAPH_VERBOSITY=10`) and attach the full output. Cause: converting <bound method Conv.call of <tensorflow.python.layers.convolutional.Conv2D object at 0x7f1cae079790>>: AssertionError: Bad argument number for Name: 3, expecting 4
INFO:tensorflow:depth of additional conv before box predictor: 0
I0312 16:57:20.061828 139762821543680 convolutional_box_predictor.py:151] depth of additional conv before box predictor: 0
WARNING:tensorflow:Entity <bound method Conv.call of <tensorflow.python.layers.convolutional.Conv2D object at 0x7f1cac9dfcd0>> could not be transformed and will be executed as-is. Please report this to the AutgoGraph team. When filing the bug, set the verbosity to 10 (on Linux, `export AUTOGRAPH_VERBOSITY=10`) and attach the full output. Cause: converting <bound method Conv.call of <tensorflow.python.layers.convolutional.Conv2D object at 0x7f1cac9dfcd0>>: AssertionError: Bad argument number for Name: 3, expecting 4
W0312 16:57:20.126295 139762821543680 ag_logging.py:145] Entity <bound method Conv.call of <tensorflow.python.layers.convolutional.Conv2D object at 0x7f1cac9dfcd0>> could not be transformed and will be executed as-is. Please report this to the AutgoGraph team. When filing the bug, set the verbosity to 10 (on Linux, `export AUTOGRAPH_VERBOSITY=10`) and attach the full output. Cause: converting <bound method Conv.call of <tensorflow.python.layers.convolutional.Conv2D object at 0x7f1cac9dfcd0>>: AssertionError: Bad argument number for Name: 3, expecting 4
WARNING:tensorflow:Entity <bound method Conv.call of <tensorflow.python.layers.convolutional.Conv2D object at 0x7f1cac957250>> could not be transformed and will be executed as-is. Please report this to the AutgoGraph team. When filing the bug, set the verbosity to 10 (on Linux, `export AUTOGRAPH_VERBOSITY=10`) and attach the full output. Cause: converting <bound method Conv.call of <tensorflow.python.layers.convolutional.Conv2D object at 0x7f1cac957250>>: AssertionError: Bad argument number for Name: 3, expecting 4
W0312 16:57:20.192180 139762821543680 ag_logging.py:145] Entity <bound method Conv.call of <tensorflow.python.layers.convolutional.Conv2D object at 0x7f1cac957250>> could not be transformed and will be executed as-is. Please report this to the AutgoGraph team. When filing the bug, set the verbosity to 10 (on Linux, `export AUTOGRAPH_VERBOSITY=10`) and attach the full output. Cause: converting <bound method Conv.call of <tensorflow.python.layers.convolutional.Conv2D object at 0x7f1cac957250>>: AssertionError: Bad argument number for Name: 3, expecting 4
INFO:tensorflow:depth of additional conv before box predictor: 0
I0312 16:57:20.194556 139762821543680 convolutional_box_predictor.py:151] depth of additional conv before box predictor: 0
WARNING:tensorflow:Entity <bound method Conv.call of <tensorflow.python.layers.convolutional.Conv2D object at 0x7f1caca0b210>> could not be transformed and will be executed as-is. Please report this to the AutgoGraph team. When filing the bug, set the verbosity to 10 (on Linux, `export AUTOGRAPH_VERBOSITY=10`) and attach the full output. Cause: converting <bound method Conv.call of <tensorflow.python.layers.convolutional.Conv2D object at 0x7f1caca0b210>>: AssertionError: Bad argument number for Name: 3, expecting 4
W0312 16:57:20.258555 139762821543680 ag_logging.py:145] Entity <bound method Conv.call of <tensorflow.python.layers.convolutional.Conv2D object at 0x7f1caca0b210>> could not be transformed and will be executed as-is. Please report this to the AutgoGraph team. When filing the bug, set the verbosity to 10 (on Linux, `export AUTOGRAPH_VERBOSITY=10`) and attach the full output. Cause: converting <bound method Conv.call of <tensorflow.python.layers.convolutional.Conv2D object at 0x7f1caca0b210>>: AssertionError: Bad argument number for Name: 3, expecting 4
WARNING:tensorflow:Entity <bound method Conv.call of <tensorflow.python.layers.convolutional.Conv2D object at 0x7f1cac97c250>> could not be transformed and will be executed as-is. Please report this to the AutgoGraph team. When filing the bug, set the verbosity to 10 (on Linux, `export AUTOGRAPH_VERBOSITY=10`) and attach the full output. Cause: converting <bound method Conv.call of <tensorflow.python.layers.convolutional.Conv2D object at 0x7f1cac97c250>>: AssertionError: Bad argument number for Name: 3, expecting 4
W0312 16:57:20.392803 139762821543680 ag_logging.py:145] Entity <bound method Conv.call of <tensorflow.python.layers.convolutional.Conv2D object at 0x7f1cac97c250>> could not be transformed and will be executed as-is. Please report this to the AutgoGraph team. When filing the bug, set the verbosity to 10 (on Linux, `export AUTOGRAPH_VERBOSITY=10`) and attach the full output. Cause: converting <bound method Conv.call of <tensorflow.python.layers.convolutional.Conv2D object at 0x7f1cac97c250>>: AssertionError: Bad argument number for Name: 3, expecting 4
INFO:tensorflow:depth of additional conv before box predictor: 0
I0312 16:57:20.395060 139762821543680 convolutional_box_predictor.py:151] depth of additional conv before box predictor: 0
WARNING:tensorflow:Entity <bound method Conv.call of <tensorflow.python.layers.convolutional.Conv2D object at 0x7f1caca0b210>> could not be transformed and will be executed as-is. Please report this to the AutgoGraph team. When filing the bug, set the verbosity to 10 (on Linux, `export AUTOGRAPH_VERBOSITY=10`) and attach the full output. Cause: converting <bound method Conv.call of <tensorflow.python.layers.convolutional.Conv2D object at 0x7f1caca0b210>>: AssertionError: Bad argument number for Name: 3, expecting 4
W0312 16:57:20.476112 139762821543680 ag_logging.py:145] Entity <bound method Conv.call of <tensorflow.python.layers.convolutional.Conv2D object at 0x7f1caca0b210>> could not be transformed and will be executed as-is. Please report this to the AutgoGraph team. When filing the bug, set the verbosity to 10 (on Linux, `export AUTOGRAPH_VERBOSITY=10`) and attach the full output. Cause: converting <bound method Conv.call of <tensorflow.python.layers.convolutional.Conv2D object at 0x7f1caca0b210>>: AssertionError: Bad argument number for Name: 3, expecting 4
WARNING:tensorflow:Entity <bound method Conv.call of <tensorflow.python.layers.convolutional.Conv2D object at 0x7f1caca0b210>> could not be transformed and will be executed as-is. Please report this to the AutgoGraph team. When filing the bug, set the verbosity to 10 (on Linux, `export AUTOGRAPH_VERBOSITY=10`) and attach the full output. Cause: converting <bound method Conv.call of <tensorflow.python.layers.convolutional.Conv2D object at 0x7f1caca0b210>>: AssertionError: Bad argument number for Name: 3, expecting 4
W0312 16:57:20.614807 139762821543680 ag_logging.py:145] Entity <bound method Conv.call of <tensorflow.python.layers.convolutional.Conv2D object at 0x7f1caca0b210>> could not be transformed and will be executed as-is. Please report this to the AutgoGraph team. When filing the bug, set the verbosity to 10 (on Linux, `export AUTOGRAPH_VERBOSITY=10`) and attach the full output. Cause: converting <bound method Conv.call of <tensorflow.python.layers.convolutional.Conv2D object at 0x7f1caca0b210>>: AssertionError: Bad argument number for Name: 3, expecting 4
WARNING:tensorflow:From /opt/agazade/data_science/training/code/mobile_detection/ssd_mobilenet/ssd_mobilenet/object_detection/core/post_processing.py:1106: add_dispatch_support.<locals>.wrapper (from tensorflow.python.ops.array_ops) is deprecated and will be removed in a future version.
Instructions for updating:
Use tf.where in 2.0, which has the same broadcast rule as np.where
W0312 16:57:20.733510 139762821543680 deprecation.py:323] From /opt/agazade/data_science/training/code/mobile_detection/ssd_mobilenet/ssd_mobilenet/object_detection/core/post_processing.py:1106: add_dispatch_support.<locals>.wrapper (from tensorflow.python.ops.array_ops) is deprecated and will be removed in a future version.
Instructions for updating:
Use tf.where in 2.0, which has the same broadcast rule as np.where
WARNING:tensorflow:From /opt/agazade/data_science/training/code/mobile_detection/ssd_mobilenet/ssd_mobilenet/object_detection/core/box_list_ops.py:422: calling reduce_sum_v1 (from tensorflow.python.ops.math_ops) with keep_dims is deprecated and will be removed in a future version.
Instructions for updating:
keep_dims is deprecated, use keepdims instead
W0312 16:57:20.952780 139762821543680 deprecation.py:506] From /opt/agazade/data_science/training/code/mobile_detection/ssd_mobilenet/ssd_mobilenet/object_detection/core/box_list_ops.py:422: calling reduce_sum_v1 (from tensorflow.python.ops.math_ops) with keep_dims is deprecated and will be removed in a future version.
Instructions for updating:
keep_dims is deprecated, use keepdims instead
WARNING:tensorflow:From /opt/agazade/data_science/training/code/mobile_detection/ssd_mobilenet/ssd_mobilenet/object_detection/core/losses.py:177: The name tf.losses.huber_loss is deprecated. Please use tf.compat.v1.losses.huber_loss instead.

W0312 16:57:21.192803 139762821543680 deprecation_wrapper.py:119] From /opt/agazade/data_science/training/code/mobile_detection/ssd_mobilenet/ssd_mobilenet/object_detection/core/losses.py:177: The name tf.losses.huber_loss is deprecated. Please use tf.compat.v1.losses.huber_loss instead.

WARNING:tensorflow:From /opt/agazade/data_science/training/code/mobile_detection/ssd_mobilenet/ssd_mobilenet/object_detection/core/losses.py:183: The name tf.losses.Reduction is deprecated. Please use tf.compat.v1.losses.Reduction instead.

W0312 16:57:21.194465 139762821543680 deprecation_wrapper.py:119] From /opt/agazade/data_science/training/code/mobile_detection/ssd_mobilenet/ssd_mobilenet/object_detection/core/losses.py:183: The name tf.losses.Reduction is deprecated. Please use tf.compat.v1.losses.Reduction instead.

WARNING:tensorflow:From /opt/agazade/data_science/training/code/mobile_detection/ssd_mobilenet/ssd_mobilenet/object_detection/eval_util.py:796: to_int64 (from tensorflow.python.ops.math_ops) is deprecated and will be removed in a future version.
Instructions for updating:
Use `tf.cast` instead.
W0312 16:57:21.316722 139762821543680 deprecation.py:323] From /opt/agazade/data_science/training/code/mobile_detection/ssd_mobilenet/ssd_mobilenet/object_detection/eval_util.py:796: to_int64 (from tensorflow.python.ops.math_ops) is deprecated and will be removed in a future version.
Instructions for updating:
Use `tf.cast` instead.
WARNING:tensorflow:From /opt/agazade/data_science/training/code/mobile_detection/ssd_mobilenet/ssd_mobilenet/object_detection/legacy/evaluator.py:264: The name tf.train.get_or_create_global_step is deprecated. Please use tf.compat.v1.train.get_or_create_global_step instead.

W0312 16:57:21.692234 139762821543680 deprecation_wrapper.py:119] From /opt/agazade/data_science/training/code/mobile_detection/ssd_mobilenet/ssd_mobilenet/object_detection/legacy/evaluator.py:264: The name tf.train.get_or_create_global_step is deprecated. Please use tf.compat.v1.train.get_or_create_global_step instead.

WARNING:tensorflow:From /opt/agazade/data_science/training/code/mobile_detection/ssd_mobilenet/ssd_mobilenet/object_detection/legacy/evaluator.py:270: The name tf.train.Saver is deprecated. Please use tf.compat.v1.train.Saver instead.

W0312 16:57:21.694534 139762821543680 deprecation_wrapper.py:119] From /opt/agazade/data_science/training/code/mobile_detection/ssd_mobilenet/ssd_mobilenet/object_detection/legacy/evaluator.py:270: The name tf.train.Saver is deprecated. Please use tf.compat.v1.train.Saver instead.

INFO:tensorflow:Starting evaluation at 2020-03-12-13:57:21
I0312 16:57:21.898280 139762821543680 eval_util.py:496] Starting evaluation at 2020-03-12-13:57:21
INFO:tensorflow:No model found in /srv/data_science/training/checkpoints/mobile_detection/model2/pretrain_model2/inf_graph.pb/saved_model.pb. Will try again in 20 seconds
I0312 16:57:21.898447 139762821543680 eval_util.py:500] No model found in /srv/data_science/training/checkpoints/mobile_detection/model2/pretrain_model2/inf_graph.pb/saved_model.pb. Will try again in 20 seconds
INFO:tensorflow:Starting evaluation at 2020-03-12-13:57:41
I0312 16:57:41.916711 139762821543680 eval_util.py:496] Starting evaluation at 2020-03-12-13:57:41
INFO:tensorflow:No model found in /srv/data_science/training/checkpoints/mobile_detection/model2/pretrain_model2/inf_graph.pb/saved_model.pb. Will try again in 20 seconds
I0312 16:57:41.917714 139762821543680 eval_util.py:500] No model found in /srv/data_science/training/checkpoints/mobile_detection/model2/pretrain_model2/inf_graph.pb/saved_model.pb. Will try again in 20 seconds
INFO:tensorflow:Starting evaluation at 2020-03-12-13:58:01
I0312 16:58:01.936685 139762821543680 eval_util.py:496] Starting evaluation at 2020-03-12-13:58:01
INFO:tensorflow:No model found in /srv/data_science/training/checkpoints/mobile_detection/model2/pretrain_model2/inf_graph.pb/saved_model.pb. Will try again in 20 seconds
I0312 16:58:01.937394 139762821543680 eval_util.py:500] No model found in /srv/data_science/training/checkpoints/mobile_detection/model2/pretrain_model2/inf_graph.pb/saved_model.pb. Will try again in 20 seconds
INFO:tensorflow:Starting evaluation at 2020-03-12-13:58:21
I0312 16:58:21.956722 139762821543680 eval_util.py:496] Starting evaluation at 2020-03-12-13:58:21
INFO:tensorflow:No model found in /srv/data_science/training/checkpoints/mobile_detection/model2/pretrain_model2/inf_graph.pb/saved_model.pb. Will try again in 20 seconds
I0312 16:58:21.957685 139762821543680 eval_util.py:500] No model found in /srv/data_science/training/checkpoints/mobile_detection/model2/pretrain_model2/inf_graph.pb/saved_model.pb. Will try again in 20 seconds
INFO:tensorflow:Starting evaluation at 2020-03-12-13:58:41
I0312 16:58:41.976670 139762821543680 eval_util.py:496] Starting evaluation at 2020-03-12-13:58:41
INFO:tensorflow:No model found in /srv/data_science/training/checkpoints/mobile_detection/model2/pretrain_model2/inf_graph.pb/saved_model.pb. Will try again in 20 seconds
I0312 16:58:41.977258 139762821543680 eval_util.py:500] No model found in /srv/data_science/training/checkpoints/mobile_detection/model2/pretrain_model2/inf_graph.pb/saved_model.pb. Will try again in 20 seconds
INFO:tensorflow:Starting evaluation at 2020-03-12-13:59:01
I0312 16:59:01.996601 139762821543680 eval_util.py:496] Starting evaluation at 2020-03-12-13:59:01
INFO:tensorflow:No model found in /srv/data_science/training/checkpoints/mobile_detection/model2/pretrain_model2/inf_graph.pb/saved_model.pb. Will try again in 20 seconds
I0312 16:59:01.996801 139762821543680 eval_util.py:500] No model found in /srv/data_science/training/checkpoints/mobile_detection/model2/pretrain_model2/inf_graph.pb/saved_model.pb. Will try again in 20 seconds
INFO:tensorflow:Starting evaluation at 2020-03-12-13:59:22
I0312 16:59:22.016539 139762821543680 eval_util.py:496] Starting evaluation at 2020-03-12-13:59:22
INFO:tensorflow:No model found in /srv/data_science/training/checkpoints/mobile_detection/model2/pretrain_model2/inf_graph.pb/saved_model.pb. Will try again in 20 seconds
I0312 16:59:22.016780 139762821543680 eval_util.py:500] No model found in /srv/data_science/training/checkpoints/mobile_detection/model2/pretrain_model2/inf_graph.pb/saved_model.pb. Will try again in 20 seconds
INFO:tensorflow:Starting evaluation at 2020-03-12-13:59:42
I0312 16:59:42.036767 139762821543680 eval_util.py:496] Starting evaluation at 2020-03-12-13:59:42
INFO:tensorflow:No model found in /srv/data_science/training/checkpoints/mobile_detection/model2/pretrain_model2/inf_graph.pb/saved_model.pb. Will try again in 20 seconds
I0312 16:59:42.037639 139762821543680 eval_util.py:500] No model found in /srv/data_science/training/checkpoints/mobile_detection/model2/pretrain_model2/inf_graph.pb/saved_model.pb. Will try again in 20 seconds
INFO:tensorflow:Starting evaluation at 2020-03-12-14:00:02
I0312 17:00:02.054760 139762821543680 eval_util.py:496] Starting evaluation at 2020-03-12-14:00:02
INFO:tensorflow:No model found in /srv/data_science/training/checkpoints/mobile_detection/model2/pretrain_model2/inf_graph.pb/saved_model.pb. Will try again in 20 seconds
I0312 17:00:02.054940 139762821543680 eval_util.py:500] No model found in /srv/data_science/training/checkpoints/mobile_detection/model2/pretrain_model2/inf_graph.pb/saved_model.pb. Will try again in 20 seconds
INFO:tensorflow:Starting evaluation at 2020-03-12-14:00:22
I0312 17:00:22.072693 139762821543680 eval_util.py:496] Starting evaluation at 2020-03-12-14:00:22
INFO:tensorflow:No model found in /srv/data_science/training/checkpoints/mobile_detection/model2/pretrain_model2/inf_graph.pb/saved_model.pb. Will try again in 20 seconds
I0312 17:00:22.073354 139762821543680 eval_util.py:500] No model found in /srv/data_science/training/checkpoints/mobile_detection/model2/pretrain_model2/inf_graph.pb/saved_model.pb. Will try again in 20 seconds
INFO:tensorflow:Starting evaluation at 2020-03-12-14:00:42
I0312 17:00:42.092724 139762821543680 eval_util.py:496] Starting evaluation at 2020-03-12-14:00:42
INFO:tensorflow:No model found in /srv/data_science/training/checkpoints/mobile_detection/model2/pretrain_model2/inf_graph.pb/saved_model.pb. Will try again in 20 seconds
I0312 17:00:42.093505 139762821543680 eval_util.py:500] No model found in /srv/data_science/training/checkpoints/mobile_detection/model2/pretrain_model2/inf_graph.pb/saved_model.pb. Will try again in 20 seconds
INFO:tensorflow:Starting evaluation at 2020-03-12-14:01:02
I0312 17:01:02.112527 139762821543680 eval_util.py:496] Starting evaluation at 2020-03-12-14:01:02
INFO:tensorflow:No model found in /srv/data_science/training/checkpoints/mobile_detection/model2/pretrain_model2/inf_graph.pb/saved_model.pb. Will try again in 20 seconds
I0312 17:01:02.112714 139762821543680 eval_util.py:500] No model found in /srv/data_science/training/checkpoints/mobile_detection/model2/pretrain_model2/inf_graph.pb/saved_model.pb. Will try again in 20 seconds
INFO:tensorflow:Starting evaluation at 2020-03-12-14:01:22
I0312 17:01:22.132703 139762821543680 eval_util.py:496] Starting evaluation at 2020-03-12-14:01:22
INFO:tensorflow:No model found in /srv/data_science/training/checkpoints/mobile_detection/model2/pretrain_model2/inf_graph.pb/saved_model.pb. Will try again in 20 seconds
I0312 17:01:22.133396 139762821543680 eval_util.py:500] No model found in /srv/data_science/training/checkpoints/mobile_detection/model2/pretrain_model2/inf_graph.pb/saved_model.pb. Will try again in 20 seconds
INFO:tensorflow:Starting evaluation at 2020-03-12-14:01:42
I0312 17:01:42.152746 139762821543680 eval_util.py:496] Starting evaluation at 2020-03-12-14:01:42
INFO:tensorflow:No model found in /srv/data_science/training/checkpoints/mobile_detection/model2/pretrain_model2/inf_graph.pb/saved_model.pb. Will try again in 20 seconds
I0312 17:01:42.153397 139762821543680 eval_util.py:500] No model found in /srv/data_science/training/checkpoints/mobile_detection/model2/pretrain_model2/inf_graph.pb/saved_model.pb. Will try again in 20 seconds
INFO:tensorflow:Starting evaluation at 2020-03-12-14:02:02
I0312 17:02:02.172586 139762821543680 eval_util.py:496] Starting evaluation at 2020-03-12-14:02:02
INFO:tensorflow:No model found in /srv/data_science/training/checkpoints/mobile_detection/model2/pretrain_model2/inf_graph.pb/saved_model.pb. Will try again in 20 seconds
I0312 17:02:02.172781 139762821543680 eval_util.py:500] No model found in /srv/data_science/training/checkpoints/mobile_detection/model2/pretrain_model2/inf_graph.pb/saved_model.pb. Will try again in 20 seconds
INFO:tensorflow:Starting evaluation at 2020-03-12-14:02:22
I0312 17:02:22.192735 139762821543680 eval_util.py:496] Starting evaluation at 2020-03-12-14:02:22
INFO:tensorflow:No model found in /srv/data_science/training/checkpoints/mobile_detection/model2/pretrain_model2/inf_graph.pb/saved_model.pb. Will try again in 20 seconds
I0312 17:02:22.193586 139762821543680 eval_util.py:500] No model found in /srv/data_science/training/checkpoints/mobile_detection/model2/pretrain_model2/inf_graph.pb/saved_model.pb. Will try again in 20 seconds
INFO:tensorflow:Starting evaluation at 2020-03-12-14:02:42
I0312 17:02:42.212639 139762821543680 eval_util.py:496] Starting evaluation at 2020-03-12-14:02:42
INFO:tensorflow:No model found in /srv/data_science/training/checkpoints/mobile_detection/model2/pretrain_model2/inf_graph.pb/saved_model.pb. Will try again in 20 seconds
I0312 17:02:42.213274 139762821543680 eval_util.py:500] No model found in /srv/data_science/training/checkpoints/mobile_detection/model2/pretrain_model2/inf_graph.pb/saved_model.pb. Will try again in 20 seconds
INFO:tensorflow:Starting evaluation at 2020-03-12-14:03:02
I0312 17:03:02.232727 139762821543680 eval_util.py:496] Starting evaluation at 2020-03-12-14:03:02
INFO:tensorflow:No model found in /srv/data_science/training/checkpoints/mobile_detection/model2/pretrain_model2/inf_graph.pb/saved_model.pb. Will try again in 20 seconds
I0312 17:03:02.233639 139762821543680 eval_util.py:500] No model found in /srv/data_science/training/checkpoints/mobile_detection/model2/pretrain_model2/inf_graph.pb/saved_model.pb. Will try again in 20 seconds
INFO:tensorflow:Starting evaluation at 2020-03-12-14:03:22
I0312 17:03:22.232614 139762821543680 eval_util.py:496] Starting evaluation at 2020-03-12-14:03:22
INFO:tensorflow:No model found in /srv/data_science/training/checkpoints/mobile_detection/model2/pretrain_model2/inf_graph.pb/saved_model.pb. Will try again in 20 seconds
I0312 17:03:22.232804 139762821543680 eval_util.py:500] No model found in /srv/data_science/training/checkpoints/mobile_detection/model2/pretrain_model2/inf_graph.pb/saved_model.pb. Will try again in 20 seconds
INFO:tensorflow:Starting evaluation at 2020-03-12-14:03:42
I0312 17:03:42.252636 139762821543680 eval_util.py:496] Starting evaluation at 2020-03-12-14:03:42
INFO:tensorflow:No model found in /srv/data_science/training/checkpoints/mobile_detection/model2/pretrain_model2/inf_graph.pb/saved_model.pb. Will try again in 20 seconds
I0312 17:03:42.253182 139762821543680 eval_util.py:500] No model found in /srv/data_science/training/checkpoints/mobile_detection/model2/pretrain_model2/inf_graph.pb/saved_model.pb. Will try again in 20 seconds
INFO:tensorflow:Starting evaluation at 2020-03-12-14:04:02
I0312 17:04:02.252618 139762821543680 eval_util.py:496] Starting evaluation at 2020-03-12-14:04:02
INFO:tensorflow:No model found in /srv/data_science/training/checkpoints/mobile_detection/model2/pretrain_model2/inf_graph.pb/saved_model.pb. Will try again in 20 seconds
I0312 17:04:02.252809 139762821543680 eval_util.py:500] No model found in /srv/data_science/training/checkpoints/mobile_detection/model2/pretrain_model2/inf_graph.pb/saved_model.pb. Will try again in 20 seconds
INFO:tensorflow:Starting evaluation at 2020-03-12-14:04:22
I0312 17:04:22.272630 139762821543680 eval_util.py:496] Starting evaluation at 2020-03-12-14:04:22
INFO:tensorflow:No model found in /srv/data_science/training/checkpoints/mobile_detection/model2/pretrain_model2/inf_graph.pb/saved_model.pb. Will try again in 20 seconds
I0312 17:04:22.273090 139762821543680 eval_util.py:500] No model found in /srv/data_science/training/checkpoints/mobile_detection/model2/pretrain_model2/inf_graph.pb/saved_model.pb. Will try again in 20 seconds
INFO:tensorflow:Starting evaluation at 2020-03-12-14:04:42
I0312 17:04:42.274332 139762821543680 eval_util.py:496] Starting evaluation at 2020-03-12-14:04:42
INFO:tensorflow:No model found in /srv/data_science/training/checkpoints/mobile_detection/model2/pretrain_model2/inf_graph.pb/saved_model.pb. Will try again in 20 seconds
I0312 17:04:42.274521 139762821543680 eval_util.py:500] No model found in /srv/data_science/training/checkpoints/mobile_detection/model2/pretrain_model2/inf_graph.pb/saved_model.pb. Will try again in 20 seconds
INFO:tensorflow:Starting evaluation at 2020-03-12-14:05:02
I0312 17:05:02.292674 139762821543680 eval_util.py:496] Starting evaluation at 2020-03-12-14:05:02
INFO:tensorflow:No model found in /srv/data_science/training/checkpoints/mobile_detection/model2/pretrain_model2/inf_graph.pb/saved_model.pb. Will try again in 20 seconds
I0312 17:05:02.293350 139762821543680 eval_util.py:500] No model found in /srv/data_science/training/checkpoints/mobile_detection/model2/pretrain_model2/inf_graph.pb/saved_model.pb. Will try again in 20 seconds
INFO:tensorflow:Starting evaluation at 2020-03-12-14:05:22
I0312 17:05:22.312751 139762821543680 eval_util.py:496] Starting evaluation at 2020-03-12-14:05:22
INFO:tensorflow:No model found in /srv/data_science/training/checkpoints/mobile_detection/model2/pretrain_model2/inf_graph.pb/saved_model.pb. Will try again in 20 seconds
I0312 17:05:22.313606 139762821543680 eval_util.py:500] No model found in /srv/data_science/training/checkpoints/mobile_detection/model2/pretrain_model2/inf_graph.pb/saved_model.pb. Will try again in 20 seconds
INFO:tensorflow:Starting evaluation at 2020-03-12-14:05:42
I0312 17:05:42.332650 139762821543680 eval_util.py:496] Starting evaluation at 2020-03-12-14:05:42
INFO:tensorflow:No model found in /srv/data_science/training/checkpoints/mobile_detection/model2/pretrain_model2/inf_graph.pb/saved_model.pb. Will try again in 20 seconds
I0312 17:05:42.333328 139762821543680 eval_util.py:500] No model found in /srv/data_science/training/checkpoints/mobile_detection/model2/pretrain_model2/inf_graph.pb/saved_model.pb. Will try again in 20 seconds
INFO:tensorflow:Starting evaluation at 2020-03-12-14:06:02
I0312 17:06:02.352741 139762821543680 eval_util.py:496] Starting evaluation at 2020-03-12-14:06:02
INFO:tensorflow:No model found in /srv/data_science/training/checkpoints/mobile_detection/model2/pretrain_model2/inf_graph.pb/saved_model.pb. Will try again in 20 seconds
I0312 17:06:02.353570 139762821543680 eval_util.py:500] No model found in /srv/data_science/training/checkpoints/mobile_detection/model2/pretrain_model2/inf_graph.pb/saved_model.pb. Will try again in 20 seconds
INFO:tensorflow:Starting evaluation at 2020-03-12-14:06:22
I0312 17:06:22.372668 139762821543680 eval_util.py:496] Starting evaluation at 2020-03-12-14:06:22
INFO:tensorflow:No model found in /srv/data_science/training/checkpoints/mobile_detection/model2/pretrain_model2/inf_graph.pb/saved_model.pb. Will try again in 20 seconds
I0312 17:06:22.373330 139762821543680 eval_util.py:500] No model found in /srv/data_science/training/checkpoints/mobile_detection/model2/pretrain_model2/inf_graph.pb/saved_model.pb. Will try again in 20 seconds
INFO:tensorflow:Starting evaluation at 2020-03-12-14:06:42
I0312 17:06:42.392659 139762821543680 eval_util.py:496] Starting evaluation at 2020-03-12-14:06:42
INFO:tensorflow:No model found in /srv/data_science/training/checkpoints/mobile_detection/model2/pretrain_model2/inf_graph.pb/saved_model.pb. Will try again in 20 seconds
I0312 17:06:42.393370 139762821543680 eval_util.py:500] No model found in /srv/data_science/training/checkpoints/mobile_detection/model2/pretrain_model2/inf_graph.pb/saved_model.pb. Will try again in 20 seconds
INFO:tensorflow:Starting evaluation at 2020-03-12-14:07:02
I0312 17:07:02.412659 139762821543680 eval_util.py:496] Starting evaluation at 2020-03-12-14:07:02
INFO:tensorflow:No model found in /srv/data_science/training/checkpoints/mobile_detection/model2/pretrain_model2/inf_graph.pb/saved_model.pb. Will try again in 20 seconds
I0312 17:07:02.413292 139762821543680 eval_util.py:500] No model found in /srv/data_science/training/checkpoints/mobile_detection/model2/pretrain_model2/inf_graph.pb/saved_model.pb. Will try again in 20 seconds
INFO:tensorflow:Starting evaluation at 2020-03-12-14:07:22
I0312 17:07:22.432682 139762821543680 eval_util.py:496] Starting evaluation at 2020-03-12-14:07:22
INFO:tensorflow:No model found in /srv/data_science/training/checkpoints/mobile_detection/model2/pretrain_model2/inf_graph.pb/saved_model.pb. Will try again in 20 seconds
I0312 17:07:22.467600 139762821543680 eval_util.py:500] No model found in /srv/data_science/training/checkpoints/mobile_detection/model2/pretrain_model2/inf_graph.pb/saved_model.pb. Will try again in 20 seconds
INFO:tensorflow:Starting evaluation at 2020-03-12-14:07:42
I0312 17:07:42.452651 139762821543680 eval_util.py:496] Starting evaluation at 2020-03-12-14:07:42
INFO:tensorflow:No model found in /srv/data_science/training/checkpoints/mobile_detection/model2/pretrain_model2/inf_graph.pb/saved_model.pb. Will try again in 20 seconds
I0312 17:07:42.453229 139762821543680 eval_util.py:500] No model found in /srv/data_science/training/checkpoints/mobile_detection/model2/pretrain_model2/inf_graph.pb/saved_model.pb. Will try again in 20 seconds
INFO:tensorflow:Starting evaluation at 2020-03-12-14:08:02
I0312 17:08:02.472659 139762821543680 eval_util.py:496] Starting evaluation at 2020-03-12-14:08:02
INFO:tensorflow:No model found in /srv/data_science/training/checkpoints/mobile_detection/model2/pretrain_model2/inf_graph.pb/saved_model.pb. Will try again in 20 seconds
I0312 17:08:02.473270 139762821543680 eval_util.py:500] No model found in /srv/data_science/training/checkpoints/mobile_detection/model2/pretrain_model2/inf_graph.pb/saved_model.pb. Will try again in 20 seconds
INFO:tensorflow:Starting evaluation at 2020-03-12-14:08:22
I0312 17:08:22.492698 139762821543680 eval_util.py:496] Starting evaluation at 2020-03-12-14:08:22
INFO:tensorflow:No model found in /srv/data_science/training/checkpoints/mobile_detection/model2/pretrain_model2/inf_graph.pb/saved_model.pb. Will try again in 20 seconds
I0312 17:08:22.493527 139762821543680 eval_util.py:500] No model found in /srv/data_science/training/checkpoints/mobile_detection/model2/pretrain_model2/inf_graph.pb/saved_model.pb. Will try again in 20 seconds
INFO:tensorflow:Starting evaluation at 2020-03-12-14:08:42
I0312 17:08:42.492609 139762821543680 eval_util.py:496] Starting evaluation at 2020-03-12-14:08:42
INFO:tensorflow:No model found in /srv/data_science/training/checkpoints/mobile_detection/model2/pretrain_model2/inf_graph.pb/saved_model.pb. Will try again in 20 seconds
I0312 17:08:42.492799 139762821543680 eval_util.py:500] No model found in /srv/data_science/training/checkpoints/mobile_detection/model2/pretrain_model2/inf_graph.pb/saved_model.pb. Will try again in 20 seconds
INFO:tensorflow:Starting evaluation at 2020-03-12-14:09:02
I0312 17:09:02.512744 139762821543680 eval_util.py:496] Starting evaluation at 2020-03-12-14:09:02
INFO:tensorflow:No model found in /srv/data_science/training/checkpoints/mobile_detection/model2/pretrain_model2/inf_graph.pb/saved_model.pb. Will try again in 20 seconds
I0312 17:09:02.513750 139762821543680 eval_util.py:500] No model found in /srv/data_science/training/checkpoints/mobile_detection/model2/pretrain_model2/inf_graph.pb/saved_model.pb. Will try again in 20 seconds
INFO:tensorflow:Starting evaluation at 2020-03-12-14:09:22
I0312 17:09:22.532678 139762821543680 eval_util.py:496] Starting evaluation at 2020-03-12-14:09:22
INFO:tensorflow:No model found in /srv/data_science/training/checkpoints/mobile_detection/model2/pretrain_model2/inf_graph.pb/saved_model.pb. Will try again in 20 seconds
I0312 17:09:22.533507 139762821543680 eval_util.py:500] No model found in /srv/data_science/training/checkpoints/mobile_detection/model2/pretrain_model2/inf_graph.pb/saved_model.pb. Will try again in 20 seconds
INFO:tensorflow:Starting evaluation at 2020-03-12-14:09:42
I0312 17:09:42.552569 139762821543680 eval_util.py:496] Starting evaluation at 2020-03-12-14:09:42
INFO:tensorflow:No model found in /srv/data_science/training/checkpoints/mobile_detection/model2/pretrain_model2/inf_graph.pb/saved_model.pb. Will try again in 20 seconds
I0312 17:09:42.552761 139762821543680 eval_util.py:500] No model found in /srv/data_science/training/checkpoints/mobile_detection/model2/pretrain_model2/inf_graph.pb/saved_model.pb. Will try again in 20 seconds
INFO:tensorflow:Starting evaluation at 2020-03-12-14:10:02
I0312 17:10:02.572698 139762821543680 eval_util.py:496] Starting evaluation at 2020-03-12-14:10:02
INFO:tensorflow:No model found in /srv/data_science/training/checkpoints/mobile_detection/model2/pretrain_model2/inf_graph.pb/saved_model.pb. Will try again in 20 seconds
I0312 17:10:02.573395 139762821543680 eval_util.py:500] No model found in /srv/data_science/training/checkpoints/mobile_detection/model2/pretrain_model2/inf_graph.pb/saved_model.pb. Will try again in 20 seconds
INFO:tensorflow:Starting evaluation at 2020-03-12-14:10:22
I0312 17:10:22.592525 139762821543680 eval_util.py:496] Starting evaluation at 2020-03-12-14:10:22
INFO:tensorflow:No model found in /srv/data_science/training/checkpoints/mobile_detection/model2/pretrain_model2/inf_graph.pb/saved_model.pb. Will try again in 20 seconds
I0312 17:10:22.592709 139762821543680 eval_util.py:500] No model found in /srv/data_science/training/checkpoints/mobile_detection/model2/pretrain_model2/inf_graph.pb/saved_model.pb. Will try again in 20 seconds
INFO:tensorflow:Starting evaluation at 2020-03-12-14:10:42
I0312 17:10:42.612625 139762821543680 eval_util.py:496] Starting evaluation at 2020-03-12-14:10:42
INFO:tensorflow:No model found in /srv/data_science/training/checkpoints/mobile_detection/model2/pretrain_model2/inf_graph.pb/saved_model.pb. Will try again in 20 seconds
I0312 17:10:42.649643 139762821543680 eval_util.py:500] No model found in /srv/data_science/training/checkpoints/mobile_detection/model2/pretrain_model2/inf_graph.pb/saved_model.pb. Will try again in 20 seconds
INFO:tensorflow:Starting evaluation at 2020-03-12-14:11:02
I0312 17:11:02.632694 139762821543680 eval_util.py:496] Starting evaluation at 2020-03-12-14:11:02
INFO:tensorflow:No model found in /srv/data_science/training/checkpoints/mobile_detection/model2/pretrain_model2/inf_graph.pb/saved_model.pb. Will try again in 20 seconds
I0312 17:11:02.634991 139762821543680 eval_util.py:500] No model found in /srv/data_science/training/checkpoints/mobile_detection/model2/pretrain_model2/inf_graph.pb/saved_model.pb. Will try again in 20 seconds
INFO:tensorflow:Starting evaluation at 2020-03-12-14:11:22
I0312 17:11:22.652785 139762821543680 eval_util.py:496] Starting evaluation at 2020-03-12-14:11:22
INFO:tensorflow:No model found in /srv/data_science/training/checkpoints/mobile_detection/model2/pretrain_model2/inf_graph.pb/saved_model.pb. Will try again in 20 seconds
I0312 17:11:22.653547 139762821543680 eval_util.py:500] No model found in /srv/data_science/training/checkpoints/mobile_detection/model2/pretrain_model2/inf_graph.pb/saved_model.pb. Will try again in 20 seconds
INFO:tensorflow:Starting evaluation at 2020-03-12-14:11:42
I0312 17:11:42.672717 139762821543680 eval_util.py:496] Starting evaluation at 2020-03-12-14:11:42
INFO:tensorflow:No model found in /srv/data_science/training/checkpoints/mobile_detection/model2/pretrain_model2/inf_graph.pb/saved_model.pb. Will try again in 20 seconds
I0312 17:11:42.673514 139762821543680 eval_util.py:500] No model found in /srv/data_science/training/checkpoints/mobile_detection/model2/pretrain_model2/inf_graph.pb/saved_model.pb. Will try again in 20 seconds
INFO:tensorflow:Starting evaluation at 2020-03-12-14:12:02
I0312 17:12:02.692634 139762821543680 eval_util.py:496] Starting evaluation at 2020-03-12-14:12:02
INFO:tensorflow:No model found in /srv/data_science/training/checkpoints/mobile_detection/model2/pretrain_model2/inf_graph.pb/saved_model.pb. Will try again in 20 seconds
I0312 17:12:02.693175 139762821543680 eval_util.py:500] No model found in /srv/data_science/training/checkpoints/mobile_detection/model2/pretrain_model2/inf_graph.pb/saved_model.pb. Will try again in 20 seconds
INFO:tensorflow:Starting evaluation at 2020-03-12-14:12:22
I0312 17:12:22.712712 139762821543680 eval_util.py:496] Starting evaluation at 2020-03-12-14:12:22
INFO:tensorflow:No model found in /srv/data_science/training/checkpoints/mobile_detection/model2/pretrain_model2/inf_graph.pb/saved_model.pb. Will try again in 20 seconds
I0312 17:12:22.713603 139762821543680 eval_util.py:500] No model found in /srv/data_science/training/checkpoints/mobile_detection/model2/pretrain_model2/inf_graph.pb/saved_model.pb. Will try again in 20 seconds
INFO:tensorflow:Starting evaluation at 2020-03-12-14:12:42
I0312 17:12:42.730109 139762821543680 eval_util.py:496] Starting evaluation at 2020-03-12-14:12:42
INFO:tensorflow:No model found in /srv/data_science/training/checkpoints/mobile_detection/model2/pretrain_model2/inf_graph.pb/saved_model.pb. Will try again in 20 seconds
I0312 17:12:42.730298 139762821543680 eval_util.py:500] No model found in /srv/data_science/training/checkpoints/mobile_detection/model2/pretrain_model2/inf_graph.pb/saved_model.pb. Will try again in 20 seconds
INFO:tensorflow:Starting evaluation at 2020-03-12-14:13:02
I0312 17:13:02.748622 139762821543680 eval_util.py:496] Starting evaluation at 2020-03-12-14:13:02
INFO:tensorflow:No model found in /srv/data_science/training/checkpoints/mobile_detection/model2/pretrain_model2/inf_graph.pb/saved_model.pb. Will try again in 20 seconds
I0312 17:13:02.749222 139762821543680 eval_util.py:500] No model found in /srv/data_science/training/checkpoints/mobile_detection/model2/pretrain_model2/inf_graph.pb/saved_model.pb. Will try again in 20 seconds
INFO:tensorflow:Starting evaluation at 2020-03-12-14:13:22
I0312 17:13:22.768732 139762821543680 eval_util.py:496] Starting evaluation at 2020-03-12-14:13:22
INFO:tensorflow:No model found in /srv/data_science/training/checkpoints/mobile_detection/model2/pretrain_model2/inf_graph.pb/saved_model.pb. Will try again in 20 seconds
I0312 17:13:22.769558 139762821543680 eval_util.py:500] No model found in /srv/data_science/training/checkpoints/mobile_detection/model2/pretrain_model2/inf_graph.pb/saved_model.pb. Will try again in 20 seconds
INFO:tensorflow:Starting evaluation at 2020-03-12-14:13:42
I0312 17:13:42.788703 139762821543680 eval_util.py:496] Starting evaluation at 2020-03-12-14:13:42
INFO:tensorflow:No model found in /srv/data_science/training/checkpoints/mobile_detection/model2/pretrain_model2/inf_graph.pb/saved_model.pb. Will try again in 20 seconds
I0312 17:13:42.789403 139762821543680 eval_util.py:500] No model found in /srv/data_science/training/checkpoints/mobile_detection/model2/pretrain_model2/inf_graph.pb/saved_model.pb. Will try again in 20 seconds
INFO:tensorflow:Starting evaluation at 2020-03-12-14:14:02
I0312 17:14:02.808673 139762821543680 eval_util.py:496] Starting evaluation at 2020-03-12-14:14:02
INFO:tensorflow:No model found in /srv/data_science/training/checkpoints/mobile_detection/model2/pretrain_model2/inf_graph.pb/saved_model.pb. Will try again in 20 seconds
I0312 17:14:02.809421 139762821543680 eval_util.py:500] No model found in /srv/data_science/training/checkpoints/mobile_detection/model2/pretrain_model2/inf_graph.pb/saved_model.pb. Will try again in 20 seconds
INFO:tensorflow:Starting evaluation at 2020-03-12-14:14:22
I0312 17:14:22.828680 139762821543680 eval_util.py:496] Starting evaluation at 2020-03-12-14:14:22
INFO:tensorflow:No model found in /srv/data_science/training/checkpoints/mobile_detection/model2/pretrain_model2/inf_graph.pb/saved_model.pb. Will try again in 20 seconds
I0312 17:14:22.829358 139762821543680 eval_util.py:500] No model found in /srv/data_science/training/checkpoints/mobile_detection/model2/pretrain_model2/inf_graph.pb/saved_model.pb. Will try again in 20 seconds
INFO:tensorflow:Starting evaluation at 2020-03-12-14:14:42
I0312 17:14:42.848590 139762821543680 eval_util.py:496] Starting evaluation at 2020-03-12-14:14:42
INFO:tensorflow:No model found in /srv/data_science/training/checkpoints/mobile_detection/model2/pretrain_model2/inf_graph.pb/saved_model.pb. Will try again in 20 seconds
I0312 17:14:42.867073 139762821543680 eval_util.py:500] No model found in /srv/data_science/training/checkpoints/mobile_detection/model2/pretrain_model2/inf_graph.pb/saved_model.pb. Will try again in 20 seconds
INFO:tensorflow:Starting evaluation at 2020-03-12-14:15:02
I0312 17:15:02.868698 139762821543680 eval_util.py:496] Starting evaluation at 2020-03-12-14:15:02
INFO:tensorflow:No model found in /srv/data_science/training/checkpoints/mobile_detection/model2/pretrain_model2/inf_graph.pb/saved_model.pb. Will try again in 20 seconds
I0312 17:15:02.869376 139762821543680 eval_util.py:500] No model found in /srv/data_science/training/checkpoints/mobile_detection/model2/pretrain_model2/inf_graph.pb/saved_model.pb. Will try again in 20 seconds
INFO:tensorflow:Starting evaluation at 2020-03-12-14:15:22
I0312 17:15:22.888638 139762821543680 eval_util.py:496] Starting evaluation at 2020-03-12-14:15:22
INFO:tensorflow:No model found in /srv/data_science/training/checkpoints/mobile_detection/model2/pretrain_model2/inf_graph.pb/saved_model.pb. Will try again in 20 seconds
I0312 17:15:22.889298 139762821543680 eval_util.py:500] No model found in /srv/data_science/training/checkpoints/mobile_detection/model2/pretrain_model2/inf_graph.pb/saved_model.pb. Will try again in 20 seconds
INFO:tensorflow:Starting evaluation at 2020-03-12-14:15:42
I0312 17:15:42.908522 139762821543680 eval_util.py:496] Starting evaluation at 2020-03-12-14:15:42
INFO:tensorflow:No model found in /srv/data_science/training/checkpoints/mobile_detection/model2/pretrain_model2/inf_graph.pb/saved_model.pb. Will try again in 20 seconds
I0312 17:15:42.908712 139762821543680 eval_util.py:500] No model found in /srv/data_science/training/checkpoints/mobile_detection/model2/pretrain_model2/inf_graph.pb/saved_model.pb. Will try again in 20 seconds
INFO:tensorflow:Starting evaluation at 2020-03-12-14:16:02
I0312 17:16:02.928706 139762821543680 eval_util.py:496] Starting evaluation at 2020-03-12-14:16:02
INFO:tensorflow:No model found in /srv/data_science/training/checkpoints/mobile_detection/model2/pretrain_model2/inf_graph.pb/saved_model.pb. Will try again in 20 seconds
I0312 17:16:02.929430 139762821543680 eval_util.py:500] No model found in /srv/data_science/training/checkpoints/mobile_detection/model2/pretrain_model2/inf_graph.pb/saved_model.pb. Will try again in 20 seconds
INFO:tensorflow:Starting evaluation at 2020-03-12-14:16:22
I0312 17:16:22.948687 139762821543680 eval_util.py:496] Starting evaluation at 2020-03-12-14:16:22
INFO:tensorflow:No model found in /srv/data_science/training/checkpoints/mobile_detection/model2/pretrain_model2/inf_graph.pb/saved_model.pb. Will try again in 20 seconds
I0312 17:16:22.949488 139762821543680 eval_util.py:500] No model found in /srv/data_science/training/checkpoints/mobile_detection/model2/pretrain_model2/inf_graph.pb/saved_model.pb. Will try again in 20 seconds
INFO:tensorflow:Starting evaluation at 2020-03-12-14:16:42
I0312 17:16:42.968691 139762821543680 eval_util.py:496] Starting evaluation at 2020-03-12-14:16:42
INFO:tensorflow:No model found in /srv/data_science/training/checkpoints/mobile_detection/model2/pretrain_model2/inf_graph.pb/saved_model.pb. Will try again in 20 seconds
I0312 17:16:42.969450 139762821543680 eval_util.py:500] No model found in /srv/data_science/training/checkpoints/mobile_detection/model2/pretrain_model2/inf_graph.pb/saved_model.pb. Will try again in 20 seconds
INFO:tensorflow:Starting evaluation at 2020-03-12-14:17:02
I0312 17:17:02.988522 139762821543680 eval_util.py:496] Starting evaluation at 2020-03-12-14:17:02
INFO:tensorflow:No model found in /srv/data_science/training/checkpoints/mobile_detection/model2/pretrain_model2/inf_graph.pb/saved_model.pb. Will try again in 20 seconds
I0312 17:17:02.988718 139762821543680 eval_util.py:500] No model found in /srv/data_science/training/checkpoints/mobile_detection/model2/pretrain_model2/inf_graph.pb/saved_model.pb. Will try again in 20 seconds
INFO:tensorflow:Starting evaluation at 2020-03-12-14:17:23
I0312 17:17:23.008681 139762821543680 eval_util.py:496] Starting evaluation at 2020-03-12-14:17:23
INFO:tensorflow:No model found in /srv/data_science/training/checkpoints/mobile_detection/model2/pretrain_model2/inf_graph.pb/saved_model.pb. Will try again in 20 seconds
I0312 17:17:23.009528 139762821543680 eval_util.py:500] No model found in /srv/data_science/training/checkpoints/mobile_detection/model2/pretrain_model2/inf_graph.pb/saved_model.pb. Will try again in 20 seconds
INFO:tensorflow:Starting evaluation at 2020-03-12-14:17:43
I0312 17:17:43.025123 139762821543680 eval_util.py:496] Starting evaluation at 2020-03-12-14:17:43
INFO:tensorflow:No model found in /srv/data_science/training/checkpoints/mobile_detection/model2/pretrain_model2/inf_graph.pb/saved_model.pb. Will try again in 20 seconds
I0312 17:17:43.025313 139762821543680 eval_util.py:500] No model found in /srv/data_science/training/checkpoints/mobile_detection/model2/pretrain_model2/inf_graph.pb/saved_model.pb. Will try again in 20 seconds
INFO:tensorflow:Starting evaluation at 2020-03-12-14:18:03
I0312 17:18:03.044653 139762821543680 eval_util.py:496] Starting evaluation at 2020-03-12-14:18:03
INFO:tensorflow:No model found in /srv/data_science/training/checkpoints/mobile_detection/model2/pretrain_model2/inf_graph.pb/saved_model.pb. Will try again in 20 seconds
I0312 17:18:03.045240 139762821543680 eval_util.py:500] No model found in /srv/data_science/training/checkpoints/mobile_detection/model2/pretrain_model2/inf_graph.pb/saved_model.pb. Will try again in 20 seconds
INFO:tensorflow:Starting evaluation at 2020-03-12-14:18:23
I0312 17:18:23.064704 139762821543680 eval_util.py:496] Starting evaluation at 2020-03-12-14:18:23
INFO:tensorflow:No model found in /srv/data_science/training/checkpoints/mobile_detection/model2/pretrain_model2/inf_graph.pb/saved_model.pb. Will try again in 20 seconds
I0312 17:18:23.065373 139762821543680 eval_util.py:500] No model found in /srv/data_science/training/checkpoints/mobile_detection/model2/pretrain_model2/inf_graph.pb/saved_model.pb. Will try again in 20 seconds
INFO:tensorflow:Starting evaluation at 2020-03-12-14:18:43
I0312 17:18:43.084607 139762821543680 eval_util.py:496] Starting evaluation at 2020-03-12-14:18:43
INFO:tensorflow:No model found in /srv/data_science/training/checkpoints/mobile_detection/model2/pretrain_model2/inf_graph.pb/saved_model.pb. Will try again in 20 seconds
I0312 17:18:43.084798 139762821543680 eval_util.py:500] No model found in /srv/data_science/training/checkpoints/mobile_detection/model2/pretrain_model2/inf_graph.pb/saved_model.pb. Will try again in 20 seconds
INFO:tensorflow:Starting evaluation at 2020-03-12-14:19:03
I0312 17:19:03.104622 139762821543680 eval_util.py:496] Starting evaluation at 2020-03-12-14:19:03
INFO:tensorflow:No model found in /srv/data_science/training/checkpoints/mobile_detection/model2/pretrain_model2/inf_graph.pb/saved_model.pb. Will try again in 20 seconds
I0312 17:19:03.104800 139762821543680 eval_util.py:500] No model found in /srv/data_science/training/checkpoints/mobile_detection/model2/pretrain_model2/inf_graph.pb/saved_model.pb. Will try again in 20 seconds
INFO:tensorflow:Starting evaluation at 2020-03-12-14:19:23
I0312 17:19:23.124547 139762821543680 eval_util.py:496] Starting evaluation at 2020-03-12-14:19:23
INFO:tensorflow:No model found in /srv/data_science/training/checkpoints/mobile_detection/model2/pretrain_model2/inf_graph.pb/saved_model.pb. Will try again in 20 seconds
I0312 17:19:23.124830 139762821543680 eval_util.py:500] No model found in /srv/data_science/training/checkpoints/mobile_detection/model2/pretrain_model2/inf_graph.pb/saved_model.pb. Will try again in 20 seconds
INFO:tensorflow:Starting evaluation at 2020-03-12-14:19:43
I0312 17:19:43.152690 139762821543680 eval_util.py:496] Starting evaluation at 2020-03-12-14:19:43
INFO:tensorflow:No model found in /srv/data_science/training/checkpoints/mobile_detection/model2/pretrain_model2/inf_graph.pb/saved_model.pb. Will try again in 20 seconds
I0312 17:19:43.180374 139762821543680 eval_util.py:500] No model found in /srv/data_science/training/checkpoints/mobile_detection/model2/pretrain_model2/inf_graph.pb/saved_model.pb. Will try again in 20 seconds
INFO:tensorflow:Starting evaluation at 2020-03-12-14:20:03
I0312 17:20:03.152577 139762821543680 eval_util.py:496] Starting evaluation at 2020-03-12-14:20:03
INFO:tensorflow:No model found in /srv/data_science/training/checkpoints/mobile_detection/model2/pretrain_model2/inf_graph.pb/saved_model.pb. Will try again in 20 seconds
I0312 17:20:03.152767 139762821543680 eval_util.py:500] No model found in /srv/data_science/training/checkpoints/mobile_detection/model2/pretrain_model2/inf_graph.pb/saved_model.pb. Will try again in 20 seconds
INFO:tensorflow:Starting evaluation at 2020-03-12-14:20:23
I0312 17:20:23.172752 139762821543680 eval_util.py:496] Starting evaluation at 2020-03-12-14:20:23
INFO:tensorflow:No model found in /srv/data_science/training/checkpoints/mobile_detection/model2/pretrain_model2/inf_graph.pb/saved_model.pb. Will try again in 20 seconds
I0312 17:20:23.173423 139762821543680 eval_util.py:500] No model found in /srv/data_science/training/checkpoints/mobile_detection/model2/pretrain_model2/inf_graph.pb/saved_model.pb. Will try again in 20 seconds
INFO:tensorflow:Starting evaluation at 2020-03-12-14:20:43
I0312 17:20:43.192675 139762821543680 eval_util.py:496] Starting evaluation at 2020-03-12-14:20:43
INFO:tensorflow:No model found in /srv/data_science/training/checkpoints/mobile_detection/model2/pretrain_model2/inf_graph.pb/saved_model.pb. Will try again in 20 seconds
I0312 17:20:43.193468 139762821543680 eval_util.py:500] No model found in /srv/data_science/training/checkpoints/mobile_detection/model2/pretrain_model2/inf_graph.pb/saved_model.pb. Will try again in 20 seconds
INFO:tensorflow:Starting evaluation at 2020-03-12-14:21:03
I0312 17:21:03.212579 139762821543680 eval_util.py:496] Starting evaluation at 2020-03-12-14:21:03
INFO:tensorflow:No model found in /srv/data_science/training/checkpoints/mobile_detection/model2/pretrain_model2/inf_graph.pb/saved_model.pb. Will try again in 20 seconds
I0312 17:21:03.212809 139762821543680 eval_util.py:500] No model found in /srv/data_science/training/checkpoints/mobile_detection/model2/pretrain_model2/inf_graph.pb/saved_model.pb. Will try again in 20 seconds
INFO:tensorflow:Starting evaluation at 2020-03-12-14:21:23
I0312 17:21:23.232698 139762821543680 eval_util.py:496] Starting evaluation at 2020-03-12-14:21:23
INFO:tensorflow:No model found in /srv/data_science/training/checkpoints/mobile_detection/model2/pretrain_model2/inf_graph.pb/saved_model.pb. Will try again in 20 seconds
I0312 17:21:23.233446 139762821543680 eval_util.py:500] No model found in /srv/data_science/training/checkpoints/mobile_detection/model2/pretrain_model2/inf_graph.pb/saved_model.pb. Will try again in 20 seconds
INFO:tensorflow:Starting evaluation at 2020-03-12-14:21:43
I0312 17:21:43.252649 139762821543680 eval_util.py:496] Starting evaluation at 2020-03-12-14:21:43
INFO:tensorflow:No model found in /srv/data_science/training/checkpoints/mobile_detection/model2/pretrain_model2/inf_graph.pb/saved_model.pb. Will try again in 20 seconds
I0312 17:21:43.253201 139762821543680 eval_util.py:500] No model found in /srv/data_science/training/checkpoints/mobile_detection/model2/pretrain_model2/inf_graph.pb/saved_model.pb. Will try again in 20 seconds
INFO:tensorflow:Starting evaluation at 2020-03-12-14:22:03
I0312 17:22:03.272668 139762821543680 eval_util.py:496] Starting evaluation at 2020-03-12-14:22:03
INFO:tensorflow:No model found in /srv/data_science/training/checkpoints/mobile_detection/model2/pretrain_model2/inf_graph.pb/saved_model.pb. Will try again in 20 seconds
I0312 17:22:03.298988 139762821543680 eval_util.py:500] No model found in /srv/data_science/training/checkpoints/mobile_detection/model2/pretrain_model2/inf_graph.pb/saved_model.pb. Will try again in 20 seconds
INFO:tensorflow:Starting evaluation at 2020-03-12-14:22:23
I0312 17:22:23.292650 139762821543680 eval_util.py:496] Starting evaluation at 2020-03-12-14:22:23
INFO:tensorflow:No model found in /srv/data_science/training/checkpoints/mobile_detection/model2/pretrain_model2/inf_graph.pb/saved_model.pb. Will try again in 20 seconds
I0312 17:22:23.293215 139762821543680 eval_util.py:500] No model found in /srv/data_science/training/checkpoints/mobile_detection/model2/pretrain_model2/inf_graph.pb/saved_model.pb. Will try again in 20 seconds
INFO:tensorflow:Starting evaluation at 2020-03-12-14:22:43
I0312 17:22:43.312665 139762821543680 eval_util.py:496] Starting evaluation at 2020-03-12-14:22:43
INFO:tensorflow:No model found in /srv/data_science/training/checkpoints/mobile_detection/model2/pretrain_model2/inf_graph.pb/saved_model.pb. Will try again in 20 seconds
I0312 17:22:43.313302 139762821543680 eval_util.py:500] No model found in /srv/data_science/training/checkpoints/mobile_detection/model2/pretrain_model2/inf_graph.pb/saved_model.pb. Will try again in 20 seconds
INFO:tensorflow:Starting evaluation at 2020-03-12-14:23:03
I0312 17:23:03.329290 139762821543680 eval_util.py:496] Starting evaluation at 2020-03-12-14:23:03
INFO:tensorflow:No model found in /srv/data_science/training/checkpoints/mobile_detection/model2/pretrain_model2/inf_graph.pb/saved_model.pb. Will try again in 20 seconds
I0312 17:23:03.329486 139762821543680 eval_util.py:500] No model found in /srv/data_science/training/checkpoints/mobile_detection/model2/pretrain_model2/inf_graph.pb/saved_model.pb. Will try again in 20 seconds
INFO:tensorflow:Starting evaluation at 2020-03-12-14:23:23
I0312 17:23:23.348662 139762821543680 eval_util.py:496] Starting evaluation at 2020-03-12-14:23:23
INFO:tensorflow:No model found in /srv/data_science/training/checkpoints/mobile_detection/model2/pretrain_model2/inf_graph.pb/saved_model.pb. Will try again in 20 seconds
I0312 17:23:23.349297 139762821543680 eval_util.py:500] No model found in /srv/data_science/training/checkpoints/mobile_detection/model2/pretrain_model2/inf_graph.pb/saved_model.pb. Will try again in 20 seconds
INFO:tensorflow:Starting evaluation at 2020-03-12-14:23:43
I0312 17:23:43.368660 139762821543680 eval_util.py:496] Starting evaluation at 2020-03-12-14:23:43
INFO:tensorflow:No model found in /srv/data_science/training/checkpoints/mobile_detection/model2/pretrain_model2/inf_graph.pb/saved_model.pb. Will try again in 20 seconds
I0312 17:23:43.369333 139762821543680 eval_util.py:500] No model found in /srv/data_science/training/checkpoints/mobile_detection/model2/pretrain_model2/inf_graph.pb/saved_model.pb. Will try again in 20 seconds
INFO:tensorflow:Starting evaluation at 2020-03-12-14:24:03
I0312 17:24:03.388640 139762821543680 eval_util.py:496] Starting evaluation at 2020-03-12-14:24:03
INFO:tensorflow:No model found in /srv/data_science/training/checkpoints/mobile_detection/model2/pretrain_model2/inf_graph.pb/saved_model.pb. Will try again in 20 seconds
I0312 17:24:03.389183 139762821543680 eval_util.py:500] No model found in /srv/data_science/training/checkpoints/mobile_detection/model2/pretrain_model2/inf_graph.pb/saved_model.pb. Will try again in 20 seconds
INFO:tensorflow:Starting evaluation at 2020-03-12-14:24:23
I0312 17:24:23.408652 139762821543680 eval_util.py:496] Starting evaluation at 2020-03-12-14:24:23
INFO:tensorflow:No model found in /srv/data_science/training/checkpoints/mobile_detection/model2/pretrain_model2/inf_graph.pb/saved_model.pb. Will try again in 20 seconds
I0312 17:24:23.409387 139762821543680 eval_util.py:500] No model found in /srv/data_science/training/checkpoints/mobile_detection/model2/pretrain_model2/inf_graph.pb/saved_model.pb. Will try again in 20 seconds
INFO:tensorflow:Starting evaluation at 2020-03-12-14:24:43
I0312 17:24:43.428694 139762821543680 eval_util.py:496] Starting evaluation at 2020-03-12-14:24:43
INFO:tensorflow:No model found in /srv/data_science/training/checkpoints/mobile_detection/model2/pretrain_model2/inf_graph.pb/saved_model.pb. Will try again in 20 seconds
I0312 17:24:43.429404 139762821543680 eval_util.py:500] No model found in /srv/data_science/training/checkpoints/mobile_detection/model2/pretrain_model2/inf_graph.pb/saved_model.pb. Will try again in 20 seconds
INFO:tensorflow:Starting evaluation at 2020-03-12-14:25:03
I0312 17:25:03.448704 139762821543680 eval_util.py:496] Starting evaluation at 2020-03-12-14:25:03
INFO:tensorflow:No model found in /srv/data_science/training/checkpoints/mobile_detection/model2/pretrain_model2/inf_graph.pb/saved_model.pb. Will try again in 20 seconds
I0312 17:25:03.449309 139762821543680 eval_util.py:500] No model found in /srv/data_science/training/checkpoints/mobile_detection/model2/pretrain_model2/inf_graph.pb/saved_model.pb. Will try again in 20 seconds
INFO:tensorflow:Starting evaluation at 2020-03-12-14:25:23
I0312 17:25:23.473143 139762821543680 eval_util.py:496] Starting evaluation at 2020-03-12-14:25:23
INFO:tensorflow:No model found in /srv/data_science/training/checkpoints/mobile_detection/model2/pretrain_model2/inf_graph.pb/saved_model.pb. Will try again in 20 seconds
I0312 17:25:23.509003 139762821543680 eval_util.py:500] No model found in /srv/data_science/training/checkpoints/mobile_detection/model2/pretrain_model2/inf_graph.pb/saved_model.pb. Will try again in 20 seconds
INFO:tensorflow:Starting evaluation at 2020-03-12-14:25:43
I0312 17:25:43.492668 139762821543680 eval_util.py:496] Starting evaluation at 2020-03-12-14:25:43
INFO:tensorflow:No model found in /srv/data_science/training/checkpoints/mobile_detection/model2/pretrain_model2/inf_graph.pb/saved_model.pb. Will try again in 20 seconds
I0312 17:25:43.493388 139762821543680 eval_util.py:500] No model found in /srv/data_science/training/checkpoints/mobile_detection/model2/pretrain_model2/inf_graph.pb/saved_model.pb. Will try again in 20 seconds
INFO:tensorflow:Starting evaluation at 2020-03-12-14:26:03
I0312 17:26:03.512686 139762821543680 eval_util.py:496] Starting evaluation at 2020-03-12-14:26:03
INFO:tensorflow:No model found in /srv/data_science/training/checkpoints/mobile_detection/model2/pretrain_model2/inf_graph.pb/saved_model.pb. Will try again in 20 seconds
I0312 17:26:03.513334 139762821543680 eval_util.py:500] No model found in /srv/data_science/training/checkpoints/mobile_detection/model2/pretrain_model2/inf_graph.pb/saved_model.pb. Will try again in 20 seconds
INFO:tensorflow:Starting evaluation at 2020-03-12-14:26:23
I0312 17:26:23.532711 139762821543680 eval_util.py:496] Starting evaluation at 2020-03-12-14:26:23
INFO:tensorflow:No model found in /srv/data_science/training/checkpoints/mobile_detection/model2/pretrain_model2/inf_graph.pb/saved_model.pb. Will try again in 20 seconds
I0312 17:26:23.533428 139762821543680 eval_util.py:500] No model found in /srv/data_science/training/checkpoints/mobile_detection/model2/pretrain_model2/inf_graph.pb/saved_model.pb. Will try again in 20 seconds
INFO:tensorflow:Starting evaluation at 2020-03-12-14:26:43
I0312 17:26:43.552572 139762821543680 eval_util.py:496] Starting evaluation at 2020-03-12-14:26:43
INFO:tensorflow:No model found in /srv/data_science/training/checkpoints/mobile_detection/model2/pretrain_model2/inf_graph.pb/saved_model.pb. Will try again in 20 seconds
I0312 17:26:43.552753 139762821543680 eval_util.py:500] No model found in /srv/data_science/training/checkpoints/mobile_detection/model2/pretrain_model2/inf_graph.pb/saved_model.pb. Will try again in 20 seconds
INFO:tensorflow:Starting evaluation at 2020-03-12-14:27:03
I0312 17:27:03.572666 139762821543680 eval_util.py:496] Starting evaluation at 2020-03-12-14:27:03
INFO:tensorflow:No model found in /srv/data_science/training/checkpoints/mobile_detection/model2/pretrain_model2/inf_graph.pb/saved_model.pb. Will try again in 20 seconds
I0312 17:27:03.573362 139762821543680 eval_util.py:500] No model found in /srv/data_science/training/checkpoints/mobile_detection/model2/pretrain_model2/inf_graph.pb/saved_model.pb. Will try again in 20 seconds
INFO:tensorflow:Starting evaluation at 2020-03-12-14:27:23
I0312 17:27:23.592705 139762821543680 eval_util.py:496] Starting evaluation at 2020-03-12-14:27:23
INFO:tensorflow:No model found in /srv/data_science/training/checkpoints/mobile_detection/model2/pretrain_model2/inf_graph.pb/saved_model.pb. Will try again in 20 seconds
I0312 17:27:23.593423 139762821543680 eval_util.py:500] No model found in /srv/data_science/training/checkpoints/mobile_detection/model2/pretrain_model2/inf_graph.pb/saved_model.pb. Will try again in 20 seconds
INFO:tensorflow:Starting evaluation at 2020-03-12-14:27:43
I0312 17:27:43.612700 139762821543680 eval_util.py:496] Starting evaluation at 2020-03-12-14:27:43
INFO:tensorflow:No model found in /srv/data_science/training/checkpoints/mobile_detection/model2/pretrain_model2/inf_graph.pb/saved_model.pb. Will try again in 20 seconds
I0312 17:27:43.613446 139762821543680 eval_util.py:500] No model found in /srv/data_science/training/checkpoints/mobile_detection/model2/pretrain_model2/inf_graph.pb/saved_model.pb. Will try again in 20 seconds
INFO:tensorflow:Starting evaluation at 2020-03-12-14:28:03
I0312 17:28:03.632574 139762821543680 eval_util.py:496] Starting evaluation at 2020-03-12-14:28:03
INFO:tensorflow:No model found in /srv/data_science/training/checkpoints/mobile_detection/model2/pretrain_model2/inf_graph.pb/saved_model.pb. Will try again in 20 seconds
I0312 17:28:03.632758 139762821543680 eval_util.py:500] No model found in /srv/data_science/training/checkpoints/mobile_detection/model2/pretrain_model2/inf_graph.pb/saved_model.pb. Will try again in 20 seconds
INFO:tensorflow:Starting evaluation at 2020-03-12-14:28:23
I0312 17:28:23.652698 139762821543680 eval_util.py:496] Starting evaluation at 2020-03-12-14:28:23
INFO:tensorflow:No model found in /srv/data_science/training/checkpoints/mobile_detection/model2/pretrain_model2/inf_graph.pb/saved_model.pb. Will try again in 20 seconds
I0312 17:28:23.653348 139762821543680 eval_util.py:500] No model found in /srv/data_science/training/checkpoints/mobile_detection/model2/pretrain_model2/inf_graph.pb/saved_model.pb. Will try again in 20 seconds
INFO:tensorflow:Starting evaluation at 2020-03-12-14:28:43
I0312 17:28:43.672696 139762821543680 eval_util.py:496] Starting evaluation at 2020-03-12-14:28:43
INFO:tensorflow:No model found in /srv/data_science/training/checkpoints/mobile_detection/model2/pretrain_model2/inf_graph.pb/saved_model.pb. Will try again in 20 seconds
I0312 17:28:43.673410 139762821543680 eval_util.py:500] No model found in /srv/data_science/training/checkpoints/mobile_detection/model2/pretrain_model2/inf_graph.pb/saved_model.pb. Will try again in 20 seconds
INFO:tensorflow:Starting evaluation at 2020-03-12-14:29:03
I0312 17:29:03.692582 139762821543680 eval_util.py:496] Starting evaluation at 2020-03-12-14:29:03
INFO:tensorflow:No model found in /srv/data_science/training/checkpoints/mobile_detection/model2/pretrain_model2/inf_graph.pb/saved_model.pb. Will try again in 20 seconds
I0312 17:29:03.692779 139762821543680 eval_util.py:500] No model found in /srv/data_science/training/checkpoints/mobile_detection/model2/pretrain_model2/inf_graph.pb/saved_model.pb. Will try again in 20 seconds
INFO:tensorflow:Starting evaluation at 2020-03-12-14:29:23
I0312 17:29:23.712535 139762821543680 eval_util.py:496] Starting evaluation at 2020-03-12-14:29:23
INFO:tensorflow:No model found in /srv/data_science/training/checkpoints/mobile_detection/model2/pretrain_model2/inf_graph.pb/saved_model.pb. Will try again in 20 seconds
I0312 17:29:23.712768 139762821543680 eval_util.py:500] No model found in /srv/data_science/training/checkpoints/mobile_detection/model2/pretrain_model2/inf_graph.pb/saved_model.pb. Will try again in 20 seconds
INFO:tensorflow:Starting evaluation at 2020-03-12-14:29:43
I0312 17:29:43.732689 139762821543680 eval_util.py:496] Starting evaluation at 2020-03-12-14:29:43
INFO:tensorflow:No model found in /srv/data_science/training/checkpoints/mobile_detection/model2/pretrain_model2/inf_graph.pb/saved_model.pb. Will try again in 20 seconds
I0312 17:29:43.759999 139762821543680 eval_util.py:500] No model found in /srv/data_science/training/checkpoints/mobile_detection/model2/pretrain_model2/inf_graph.pb/saved_model.pb. Will try again in 20 seconds
INFO:tensorflow:Starting evaluation at 2020-03-12-14:30:03
I0312 17:30:03.756513 139762821543680 eval_util.py:496] Starting evaluation at 2020-03-12-14:30:03
INFO:tensorflow:No model found in /srv/data_science/training/checkpoints/mobile_detection/model2/pretrain_model2/inf_graph.pb/saved_model.pb. Will try again in 20 seconds
I0312 17:30:03.757195 139762821543680 eval_util.py:500] No model found in /srv/data_science/training/checkpoints/mobile_detection/model2/pretrain_model2/inf_graph.pb/saved_model.pb. Will try again in 20 seconds
INFO:tensorflow:Starting evaluation at 2020-03-12-14:30:23
I0312 17:30:23.764817 139762821543680 eval_util.py:496] Starting evaluation at 2020-03-12-14:30:23
INFO:tensorflow:No model found in /srv/data_science/training/checkpoints/mobile_detection/model2/pretrain_model2/inf_graph.pb/saved_model.pb. Will try again in 20 seconds
I0312 17:30:23.765014 139762821543680 eval_util.py:500] No model found in /srv/data_science/training/checkpoints/mobile_detection/model2/pretrain_model2/inf_graph.pb/saved_model.pb. Will try again in 20 seconds
INFO:tensorflow:Starting evaluation at 2020-03-12-14:30:43
I0312 17:30:43.784658 139762821543680 eval_util.py:496] Starting evaluation at 2020-03-12-14:30:43
INFO:tensorflow:No model found in /srv/data_science/training/checkpoints/mobile_detection/model2/pretrain_model2/inf_graph.pb/saved_model.pb. Will try again in 20 seconds
I0312 17:30:43.785350 139762821543680 eval_util.py:500] No model found in /srv/data_science/training/checkpoints/mobile_detection/model2/pretrain_model2/inf_graph.pb/saved_model.pb. Will try again in 20 seconds
INFO:tensorflow:Starting evaluation at 2020-03-12-14:31:03
I0312 17:31:03.804718 139762821543680 eval_util.py:496] Starting evaluation at 2020-03-12-14:31:03
INFO:tensorflow:No model found in /srv/data_science/training/checkpoints/mobile_detection/model2/pretrain_model2/inf_graph.pb/saved_model.pb. Will try again in 20 seconds
I0312 17:31:03.805522 139762821543680 eval_util.py:500] No model found in /srv/data_science/training/checkpoints/mobile_detection/model2/pretrain_model2/inf_graph.pb/saved_model.pb. Will try again in 20 seconds
INFO:tensorflow:Starting evaluation at 2020-03-12-14:31:23
I0312 17:31:23.824581 139762821543680 eval_util.py:496] Starting evaluation at 2020-03-12-14:31:23
INFO:tensorflow:No model found in /srv/data_science/training/checkpoints/mobile_detection/model2/pretrain_model2/inf_graph.pb/saved_model.pb. Will try again in 20 seconds
I0312 17:31:23.824772 139762821543680 eval_util.py:500] No model found in /srv/data_science/training/checkpoints/mobile_detection/model2/pretrain_model2/inf_graph.pb/saved_model.pb. Will try again in 20 seconds
INFO:tensorflow:Starting evaluation at 2020-03-12-14:31:43
I0312 17:31:43.844705 139762821543680 eval_util.py:496] Starting evaluation at 2020-03-12-14:31:43
INFO:tensorflow:No model found in /srv/data_science/training/checkpoints/mobile_detection/model2/pretrain_model2/inf_graph.pb/saved_model.pb. Will try again in 20 seconds
I0312 17:31:43.845470 139762821543680 eval_util.py:500] No model found in /srv/data_science/training/checkpoints/mobile_detection/model2/pretrain_model2/inf_graph.pb/saved_model.pb. Will try again in 20 seconds
INFO:tensorflow:Starting evaluation at 2020-03-12-14:32:03
I0312 17:32:03.866365 139762821543680 eval_util.py:496] Starting evaluation at 2020-03-12-14:32:03
INFO:tensorflow:No model found in /srv/data_science/training/checkpoints/mobile_detection/model2/pretrain_model2/inf_graph.pb/saved_model.pb. Will try again in 20 seconds
I0312 17:32:03.867100 139762821543680 eval_util.py:500] No model found in /srv/data_science/training/checkpoints/mobile_detection/model2/pretrain_model2/inf_graph.pb/saved_model.pb. Will try again in 20 seconds
INFO:tensorflow:Starting evaluation at 2020-03-12-14:32:23
I0312 17:32:23.866219 139762821543680 eval_util.py:496] Starting evaluation at 2020-03-12-14:32:23
INFO:tensorflow:No model found in /srv/data_science/training/checkpoints/mobile_detection/model2/pretrain_model2/inf_graph.pb/saved_model.pb. Will try again in 20 seconds
I0312 17:32:23.866405 139762821543680 eval_util.py:500] No model found in /srv/data_science/training/checkpoints/mobile_detection/model2/pretrain_model2/inf_graph.pb/saved_model.pb. Will try again in 20 seconds
INFO:tensorflow:Starting evaluation at 2020-03-12-14:32:43
I0312 17:32:43.884701 139762821543680 eval_util.py:496] Starting evaluation at 2020-03-12-14:32:43
INFO:tensorflow:No model found in /srv/data_science/training/checkpoints/mobile_detection/model2/pretrain_model2/inf_graph.pb/saved_model.pb. Will try again in 20 seconds
I0312 17:32:43.885480 139762821543680 eval_util.py:500] No model found in /srv/data_science/training/checkpoints/mobile_detection/model2/pretrain_model2/inf_graph.pb/saved_model.pb. Will try again in 20 seconds
INFO:tensorflow:Starting evaluation at 2020-03-12-14:33:03
I0312 17:33:03.904622 139762821543680 eval_util.py:496] Starting evaluation at 2020-03-12-14:33:03
INFO:tensorflow:No model found in /srv/data_science/training/checkpoints/mobile_detection/model2/pretrain_model2/inf_graph.pb/saved_model.pb. Will try again in 20 seconds
I0312 17:33:03.905051 139762821543680 eval_util.py:500] No model found in /srv/data_science/training/checkpoints/mobile_detection/model2/pretrain_model2/inf_graph.pb/saved_model.pb. Will try again in 20 seconds
INFO:tensorflow:Starting evaluation at 2020-03-12-14:33:23
I0312 17:33:23.924682 139762821543680 eval_util.py:496] Starting evaluation at 2020-03-12-14:33:23
INFO:tensorflow:No model found in /srv/data_science/training/checkpoints/mobile_detection/model2/pretrain_model2/inf_graph.pb/saved_model.pb. Will try again in 20 seconds
I0312 17:33:23.925406 139762821543680 eval_util.py:500] No model found in /srv/data_science/training/checkpoints/mobile_detection/model2/pretrain_model2/inf_graph.pb/saved_model.pb. Will try again in 20 seconds
INFO:tensorflow:Starting evaluation at 2020-03-12-14:33:43
I0312 17:33:43.944663 139762821543680 eval_util.py:496] Starting evaluation at 2020-03-12-14:33:43
INFO:tensorflow:No model found in /srv/data_science/training/checkpoints/mobile_detection/model2/pretrain_model2/inf_graph.pb/saved_model.pb. Will try again in 20 seconds
I0312 17:33:43.945195 139762821543680 eval_util.py:500] No model found in /srv/data_science/training/checkpoints/mobile_detection/model2/pretrain_model2/inf_graph.pb/saved_model.pb. Will try again in 20 seconds
INFO:tensorflow:Starting evaluation at 2020-03-12-14:34:03
I0312 17:34:03.960158 139762821543680 eval_util.py:496] Starting evaluation at 2020-03-12-14:34:03
INFO:tensorflow:No model found in /srv/data_science/training/checkpoints/mobile_detection/model2/pretrain_model2/inf_graph.pb/saved_model.pb. Will try again in 20 seconds
I0312 17:34:03.960396 139762821543680 eval_util.py:500] No model found in /srv/data_science/training/checkpoints/mobile_detection/model2/pretrain_model2/inf_graph.pb/saved_model.pb. Will try again in 20 seconds
INFO:tensorflow:Starting evaluation at 2020-03-12-14:34:23
I0312 17:34:23.976709 139762821543680 eval_util.py:496] Starting evaluation at 2020-03-12-14:34:23
INFO:tensorflow:No model found in /srv/data_science/training/checkpoints/mobile_detection/model2/pretrain_model2/inf_graph.pb/saved_model.pb. Will try again in 20 seconds
I0312 17:34:23.977414 139762821543680 eval_util.py:500] No model found in /srv/data_science/training/checkpoints/mobile_detection/model2/pretrain_model2/inf_graph.pb/saved_model.pb. Will try again in 20 seconds
INFO:tensorflow:Starting evaluation at 2020-03-12-14:34:43
I0312 17:34:43.996674 139762821543680 eval_util.py:496] Starting evaluation at 2020-03-12-14:34:43
INFO:tensorflow:No model found in /srv/data_science/training/checkpoints/mobile_detection/model2/pretrain_model2/inf_graph.pb/saved_model.pb. Will try again in 20 seconds
I0312 17:34:43.997362 139762821543680 eval_util.py:500] No model found in /srv/data_science/training/checkpoints/mobile_detection/model2/pretrain_model2/inf_graph.pb/saved_model.pb. Will try again in 20 seconds
INFO:tensorflow:Starting evaluation at 2020-03-12-14:35:04
I0312 17:35:04.016692 139762821543680 eval_util.py:496] Starting evaluation at 2020-03-12-14:35:04
INFO:tensorflow:No model found in /srv/data_science/training/checkpoints/mobile_detection/model2/pretrain_model2/inf_graph.pb/saved_model.pb. Will try again in 20 seconds
I0312 17:35:04.017395 139762821543680 eval_util.py:500] No model found in /srv/data_science/training/checkpoints/mobile_detection/model2/pretrain_model2/inf_graph.pb/saved_model.pb. Will try again in 20 seconds
INFO:tensorflow:Starting evaluation at 2020-03-12-14:35:24
I0312 17:35:24.036647 139762821543680 eval_util.py:496] Starting evaluation at 2020-03-12-14:35:24
INFO:tensorflow:No model found in /srv/data_science/training/checkpoints/mobile_detection/model2/pretrain_model2/inf_graph.pb/saved_model.pb. Will try again in 20 seconds
I0312 17:35:24.037291 139762821543680 eval_util.py:500] No model found in /srv/data_science/training/checkpoints/mobile_detection/model2/pretrain_model2/inf_graph.pb/saved_model.pb. Will try again in 20 seconds
Traceback (most recent call last):
  File "ssd_mobilenet/object_detection/legacy/eval.py", line 143, in <module>
    tf.app.run()
  File "/home/agazade/.conda/envs/main/lib/python3.7/site-packages/tensorflow/python/platform/app.py", line 40, in run
    _run(main=main, argv=argv, flags_parser=_parse_flags_tolerate_undef)
  File "/home/agazade/.conda/envs/main/lib/python3.7/site-packages/absl/app.py", line 299, in run
    _run_main(main, args)
  File "/home/agazade/.conda/envs/main/lib/python3.7/site-packages/absl/app.py", line 250, in _run_main
    sys.exit(main(argv))
  File "/home/agazade/.conda/envs/main/lib/python3.7/site-packages/tensorflow/python/util/deprecation.py", line 324, in new_func
    return func(*args, **kwargs)
  File "ssd_mobilenet/object_detection/legacy/eval.py", line 139, in main
    graph_hook_fn=graph_rewriter_fn)
  File "/opt/agazade/data_science/training/code/mobile_detection/ssd_mobilenet/ssd_mobilenet/object_detection/legacy/evaluator.py", line 296, in evaluate
    eval_export_path=eval_config.export_path)
  File "/opt/agazade/data_science/training/code/mobile_detection/ssd_mobilenet/ssd_mobilenet/object_detection/eval_util.py", line 533, in repeated_checkpoint_run
    time.sleep(time_to_next_eval)
KeyboardInterrupt
