{
 "cells": [
  {
   "cell_type": "code",
   "execution_count": 4,
   "metadata": {},
   "outputs": [],
   "source": [
    "from pathlib import Path\n",
    "import os\n",
    "os.environ[\"CUDA_VISIBLE_DEVICES\"] = \"-1\""
   ]
  },
  {
   "cell_type": "code",
   "execution_count": 5,
   "metadata": {},
   "outputs": [
    {
     "name": "stdout",
     "output_type": "stream",
     "text": [
      "env: PYTHONPATH=/srv/data_science/libraries/python-libs/:ssd_mobilenet:ssd_mobilenet/slim:ssd_mobilenet:ssd_mobilenet/slim\n"
     ]
    }
   ],
   "source": [
    "path = %env PYTHONPATH\n",
    "%set_env PYTHONPATH=$path:ssd_mobilenet:ssd_mobilenet/slim"
   ]
  },
  {
   "cell_type": "code",
   "execution_count": 5,
   "metadata": {},
   "outputs": [],
   "source": [
    "model_dir = '/srv/data_science/training/checkpoints/mobile_detection/model2/pretrain_model2'\n",
    "model_dir_p = Path(model_dir)\n",
    "trained_checkpoint = str(model_dir_p / 'model.ckpt-397722')\n",
    "# output_directory = str(model_dir_p / 'inf_graph_noopt.pb')\n",
    "output_directory = str(model_dir_p / 'inf_graph.pb')\n",
    "config = '/srv/data_science/training/code/mobile_detection/ssd_mobilenet/ssd_mobilenet/configs/ssdlite_mobilenet_v3_large_1.config'"
   ]
  },
  {
   "cell_type": "code",
   "execution_count": 6,
   "metadata": {},
   "outputs": [],
   "source": [
    "model_dir = '/srv/data_science/training/checkpoints/mobile_detection/model3/pretrain_model1'\n",
    "model_dir_p = Path(model_dir)\n",
    "trained_checkpoint = str(model_dir_p / 'model.ckpt-399296')\n",
    "output_directory = str(model_dir_p / 'inf_graph.pb')\n",
    "config = '/srv/data_science/training/code/mobile_detection/ssd_mobilenet/ssd_mobilenet/configs/ssdlite_mobilenet_v3_large_2.config'"
   ]
  },
  {
   "cell_type": "code",
   "execution_count": 7,
   "metadata": {},
   "outputs": [
    {
     "name": "stdout",
     "output_type": "stream",
     "text": [
      "/home/agazade/.conda/envs/main/lib/python3.7/site-packages/tensorflow/python/framework/dtypes.py:516: FutureWarning: Passing (type, 1) or '1type' as a synonym of type is deprecated; in a future version of numpy, it will be understood as (type, (1,)) / '(1,)type'.\n",
      "  _np_qint8 = np.dtype([(\"qint8\", np.int8, 1)])\n",
      "/home/agazade/.conda/envs/main/lib/python3.7/site-packages/tensorflow/python/framework/dtypes.py:517: FutureWarning: Passing (type, 1) or '1type' as a synonym of type is deprecated; in a future version of numpy, it will be understood as (type, (1,)) / '(1,)type'.\n",
      "  _np_quint8 = np.dtype([(\"quint8\", np.uint8, 1)])\n",
      "/home/agazade/.conda/envs/main/lib/python3.7/site-packages/tensorflow/python/framework/dtypes.py:518: FutureWarning: Passing (type, 1) or '1type' as a synonym of type is deprecated; in a future version of numpy, it will be understood as (type, (1,)) / '(1,)type'.\n",
      "  _np_qint16 = np.dtype([(\"qint16\", np.int16, 1)])\n",
      "/home/agazade/.conda/envs/main/lib/python3.7/site-packages/tensorflow/python/framework/dtypes.py:519: FutureWarning: Passing (type, 1) or '1type' as a synonym of type is deprecated; in a future version of numpy, it will be understood as (type, (1,)) / '(1,)type'.\n",
      "  _np_quint16 = np.dtype([(\"quint16\", np.uint16, 1)])\n",
      "/home/agazade/.conda/envs/main/lib/python3.7/site-packages/tensorflow/python/framework/dtypes.py:520: FutureWarning: Passing (type, 1) or '1type' as a synonym of type is deprecated; in a future version of numpy, it will be understood as (type, (1,)) / '(1,)type'.\n",
      "  _np_qint32 = np.dtype([(\"qint32\", np.int32, 1)])\n",
      "/home/agazade/.conda/envs/main/lib/python3.7/site-packages/tensorflow/python/framework/dtypes.py:525: FutureWarning: Passing (type, 1) or '1type' as a synonym of type is deprecated; in a future version of numpy, it will be understood as (type, (1,)) / '(1,)type'.\n",
      "  np_resource = np.dtype([(\"resource\", np.ubyte, 1)])\n",
      "/home/agazade/.conda/envs/main/lib/python3.7/site-packages/tensorboard/compat/tensorflow_stub/dtypes.py:541: FutureWarning: Passing (type, 1) or '1type' as a synonym of type is deprecated; in a future version of numpy, it will be understood as (type, (1,)) / '(1,)type'.\n",
      "  _np_qint8 = np.dtype([(\"qint8\", np.int8, 1)])\n",
      "/home/agazade/.conda/envs/main/lib/python3.7/site-packages/tensorboard/compat/tensorflow_stub/dtypes.py:542: FutureWarning: Passing (type, 1) or '1type' as a synonym of type is deprecated; in a future version of numpy, it will be understood as (type, (1,)) / '(1,)type'.\n",
      "  _np_quint8 = np.dtype([(\"quint8\", np.uint8, 1)])\n",
      "/home/agazade/.conda/envs/main/lib/python3.7/site-packages/tensorboard/compat/tensorflow_stub/dtypes.py:543: FutureWarning: Passing (type, 1) or '1type' as a synonym of type is deprecated; in a future version of numpy, it will be understood as (type, (1,)) / '(1,)type'.\n",
      "  _np_qint16 = np.dtype([(\"qint16\", np.int16, 1)])\n",
      "/home/agazade/.conda/envs/main/lib/python3.7/site-packages/tensorboard/compat/tensorflow_stub/dtypes.py:544: FutureWarning: Passing (type, 1) or '1type' as a synonym of type is deprecated; in a future version of numpy, it will be understood as (type, (1,)) / '(1,)type'.\n",
      "  _np_quint16 = np.dtype([(\"quint16\", np.uint16, 1)])\n",
      "/home/agazade/.conda/envs/main/lib/python3.7/site-packages/tensorboard/compat/tensorflow_stub/dtypes.py:545: FutureWarning: Passing (type, 1) or '1type' as a synonym of type is deprecated; in a future version of numpy, it will be understood as (type, (1,)) / '(1,)type'.\n",
      "  _np_qint32 = np.dtype([(\"qint32\", np.int32, 1)])\n",
      "/home/agazade/.conda/envs/main/lib/python3.7/site-packages/tensorboard/compat/tensorflow_stub/dtypes.py:550: FutureWarning: Passing (type, 1) or '1type' as a synonym of type is deprecated; in a future version of numpy, it will be understood as (type, (1,)) / '(1,)type'.\n",
      "  np_resource = np.dtype([(\"resource\", np.ubyte, 1)])\n",
      "WARNING:tensorflow:From /opt/agazade/data_science/training/code/mobile_detection/ssd_mobilenet/ssd_mobilenet/slim/nets/mobilenet/mobilenet.py:399: The name tf.nn.avg_pool is deprecated. Please use tf.nn.avg_pool2d instead.\n",
      "\n",
      "WARNING:tensorflow:From ssd_mobilenet/object_detection/export_tflite_ssd_graph.py:146: The name tf.app.run is deprecated. Please use tf.compat.v1.app.run instead.\n",
      "\n",
      "WARNING:tensorflow:From ssd_mobilenet/object_detection/export_tflite_ssd_graph.py:136: The name tf.gfile.GFile is deprecated. Please use tf.io.gfile.GFile instead.\n",
      "\n",
      "W0319 21:01:12.887680 140193590601472 deprecation_wrapper.py:119] From ssd_mobilenet/object_detection/export_tflite_ssd_graph.py:136: The name tf.gfile.GFile is deprecated. Please use tf.io.gfile.GFile instead.\n",
      "\n",
      "WARNING:tensorflow:From /opt/agazade/data_science/training/code/mobile_detection/ssd_mobilenet/ssd_mobilenet/object_detection/export_tflite_ssd_graph_lib.py:195: The name tf.gfile.MakeDirs is deprecated. Please use tf.io.gfile.makedirs instead.\n",
      "\n",
      "W0319 21:01:12.890830 140193590601472 deprecation_wrapper.py:119] From /opt/agazade/data_science/training/code/mobile_detection/ssd_mobilenet/ssd_mobilenet/object_detection/export_tflite_ssd_graph_lib.py:195: The name tf.gfile.MakeDirs is deprecated. Please use tf.io.gfile.makedirs instead.\n",
      "\n",
      "WARNING:tensorflow:From /opt/agazade/data_science/training/code/mobile_detection/ssd_mobilenet/ssd_mobilenet/object_detection/export_tflite_ssd_graph_lib.py:239: The name tf.placeholder is deprecated. Please use tf.compat.v1.placeholder instead.\n",
      "\n",
      "W0319 21:01:12.891001 140193590601472 deprecation_wrapper.py:119] From /opt/agazade/data_science/training/code/mobile_detection/ssd_mobilenet/ssd_mobilenet/object_detection/export_tflite_ssd_graph_lib.py:239: The name tf.placeholder is deprecated. Please use tf.compat.v1.placeholder instead.\n",
      "\n",
      "WARNING:tensorflow:From /opt/agazade/data_science/training/code/mobile_detection/ssd_mobilenet/ssd_mobilenet/object_detection/meta_architectures/ssd_meta_arch.py:597: The name tf.variable_scope is deprecated. Please use tf.compat.v1.variable_scope instead.\n",
      "\n",
      "W0319 21:01:12.892710 140193590601472 deprecation_wrapper.py:119] From /opt/agazade/data_science/training/code/mobile_detection/ssd_mobilenet/ssd_mobilenet/object_detection/meta_architectures/ssd_meta_arch.py:597: The name tf.variable_scope is deprecated. Please use tf.compat.v1.variable_scope instead.\n",
      "\n",
      "WARNING:tensorflow:Entity <bound method Conv.call of <tensorflow.python.layers.convolutional.Conv2D object at 0x7f80faf4a7d0>> could not be transformed and will be executed as-is. Please report this to the AutgoGraph team. When filing the bug, set the verbosity to 10 (on Linux, `export AUTOGRAPH_VERBOSITY=10`) and attach the full output. Cause: converting <bound method Conv.call of <tensorflow.python.layers.convolutional.Conv2D object at 0x7f80faf4a7d0>>: AssertionError: Bad argument number for Name: 3, expecting 4\n",
      "W0319 21:01:12.938894 140193590601472 ag_logging.py:145] Entity <bound method Conv.call of <tensorflow.python.layers.convolutional.Conv2D object at 0x7f80faf4a7d0>> could not be transformed and will be executed as-is. Please report this to the AutgoGraph team. When filing the bug, set the verbosity to 10 (on Linux, `export AUTOGRAPH_VERBOSITY=10`) and attach the full output. Cause: converting <bound method Conv.call of <tensorflow.python.layers.convolutional.Conv2D object at 0x7f80faf4a7d0>>: AssertionError: Bad argument number for Name: 3, expecting 4\n",
      "WARNING:tensorflow:Entity <bound method Conv.call of <tensorflow.python.layers.convolutional.Conv2D object at 0x7f80faf4abd0>> could not be transformed and will be executed as-is. Please report this to the AutgoGraph team. When filing the bug, set the verbosity to 10 (on Linux, `export AUTOGRAPH_VERBOSITY=10`) and attach the full output. Cause: converting <bound method Conv.call of <tensorflow.python.layers.convolutional.Conv2D object at 0x7f80faf4abd0>>: AssertionError: Bad argument number for Name: 3, expecting 4\n",
      "W0319 21:01:13.012348 140193590601472 ag_logging.py:145] Entity <bound method Conv.call of <tensorflow.python.layers.convolutional.Conv2D object at 0x7f80faf4abd0>> could not be transformed and will be executed as-is. Please report this to the AutgoGraph team. When filing the bug, set the verbosity to 10 (on Linux, `export AUTOGRAPH_VERBOSITY=10`) and attach the full output. Cause: converting <bound method Conv.call of <tensorflow.python.layers.convolutional.Conv2D object at 0x7f80faf4abd0>>: AssertionError: Bad argument number for Name: 3, expecting 4\n",
      "WARNING:tensorflow:Entity <bound method Conv.call of <tensorflow.python.layers.convolutional.Conv2D object at 0x7f80fa5a2b90>> could not be transformed and will be executed as-is. Please report this to the AutgoGraph team. When filing the bug, set the verbosity to 10 (on Linux, `export AUTOGRAPH_VERBOSITY=10`) and attach the full output. Cause: converting <bound method Conv.call of <tensorflow.python.layers.convolutional.Conv2D object at 0x7f80fa5a2b90>>: AssertionError: Bad argument number for Name: 3, expecting 4\n",
      "W0319 21:01:13.067847 140193590601472 ag_logging.py:145] Entity <bound method Conv.call of <tensorflow.python.layers.convolutional.Conv2D object at 0x7f80fa5a2b90>> could not be transformed and will be executed as-is. Please report this to the AutgoGraph team. When filing the bug, set the verbosity to 10 (on Linux, `export AUTOGRAPH_VERBOSITY=10`) and attach the full output. Cause: converting <bound method Conv.call of <tensorflow.python.layers.convolutional.Conv2D object at 0x7f80fa5a2b90>>: AssertionError: Bad argument number for Name: 3, expecting 4\n",
      "WARNING:tensorflow:Entity <bound method Conv.call of <tensorflow.python.layers.convolutional.Conv2D object at 0x7f80fa5cee10>> could not be transformed and will be executed as-is. Please report this to the AutgoGraph team. When filing the bug, set the verbosity to 10 (on Linux, `export AUTOGRAPH_VERBOSITY=10`) and attach the full output. Cause: converting <bound method Conv.call of <tensorflow.python.layers.convolutional.Conv2D object at 0x7f80fa5cee10>>: AssertionError: Bad argument number for Name: 3, expecting 4\n",
      "W0319 21:01:13.137971 140193590601472 ag_logging.py:145] Entity <bound method Conv.call of <tensorflow.python.layers.convolutional.Conv2D object at 0x7f80fa5cee10>> could not be transformed and will be executed as-is. Please report this to the AutgoGraph team. When filing the bug, set the verbosity to 10 (on Linux, `export AUTOGRAPH_VERBOSITY=10`) and attach the full output. Cause: converting <bound method Conv.call of <tensorflow.python.layers.convolutional.Conv2D object at 0x7f80fa5cee10>>: AssertionError: Bad argument number for Name: 3, expecting 4\n",
      "WARNING:tensorflow:Entity <bound method Conv.call of <tensorflow.python.layers.convolutional.Conv2D object at 0x7f80fa5a4d90>> could not be transformed and will be executed as-is. Please report this to the AutgoGraph team. When filing the bug, set the verbosity to 10 (on Linux, `export AUTOGRAPH_VERBOSITY=10`) and attach the full output. Cause: converting <bound method Conv.call of <tensorflow.python.layers.convolutional.Conv2D object at 0x7f80fa5a4d90>>: AssertionError: Bad argument number for Name: 3, expecting 4\n",
      "W0319 21:01:13.192609 140193590601472 ag_logging.py:145] Entity <bound method Conv.call of <tensorflow.python.layers.convolutional.Conv2D object at 0x7f80fa5a4d90>> could not be transformed and will be executed as-is. Please report this to the AutgoGraph team. When filing the bug, set the verbosity to 10 (on Linux, `export AUTOGRAPH_VERBOSITY=10`) and attach the full output. Cause: converting <bound method Conv.call of <tensorflow.python.layers.convolutional.Conv2D object at 0x7f80fa5a4d90>>: AssertionError: Bad argument number for Name: 3, expecting 4\n",
      "WARNING:tensorflow:Entity <bound method Conv.call of <tensorflow.python.layers.convolutional.Conv2D object at 0x7f80fa5b7ed0>> could not be transformed and will be executed as-is. Please report this to the AutgoGraph team. When filing the bug, set the verbosity to 10 (on Linux, `export AUTOGRAPH_VERBOSITY=10`) and attach the full output. Cause: converting <bound method Conv.call of <tensorflow.python.layers.convolutional.Conv2D object at 0x7f80fa5b7ed0>>: AssertionError: Bad argument number for Name: 3, expecting 4\n",
      "W0319 21:01:13.262581 140193590601472 ag_logging.py:145] Entity <bound method Conv.call of <tensorflow.python.layers.convolutional.Conv2D object at 0x7f80fa5b7ed0>> could not be transformed and will be executed as-is. Please report this to the AutgoGraph team. When filing the bug, set the verbosity to 10 (on Linux, `export AUTOGRAPH_VERBOSITY=10`) and attach the full output. Cause: converting <bound method Conv.call of <tensorflow.python.layers.convolutional.Conv2D object at 0x7f80fa5b7ed0>>: AssertionError: Bad argument number for Name: 3, expecting 4\n",
      "WARNING:tensorflow:Entity <bound method Conv.call of <tensorflow.python.layers.convolutional.Conv2D object at 0x7f80fa499910>> could not be transformed and will be executed as-is. Please report this to the AutgoGraph team. When filing the bug, set the verbosity to 10 (on Linux, `export AUTOGRAPH_VERBOSITY=10`) and attach the full output. Cause: converting <bound method Conv.call of <tensorflow.python.layers.convolutional.Conv2D object at 0x7f80fa499910>>: AssertionError: Bad argument number for Name: 3, expecting 4\n",
      "W0319 21:01:13.365147 140193590601472 ag_logging.py:145] Entity <bound method Conv.call of <tensorflow.python.layers.convolutional.Conv2D object at 0x7f80fa499910>> could not be transformed and will be executed as-is. Please report this to the AutgoGraph team. When filing the bug, set the verbosity to 10 (on Linux, `export AUTOGRAPH_VERBOSITY=10`) and attach the full output. Cause: converting <bound method Conv.call of <tensorflow.python.layers.convolutional.Conv2D object at 0x7f80fa499910>>: AssertionError: Bad argument number for Name: 3, expecting 4\n",
      "WARNING:tensorflow:Entity <bound method Conv.call of <tensorflow.python.layers.convolutional.Conv2D object at 0x7f80fa4a0310>> could not be transformed and will be executed as-is. Please report this to the AutgoGraph team. When filing the bug, set the verbosity to 10 (on Linux, `export AUTOGRAPH_VERBOSITY=10`) and attach the full output. Cause: converting <bound method Conv.call of <tensorflow.python.layers.convolutional.Conv2D object at 0x7f80fa4a0310>>: AssertionError: Bad argument number for Name: 3, expecting 4\n",
      "W0319 21:01:13.439352 140193590601472 ag_logging.py:145] Entity <bound method Conv.call of <tensorflow.python.layers.convolutional.Conv2D object at 0x7f80fa4a0310>> could not be transformed and will be executed as-is. Please report this to the AutgoGraph team. When filing the bug, set the verbosity to 10 (on Linux, `export AUTOGRAPH_VERBOSITY=10`) and attach the full output. Cause: converting <bound method Conv.call of <tensorflow.python.layers.convolutional.Conv2D object at 0x7f80fa4a0310>>: AssertionError: Bad argument number for Name: 3, expecting 4\n",
      "WARNING:tensorflow:Entity <bound method Conv.call of <tensorflow.python.layers.convolutional.Conv2D object at 0x7f80fa4c3550>> could not be transformed and will be executed as-is. Please report this to the AutgoGraph team. When filing the bug, set the verbosity to 10 (on Linux, `export AUTOGRAPH_VERBOSITY=10`) and attach the full output. Cause: converting <bound method Conv.call of <tensorflow.python.layers.convolutional.Conv2D object at 0x7f80fa4c3550>>: AssertionError: Bad argument number for Name: 3, expecting 4\n",
      "W0319 21:01:13.490864 140193590601472 ag_logging.py:145] Entity <bound method Conv.call of <tensorflow.python.layers.convolutional.Conv2D object at 0x7f80fa4c3550>> could not be transformed and will be executed as-is. Please report this to the AutgoGraph team. When filing the bug, set the verbosity to 10 (on Linux, `export AUTOGRAPH_VERBOSITY=10`) and attach the full output. Cause: converting <bound method Conv.call of <tensorflow.python.layers.convolutional.Conv2D object at 0x7f80fa4c3550>>: AssertionError: Bad argument number for Name: 3, expecting 4\n",
      "WARNING:tensorflow:Entity <bound method Conv.call of <tensorflow.python.layers.convolutional.Conv2D object at 0x7f80fa4c3550>> could not be transformed and will be executed as-is. Please report this to the AutgoGraph team. When filing the bug, set the verbosity to 10 (on Linux, `export AUTOGRAPH_VERBOSITY=10`) and attach the full output. Cause: converting <bound method Conv.call of <tensorflow.python.layers.convolutional.Conv2D object at 0x7f80fa4c3550>>: AssertionError: Bad argument number for Name: 3, expecting 4\n",
      "W0319 21:01:13.537350 140193590601472 ag_logging.py:145] Entity <bound method Conv.call of <tensorflow.python.layers.convolutional.Conv2D object at 0x7f80fa4c3550>> could not be transformed and will be executed as-is. Please report this to the AutgoGraph team. When filing the bug, set the verbosity to 10 (on Linux, `export AUTOGRAPH_VERBOSITY=10`) and attach the full output. Cause: converting <bound method Conv.call of <tensorflow.python.layers.convolutional.Conv2D object at 0x7f80fa4c3550>>: AssertionError: Bad argument number for Name: 3, expecting 4\n",
      "WARNING:tensorflow:Entity <bound method Conv.call of <tensorflow.python.layers.convolutional.Conv2D object at 0x7f80fa481490>> could not be transformed and will be executed as-is. Please report this to the AutgoGraph team. When filing the bug, set the verbosity to 10 (on Linux, `export AUTOGRAPH_VERBOSITY=10`) and attach the full output. Cause: converting <bound method Conv.call of <tensorflow.python.layers.convolutional.Conv2D object at 0x7f80fa481490>>: AssertionError: Bad argument number for Name: 3, expecting 4\n",
      "W0319 21:01:13.592555 140193590601472 ag_logging.py:145] Entity <bound method Conv.call of <tensorflow.python.layers.convolutional.Conv2D object at 0x7f80fa481490>> could not be transformed and will be executed as-is. Please report this to the AutgoGraph team. When filing the bug, set the verbosity to 10 (on Linux, `export AUTOGRAPH_VERBOSITY=10`) and attach the full output. Cause: converting <bound method Conv.call of <tensorflow.python.layers.convolutional.Conv2D object at 0x7f80fa481490>>: AssertionError: Bad argument number for Name: 3, expecting 4\n",
      "WARNING:tensorflow:Entity <bound method Conv.call of <tensorflow.python.layers.convolutional.Conv2D object at 0x7f80fa227f10>> could not be transformed and will be executed as-is. Please report this to the AutgoGraph team. When filing the bug, set the verbosity to 10 (on Linux, `export AUTOGRAPH_VERBOSITY=10`) and attach the full output. Cause: converting <bound method Conv.call of <tensorflow.python.layers.convolutional.Conv2D object at 0x7f80fa227f10>>: AssertionError: Bad argument number for Name: 3, expecting 4\n",
      "W0319 21:01:13.666835 140193590601472 ag_logging.py:145] Entity <bound method Conv.call of <tensorflow.python.layers.convolutional.Conv2D object at 0x7f80fa227f10>> could not be transformed and will be executed as-is. Please report this to the AutgoGraph team. When filing the bug, set the verbosity to 10 (on Linux, `export AUTOGRAPH_VERBOSITY=10`) and attach the full output. Cause: converting <bound method Conv.call of <tensorflow.python.layers.convolutional.Conv2D object at 0x7f80fa227f10>>: AssertionError: Bad argument number for Name: 3, expecting 4\n",
      "WARNING:tensorflow:Entity <bound method Conv.call of <tensorflow.python.layers.convolutional.Conv2D object at 0x7f80fa29d850>> could not be transformed and will be executed as-is. Please report this to the AutgoGraph team. When filing the bug, set the verbosity to 10 (on Linux, `export AUTOGRAPH_VERBOSITY=10`) and attach the full output. Cause: converting <bound method Conv.call of <tensorflow.python.layers.convolutional.Conv2D object at 0x7f80fa29d850>>: AssertionError: Bad argument number for Name: 3, expecting 4\n",
      "W0319 21:01:13.714819 140193590601472 ag_logging.py:145] Entity <bound method Conv.call of <tensorflow.python.layers.convolutional.Conv2D object at 0x7f80fa29d850>> could not be transformed and will be executed as-is. Please report this to the AutgoGraph team. When filing the bug, set the verbosity to 10 (on Linux, `export AUTOGRAPH_VERBOSITY=10`) and attach the full output. Cause: converting <bound method Conv.call of <tensorflow.python.layers.convolutional.Conv2D object at 0x7f80fa29d850>>: AssertionError: Bad argument number for Name: 3, expecting 4\n",
      "WARNING:tensorflow:Entity <bound method Conv.call of <tensorflow.python.layers.convolutional.Conv2D object at 0x7f80fa227850>> could not be transformed and will be executed as-is. Please report this to the AutgoGraph team. When filing the bug, set the verbosity to 10 (on Linux, `export AUTOGRAPH_VERBOSITY=10`) and attach the full output. Cause: converting <bound method Conv.call of <tensorflow.python.layers.convolutional.Conv2D object at 0x7f80fa227850>>: AssertionError: Bad argument number for Name: 3, expecting 4\n",
      "W0319 21:01:13.761358 140193590601472 ag_logging.py:145] Entity <bound method Conv.call of <tensorflow.python.layers.convolutional.Conv2D object at 0x7f80fa227850>> could not be transformed and will be executed as-is. Please report this to the AutgoGraph team. When filing the bug, set the verbosity to 10 (on Linux, `export AUTOGRAPH_VERBOSITY=10`) and attach the full output. Cause: converting <bound method Conv.call of <tensorflow.python.layers.convolutional.Conv2D object at 0x7f80fa227850>>: AssertionError: Bad argument number for Name: 3, expecting 4\n",
      "WARNING:tensorflow:Entity <bound method Conv.call of <tensorflow.python.layers.convolutional.Conv2D object at 0x7f80fa2af290>> could not be transformed and will be executed as-is. Please report this to the AutgoGraph team. When filing the bug, set the verbosity to 10 (on Linux, `export AUTOGRAPH_VERBOSITY=10`) and attach the full output. Cause: converting <bound method Conv.call of <tensorflow.python.layers.convolutional.Conv2D object at 0x7f80fa2af290>>: AssertionError: Bad argument number for Name: 3, expecting 4\n",
      "W0319 21:01:13.815897 140193590601472 ag_logging.py:145] Entity <bound method Conv.call of <tensorflow.python.layers.convolutional.Conv2D object at 0x7f80fa2af290>> could not be transformed and will be executed as-is. Please report this to the AutgoGraph team. When filing the bug, set the verbosity to 10 (on Linux, `export AUTOGRAPH_VERBOSITY=10`) and attach the full output. Cause: converting <bound method Conv.call of <tensorflow.python.layers.convolutional.Conv2D object at 0x7f80fa2af290>>: AssertionError: Bad argument number for Name: 3, expecting 4\n",
      "WARNING:tensorflow:Entity <bound method Conv.call of <tensorflow.python.layers.convolutional.Conv2D object at 0x7f80fa12b190>> could not be transformed and will be executed as-is. Please report this to the AutgoGraph team. When filing the bug, set the verbosity to 10 (on Linux, `export AUTOGRAPH_VERBOSITY=10`) and attach the full output. Cause: converting <bound method Conv.call of <tensorflow.python.layers.convolutional.Conv2D object at 0x7f80fa12b190>>: AssertionError: Bad argument number for Name: 3, expecting 4\n",
      "W0319 21:01:13.889066 140193590601472 ag_logging.py:145] Entity <bound method Conv.call of <tensorflow.python.layers.convolutional.Conv2D object at 0x7f80fa12b190>> could not be transformed and will be executed as-is. Please report this to the AutgoGraph team. When filing the bug, set the verbosity to 10 (on Linux, `export AUTOGRAPH_VERBOSITY=10`) and attach the full output. Cause: converting <bound method Conv.call of <tensorflow.python.layers.convolutional.Conv2D object at 0x7f80fa12b190>>: AssertionError: Bad argument number for Name: 3, expecting 4\n",
      "WARNING:tensorflow:Entity <bound method Conv.call of <tensorflow.python.layers.convolutional.Conv2D object at 0x7f80fa0d3390>> could not be transformed and will be executed as-is. Please report this to the AutgoGraph team. When filing the bug, set the verbosity to 10 (on Linux, `export AUTOGRAPH_VERBOSITY=10`) and attach the full output. Cause: converting <bound method Conv.call of <tensorflow.python.layers.convolutional.Conv2D object at 0x7f80fa0d3390>>: AssertionError: Bad argument number for Name: 3, expecting 4\n",
      "W0319 21:01:13.936403 140193590601472 ag_logging.py:145] Entity <bound method Conv.call of <tensorflow.python.layers.convolutional.Conv2D object at 0x7f80fa0d3390>> could not be transformed and will be executed as-is. Please report this to the AutgoGraph team. When filing the bug, set the verbosity to 10 (on Linux, `export AUTOGRAPH_VERBOSITY=10`) and attach the full output. Cause: converting <bound method Conv.call of <tensorflow.python.layers.convolutional.Conv2D object at 0x7f80fa0d3390>>: AssertionError: Bad argument number for Name: 3, expecting 4\n",
      "WARNING:tensorflow:Entity <bound method Conv.call of <tensorflow.python.layers.convolutional.Conv2D object at 0x7f80fa256cd0>> could not be transformed and will be executed as-is. Please report this to the AutgoGraph team. When filing the bug, set the verbosity to 10 (on Linux, `export AUTOGRAPH_VERBOSITY=10`) and attach the full output. Cause: converting <bound method Conv.call of <tensorflow.python.layers.convolutional.Conv2D object at 0x7f80fa256cd0>>: AssertionError: Bad argument number for Name: 3, expecting 4\n",
      "W0319 21:01:13.982952 140193590601472 ag_logging.py:145] Entity <bound method Conv.call of <tensorflow.python.layers.convolutional.Conv2D object at 0x7f80fa256cd0>> could not be transformed and will be executed as-is. Please report this to the AutgoGraph team. When filing the bug, set the verbosity to 10 (on Linux, `export AUTOGRAPH_VERBOSITY=10`) and attach the full output. Cause: converting <bound method Conv.call of <tensorflow.python.layers.convolutional.Conv2D object at 0x7f80fa256cd0>>: AssertionError: Bad argument number for Name: 3, expecting 4\n",
      "WARNING:tensorflow:Entity <bound method Conv.call of <tensorflow.python.layers.convolutional.Conv2D object at 0x7f80fa1ea810>> could not be transformed and will be executed as-is. Please report this to the AutgoGraph team. When filing the bug, set the verbosity to 10 (on Linux, `export AUTOGRAPH_VERBOSITY=10`) and attach the full output. Cause: converting <bound method Conv.call of <tensorflow.python.layers.convolutional.Conv2D object at 0x7f80fa1ea810>>: AssertionError: Bad argument number for Name: 3, expecting 4\n",
      "W0319 21:01:14.037642 140193590601472 ag_logging.py:145] Entity <bound method Conv.call of <tensorflow.python.layers.convolutional.Conv2D object at 0x7f80fa1ea810>> could not be transformed and will be executed as-is. Please report this to the AutgoGraph team. When filing the bug, set the verbosity to 10 (on Linux, `export AUTOGRAPH_VERBOSITY=10`) and attach the full output. Cause: converting <bound method Conv.call of <tensorflow.python.layers.convolutional.Conv2D object at 0x7f80fa1ea810>>: AssertionError: Bad argument number for Name: 3, expecting 4\n",
      "WARNING:tensorflow:Entity <bound method Conv.call of <tensorflow.python.layers.convolutional.Conv2D object at 0x7f80fa0debd0>> could not be transformed and will be executed as-is. Please report this to the AutgoGraph team. When filing the bug, set the verbosity to 10 (on Linux, `export AUTOGRAPH_VERBOSITY=10`) and attach the full output. Cause: converting <bound method Conv.call of <tensorflow.python.layers.convolutional.Conv2D object at 0x7f80fa0debd0>>: AssertionError: Bad argument number for Name: 3, expecting 4\n",
      "W0319 21:01:14.111230 140193590601472 ag_logging.py:145] Entity <bound method Conv.call of <tensorflow.python.layers.convolutional.Conv2D object at 0x7f80fa0debd0>> could not be transformed and will be executed as-is. Please report this to the AutgoGraph team. When filing the bug, set the verbosity to 10 (on Linux, `export AUTOGRAPH_VERBOSITY=10`) and attach the full output. Cause: converting <bound method Conv.call of <tensorflow.python.layers.convolutional.Conv2D object at 0x7f80fa0debd0>>: AssertionError: Bad argument number for Name: 3, expecting 4\n",
      "WARNING:tensorflow:Entity <bound method Conv.call of <tensorflow.python.layers.convolutional.Conv2D object at 0x7f80fa192dd0>> could not be transformed and will be executed as-is. Please report this to the AutgoGraph team. When filing the bug, set the verbosity to 10 (on Linux, `export AUTOGRAPH_VERBOSITY=10`) and attach the full output. Cause: converting <bound method Conv.call of <tensorflow.python.layers.convolutional.Conv2D object at 0x7f80fa192dd0>>: AssertionError: Bad argument number for Name: 3, expecting 4\n",
      "W0319 21:01:14.165454 140193590601472 ag_logging.py:145] Entity <bound method Conv.call of <tensorflow.python.layers.convolutional.Conv2D object at 0x7f80fa192dd0>> could not be transformed and will be executed as-is. Please report this to the AutgoGraph team. When filing the bug, set the verbosity to 10 (on Linux, `export AUTOGRAPH_VERBOSITY=10`) and attach the full output. Cause: converting <bound method Conv.call of <tensorflow.python.layers.convolutional.Conv2D object at 0x7f80fa192dd0>>: AssertionError: Bad argument number for Name: 3, expecting 4\n",
      "WARNING:tensorflow:Entity <bound method Conv.call of <tensorflow.python.layers.convolutional.Conv2D object at 0x7f80f9fec450>> could not be transformed and will be executed as-is. Please report this to the AutgoGraph team. When filing the bug, set the verbosity to 10 (on Linux, `export AUTOGRAPH_VERBOSITY=10`) and attach the full output. Cause: converting <bound method Conv.call of <tensorflow.python.layers.convolutional.Conv2D object at 0x7f80f9fec450>>: AssertionError: Bad argument number for Name: 3, expecting 4\n",
      "W0319 21:01:14.238550 140193590601472 ag_logging.py:145] Entity <bound method Conv.call of <tensorflow.python.layers.convolutional.Conv2D object at 0x7f80f9fec450>> could not be transformed and will be executed as-is. Please report this to the AutgoGraph team. When filing the bug, set the verbosity to 10 (on Linux, `export AUTOGRAPH_VERBOSITY=10`) and attach the full output. Cause: converting <bound method Conv.call of <tensorflow.python.layers.convolutional.Conv2D object at 0x7f80f9fec450>>: AssertionError: Bad argument number for Name: 3, expecting 4\n",
      "WARNING:tensorflow:Entity <bound method Conv.call of <tensorflow.python.layers.convolutional.Conv2D object at 0x7f80f9fec450>> could not be transformed and will be executed as-is. Please report this to the AutgoGraph team. When filing the bug, set the verbosity to 10 (on Linux, `export AUTOGRAPH_VERBOSITY=10`) and attach the full output. Cause: converting <bound method Conv.call of <tensorflow.python.layers.convolutional.Conv2D object at 0x7f80f9fec450>>: AssertionError: Bad argument number for Name: 3, expecting 4\n",
      "W0319 21:01:14.293436 140193590601472 ag_logging.py:145] Entity <bound method Conv.call of <tensorflow.python.layers.convolutional.Conv2D object at 0x7f80f9fec450>> could not be transformed and will be executed as-is. Please report this to the AutgoGraph team. When filing the bug, set the verbosity to 10 (on Linux, `export AUTOGRAPH_VERBOSITY=10`) and attach the full output. Cause: converting <bound method Conv.call of <tensorflow.python.layers.convolutional.Conv2D object at 0x7f80f9fec450>>: AssertionError: Bad argument number for Name: 3, expecting 4\n",
      "WARNING:tensorflow:Entity <bound method Conv.call of <tensorflow.python.layers.convolutional.Conv2D object at 0x7f80f9e80550>> could not be transformed and will be executed as-is. Please report this to the AutgoGraph team. When filing the bug, set the verbosity to 10 (on Linux, `export AUTOGRAPH_VERBOSITY=10`) and attach the full output. Cause: converting <bound method Conv.call of <tensorflow.python.layers.convolutional.Conv2D object at 0x7f80f9e80550>>: AssertionError: Bad argument number for Name: 3, expecting 4\n",
      "W0319 21:01:14.366712 140193590601472 ag_logging.py:145] Entity <bound method Conv.call of <tensorflow.python.layers.convolutional.Conv2D object at 0x7f80f9e80550>> could not be transformed and will be executed as-is. Please report this to the AutgoGraph team. When filing the bug, set the verbosity to 10 (on Linux, `export AUTOGRAPH_VERBOSITY=10`) and attach the full output. Cause: converting <bound method Conv.call of <tensorflow.python.layers.convolutional.Conv2D object at 0x7f80f9e80550>>: AssertionError: Bad argument number for Name: 3, expecting 4\n",
      "WARNING:tensorflow:Entity <bound method Conv.call of <tensorflow.python.layers.convolutional.Conv2D object at 0x7f80f9d8d590>> could not be transformed and will be executed as-is. Please report this to the AutgoGraph team. When filing the bug, set the verbosity to 10 (on Linux, `export AUTOGRAPH_VERBOSITY=10`) and attach the full output. Cause: converting <bound method Conv.call of <tensorflow.python.layers.convolutional.Conv2D object at 0x7f80f9d8d590>>: AssertionError: Bad argument number for Name: 3, expecting 4\n",
      "W0319 21:01:14.421537 140193590601472 ag_logging.py:145] Entity <bound method Conv.call of <tensorflow.python.layers.convolutional.Conv2D object at 0x7f80f9d8d590>> could not be transformed and will be executed as-is. Please report this to the AutgoGraph team. When filing the bug, set the verbosity to 10 (on Linux, `export AUTOGRAPH_VERBOSITY=10`) and attach the full output. Cause: converting <bound method Conv.call of <tensorflow.python.layers.convolutional.Conv2D object at 0x7f80f9d8d590>>: AssertionError: Bad argument number for Name: 3, expecting 4\n",
      "WARNING:tensorflow:Entity <bound method Conv.call of <tensorflow.python.layers.convolutional.Conv2D object at 0x7f80f9d89dd0>> could not be transformed and will be executed as-is. Please report this to the AutgoGraph team. When filing the bug, set the verbosity to 10 (on Linux, `export AUTOGRAPH_VERBOSITY=10`) and attach the full output. Cause: converting <bound method Conv.call of <tensorflow.python.layers.convolutional.Conv2D object at 0x7f80f9d89dd0>>: AssertionError: Bad argument number for Name: 3, expecting 4\n",
      "W0319 21:01:14.494875 140193590601472 ag_logging.py:145] Entity <bound method Conv.call of <tensorflow.python.layers.convolutional.Conv2D object at 0x7f80f9d89dd0>> could not be transformed and will be executed as-is. Please report this to the AutgoGraph team. When filing the bug, set the verbosity to 10 (on Linux, `export AUTOGRAPH_VERBOSITY=10`) and attach the full output. Cause: converting <bound method Conv.call of <tensorflow.python.layers.convolutional.Conv2D object at 0x7f80f9d89dd0>>: AssertionError: Bad argument number for Name: 3, expecting 4\n",
      "WARNING:tensorflow:Entity <bound method Conv.call of <tensorflow.python.layers.convolutional.Conv2D object at 0x7f80f9c6ea90>> could not be transformed and will be executed as-is. Please report this to the AutgoGraph team. When filing the bug, set the verbosity to 10 (on Linux, `export AUTOGRAPH_VERBOSITY=10`) and attach the full output. Cause: converting <bound method Conv.call of <tensorflow.python.layers.convolutional.Conv2D object at 0x7f80f9c6ea90>>: AssertionError: Bad argument number for Name: 3, expecting 4\n",
      "W0319 21:01:14.550032 140193590601472 ag_logging.py:145] Entity <bound method Conv.call of <tensorflow.python.layers.convolutional.Conv2D object at 0x7f80f9c6ea90>> could not be transformed and will be executed as-is. Please report this to the AutgoGraph team. When filing the bug, set the verbosity to 10 (on Linux, `export AUTOGRAPH_VERBOSITY=10`) and attach the full output. Cause: converting <bound method Conv.call of <tensorflow.python.layers.convolutional.Conv2D object at 0x7f80f9c6ea90>>: AssertionError: Bad argument number for Name: 3, expecting 4\n",
      "WARNING:tensorflow:Entity <bound method Conv.call of <tensorflow.python.layers.convolutional.Conv2D object at 0x7f80f9b1cd90>> could not be transformed and will be executed as-is. Please report this to the AutgoGraph team. When filing the bug, set the verbosity to 10 (on Linux, `export AUTOGRAPH_VERBOSITY=10`) and attach the full output. Cause: converting <bound method Conv.call of <tensorflow.python.layers.convolutional.Conv2D object at 0x7f80f9b1cd90>>: AssertionError: Bad argument number for Name: 3, expecting 4\n",
      "W0319 21:01:14.679338 140193590601472 ag_logging.py:145] Entity <bound method Conv.call of <tensorflow.python.layers.convolutional.Conv2D object at 0x7f80f9b1cd90>> could not be transformed and will be executed as-is. Please report this to the AutgoGraph team. When filing the bug, set the verbosity to 10 (on Linux, `export AUTOGRAPH_VERBOSITY=10`) and attach the full output. Cause: converting <bound method Conv.call of <tensorflow.python.layers.convolutional.Conv2D object at 0x7f80f9b1cd90>>: AssertionError: Bad argument number for Name: 3, expecting 4\n",
      "WARNING:tensorflow:Entity <bound method Conv.call of <tensorflow.python.layers.convolutional.Conv2D object at 0x7f80fa699b50>> could not be transformed and will be executed as-is. Please report this to the AutgoGraph team. When filing the bug, set the verbosity to 10 (on Linux, `export AUTOGRAPH_VERBOSITY=10`) and attach the full output. Cause: converting <bound method Conv.call of <tensorflow.python.layers.convolutional.Conv2D object at 0x7f80fa699b50>>: AssertionError: Bad argument number for Name: 3, expecting 4\n",
      "W0319 21:01:14.726522 140193590601472 ag_logging.py:145] Entity <bound method Conv.call of <tensorflow.python.layers.convolutional.Conv2D object at 0x7f80fa699b50>> could not be transformed and will be executed as-is. Please report this to the AutgoGraph team. When filing the bug, set the verbosity to 10 (on Linux, `export AUTOGRAPH_VERBOSITY=10`) and attach the full output. Cause: converting <bound method Conv.call of <tensorflow.python.layers.convolutional.Conv2D object at 0x7f80fa699b50>>: AssertionError: Bad argument number for Name: 3, expecting 4\n",
      "WARNING:tensorflow:Entity <bound method Conv.call of <tensorflow.python.layers.convolutional.Conv2D object at 0x7f80f9be5790>> could not be transformed and will be executed as-is. Please report this to the AutgoGraph team. When filing the bug, set the verbosity to 10 (on Linux, `export AUTOGRAPH_VERBOSITY=10`) and attach the full output. Cause: converting <bound method Conv.call of <tensorflow.python.layers.convolutional.Conv2D object at 0x7f80f9be5790>>: AssertionError: Bad argument number for Name: 3, expecting 4\n",
      "W0319 21:01:14.773186 140193590601472 ag_logging.py:145] Entity <bound method Conv.call of <tensorflow.python.layers.convolutional.Conv2D object at 0x7f80f9be5790>> could not be transformed and will be executed as-is. Please report this to the AutgoGraph team. When filing the bug, set the verbosity to 10 (on Linux, `export AUTOGRAPH_VERBOSITY=10`) and attach the full output. Cause: converting <bound method Conv.call of <tensorflow.python.layers.convolutional.Conv2D object at 0x7f80f9be5790>>: AssertionError: Bad argument number for Name: 3, expecting 4\n",
      "WARNING:tensorflow:Entity <bound method Conv.call of <tensorflow.python.layers.convolutional.Conv2D object at 0x7f80f9bea590>> could not be transformed and will be executed as-is. Please report this to the AutgoGraph team. When filing the bug, set the verbosity to 10 (on Linux, `export AUTOGRAPH_VERBOSITY=10`) and attach the full output. Cause: converting <bound method Conv.call of <tensorflow.python.layers.convolutional.Conv2D object at 0x7f80f9bea590>>: AssertionError: Bad argument number for Name: 3, expecting 4\n",
      "W0319 21:01:14.827682 140193590601472 ag_logging.py:145] Entity <bound method Conv.call of <tensorflow.python.layers.convolutional.Conv2D object at 0x7f80f9bea590>> could not be transformed and will be executed as-is. Please report this to the AutgoGraph team. When filing the bug, set the verbosity to 10 (on Linux, `export AUTOGRAPH_VERBOSITY=10`) and attach the full output. Cause: converting <bound method Conv.call of <tensorflow.python.layers.convolutional.Conv2D object at 0x7f80f9bea590>>: AssertionError: Bad argument number for Name: 3, expecting 4\n",
      "WARNING:tensorflow:Entity <bound method Conv.call of <tensorflow.python.layers.convolutional.Conv2D object at 0x7f80f99d8910>> could not be transformed and will be executed as-is. Please report this to the AutgoGraph team. When filing the bug, set the verbosity to 10 (on Linux, `export AUTOGRAPH_VERBOSITY=10`) and attach the full output. Cause: converting <bound method Conv.call of <tensorflow.python.layers.convolutional.Conv2D object at 0x7f80f99d8910>>: AssertionError: Bad argument number for Name: 3, expecting 4\n",
      "W0319 21:01:14.903903 140193590601472 ag_logging.py:145] Entity <bound method Conv.call of <tensorflow.python.layers.convolutional.Conv2D object at 0x7f80f99d8910>> could not be transformed and will be executed as-is. Please report this to the AutgoGraph team. When filing the bug, set the verbosity to 10 (on Linux, `export AUTOGRAPH_VERBOSITY=10`) and attach the full output. Cause: converting <bound method Conv.call of <tensorflow.python.layers.convolutional.Conv2D object at 0x7f80f99d8910>>: AssertionError: Bad argument number for Name: 3, expecting 4\n",
      "WARNING:tensorflow:Entity <bound method Conv.call of <tensorflow.python.layers.convolutional.Conv2D object at 0x7f80f9a337d0>> could not be transformed and will be executed as-is. Please report this to the AutgoGraph team. When filing the bug, set the verbosity to 10 (on Linux, `export AUTOGRAPH_VERBOSITY=10`) and attach the full output. Cause: converting <bound method Conv.call of <tensorflow.python.layers.convolutional.Conv2D object at 0x7f80f9a337d0>>: AssertionError: Bad argument number for Name: 3, expecting 4\n",
      "W0319 21:01:14.951392 140193590601472 ag_logging.py:145] Entity <bound method Conv.call of <tensorflow.python.layers.convolutional.Conv2D object at 0x7f80f9a337d0>> could not be transformed and will be executed as-is. Please report this to the AutgoGraph team. When filing the bug, set the verbosity to 10 (on Linux, `export AUTOGRAPH_VERBOSITY=10`) and attach the full output. Cause: converting <bound method Conv.call of <tensorflow.python.layers.convolutional.Conv2D object at 0x7f80f9a337d0>>: AssertionError: Bad argument number for Name: 3, expecting 4\n",
      "WARNING:tensorflow:Entity <bound method Conv.call of <tensorflow.python.layers.convolutional.Conv2D object at 0x7f80fa65c390>> could not be transformed and will be executed as-is. Please report this to the AutgoGraph team. When filing the bug, set the verbosity to 10 (on Linux, `export AUTOGRAPH_VERBOSITY=10`) and attach the full output. Cause: converting <bound method Conv.call of <tensorflow.python.layers.convolutional.Conv2D object at 0x7f80fa65c390>>: AssertionError: Bad argument number for Name: 3, expecting 4\n",
      "W0319 21:01:14.997882 140193590601472 ag_logging.py:145] Entity <bound method Conv.call of <tensorflow.python.layers.convolutional.Conv2D object at 0x7f80fa65c390>> could not be transformed and will be executed as-is. Please report this to the AutgoGraph team. When filing the bug, set the verbosity to 10 (on Linux, `export AUTOGRAPH_VERBOSITY=10`) and attach the full output. Cause: converting <bound method Conv.call of <tensorflow.python.layers.convolutional.Conv2D object at 0x7f80fa65c390>>: AssertionError: Bad argument number for Name: 3, expecting 4\n",
      "WARNING:tensorflow:Entity <bound method Conv.call of <tensorflow.python.layers.convolutional.Conv2D object at 0x7f80fa609c10>> could not be transformed and will be executed as-is. Please report this to the AutgoGraph team. When filing the bug, set the verbosity to 10 (on Linux, `export AUTOGRAPH_VERBOSITY=10`) and attach the full output. Cause: converting <bound method Conv.call of <tensorflow.python.layers.convolutional.Conv2D object at 0x7f80fa609c10>>: AssertionError: Bad argument number for Name: 3, expecting 4\n",
      "W0319 21:01:15.052566 140193590601472 ag_logging.py:145] Entity <bound method Conv.call of <tensorflow.python.layers.convolutional.Conv2D object at 0x7f80fa609c10>> could not be transformed and will be executed as-is. Please report this to the AutgoGraph team. When filing the bug, set the verbosity to 10 (on Linux, `export AUTOGRAPH_VERBOSITY=10`) and attach the full output. Cause: converting <bound method Conv.call of <tensorflow.python.layers.convolutional.Conv2D object at 0x7f80fa609c10>>: AssertionError: Bad argument number for Name: 3, expecting 4\n",
      "WARNING:tensorflow:Entity <bound method Conv.call of <tensorflow.python.layers.convolutional.Conv2D object at 0x7f80f9861250>> could not be transformed and will be executed as-is. Please report this to the AutgoGraph team. When filing the bug, set the verbosity to 10 (on Linux, `export AUTOGRAPH_VERBOSITY=10`) and attach the full output. Cause: converting <bound method Conv.call of <tensorflow.python.layers.convolutional.Conv2D object at 0x7f80f9861250>>: AssertionError: Bad argument number for Name: 3, expecting 4\n",
      "W0319 21:01:15.129114 140193590601472 ag_logging.py:145] Entity <bound method Conv.call of <tensorflow.python.layers.convolutional.Conv2D object at 0x7f80f9861250>> could not be transformed and will be executed as-is. Please report this to the AutgoGraph team. When filing the bug, set the verbosity to 10 (on Linux, `export AUTOGRAPH_VERBOSITY=10`) and attach the full output. Cause: converting <bound method Conv.call of <tensorflow.python.layers.convolutional.Conv2D object at 0x7f80f9861250>>: AssertionError: Bad argument number for Name: 3, expecting 4\n",
      "WARNING:tensorflow:Entity <bound method Conv.call of <tensorflow.python.layers.convolutional.Conv2D object at 0x7f80f97e5910>> could not be transformed and will be executed as-is. Please report this to the AutgoGraph team. When filing the bug, set the verbosity to 10 (on Linux, `export AUTOGRAPH_VERBOSITY=10`) and attach the full output. Cause: converting <bound method Conv.call of <tensorflow.python.layers.convolutional.Conv2D object at 0x7f80f97e5910>>: AssertionError: Bad argument number for Name: 3, expecting 4\n",
      "W0319 21:01:15.175861 140193590601472 ag_logging.py:145] Entity <bound method Conv.call of <tensorflow.python.layers.convolutional.Conv2D object at 0x7f80f97e5910>> could not be transformed and will be executed as-is. Please report this to the AutgoGraph team. When filing the bug, set the verbosity to 10 (on Linux, `export AUTOGRAPH_VERBOSITY=10`) and attach the full output. Cause: converting <bound method Conv.call of <tensorflow.python.layers.convolutional.Conv2D object at 0x7f80f97e5910>>: AssertionError: Bad argument number for Name: 3, expecting 4\n",
      "WARNING:tensorflow:Entity <bound method Conv.call of <tensorflow.python.layers.convolutional.Conv2D object at 0x7f80f99eab10>> could not be transformed and will be executed as-is. Please report this to the AutgoGraph team. When filing the bug, set the verbosity to 10 (on Linux, `export AUTOGRAPH_VERBOSITY=10`) and attach the full output. Cause: converting <bound method Conv.call of <tensorflow.python.layers.convolutional.Conv2D object at 0x7f80f99eab10>>: AssertionError: Bad argument number for Name: 3, expecting 4\n",
      "W0319 21:01:15.223101 140193590601472 ag_logging.py:145] Entity <bound method Conv.call of <tensorflow.python.layers.convolutional.Conv2D object at 0x7f80f99eab10>> could not be transformed and will be executed as-is. Please report this to the AutgoGraph team. When filing the bug, set the verbosity to 10 (on Linux, `export AUTOGRAPH_VERBOSITY=10`) and attach the full output. Cause: converting <bound method Conv.call of <tensorflow.python.layers.convolutional.Conv2D object at 0x7f80f99eab10>>: AssertionError: Bad argument number for Name: 3, expecting 4\n",
      "WARNING:tensorflow:Entity <bound method Conv.call of <tensorflow.python.layers.convolutional.Conv2D object at 0x7f80f99066d0>> could not be transformed and will be executed as-is. Please report this to the AutgoGraph team. When filing the bug, set the verbosity to 10 (on Linux, `export AUTOGRAPH_VERBOSITY=10`) and attach the full output. Cause: converting <bound method Conv.call of <tensorflow.python.layers.convolutional.Conv2D object at 0x7f80f99066d0>>: AssertionError: Bad argument number for Name: 3, expecting 4\n",
      "W0319 21:01:15.277354 140193590601472 ag_logging.py:145] Entity <bound method Conv.call of <tensorflow.python.layers.convolutional.Conv2D object at 0x7f80f99066d0>> could not be transformed and will be executed as-is. Please report this to the AutgoGraph team. When filing the bug, set the verbosity to 10 (on Linux, `export AUTOGRAPH_VERBOSITY=10`) and attach the full output. Cause: converting <bound method Conv.call of <tensorflow.python.layers.convolutional.Conv2D object at 0x7f80f99066d0>>: AssertionError: Bad argument number for Name: 3, expecting 4\n",
      "WARNING:tensorflow:Entity <bound method Conv.call of <tensorflow.python.layers.convolutional.Conv2D object at 0x7f80f96c6910>> could not be transformed and will be executed as-is. Please report this to the AutgoGraph team. When filing the bug, set the verbosity to 10 (on Linux, `export AUTOGRAPH_VERBOSITY=10`) and attach the full output. Cause: converting <bound method Conv.call of <tensorflow.python.layers.convolutional.Conv2D object at 0x7f80f96c6910>>: AssertionError: Bad argument number for Name: 3, expecting 4\n",
      "W0319 21:01:15.354138 140193590601472 ag_logging.py:145] Entity <bound method Conv.call of <tensorflow.python.layers.convolutional.Conv2D object at 0x7f80f96c6910>> could not be transformed and will be executed as-is. Please report this to the AutgoGraph team. When filing the bug, set the verbosity to 10 (on Linux, `export AUTOGRAPH_VERBOSITY=10`) and attach the full output. Cause: converting <bound method Conv.call of <tensorflow.python.layers.convolutional.Conv2D object at 0x7f80f96c6910>>: AssertionError: Bad argument number for Name: 3, expecting 4\n",
      "WARNING:tensorflow:Entity <bound method Conv.call of <tensorflow.python.layers.convolutional.Conv2D object at 0x7f80f96db790>> could not be transformed and will be executed as-is. Please report this to the AutgoGraph team. When filing the bug, set the verbosity to 10 (on Linux, `export AUTOGRAPH_VERBOSITY=10`) and attach the full output. Cause: converting <bound method Conv.call of <tensorflow.python.layers.convolutional.Conv2D object at 0x7f80f96db790>>: AssertionError: Bad argument number for Name: 3, expecting 4\n",
      "W0319 21:01:15.401454 140193590601472 ag_logging.py:145] Entity <bound method Conv.call of <tensorflow.python.layers.convolutional.Conv2D object at 0x7f80f96db790>> could not be transformed and will be executed as-is. Please report this to the AutgoGraph team. When filing the bug, set the verbosity to 10 (on Linux, `export AUTOGRAPH_VERBOSITY=10`) and attach the full output. Cause: converting <bound method Conv.call of <tensorflow.python.layers.convolutional.Conv2D object at 0x7f80f96db790>>: AssertionError: Bad argument number for Name: 3, expecting 4\n",
      "WARNING:tensorflow:Entity <bound method Conv.call of <tensorflow.python.layers.convolutional.Conv2D object at 0x7f80f9963150>> could not be transformed and will be executed as-is. Please report this to the AutgoGraph team. When filing the bug, set the verbosity to 10 (on Linux, `export AUTOGRAPH_VERBOSITY=10`) and attach the full output. Cause: converting <bound method Conv.call of <tensorflow.python.layers.convolutional.Conv2D object at 0x7f80f9963150>>: AssertionError: Bad argument number for Name: 3, expecting 4\n",
      "W0319 21:01:15.448307 140193590601472 ag_logging.py:145] Entity <bound method Conv.call of <tensorflow.python.layers.convolutional.Conv2D object at 0x7f80f9963150>> could not be transformed and will be executed as-is. Please report this to the AutgoGraph team. When filing the bug, set the verbosity to 10 (on Linux, `export AUTOGRAPH_VERBOSITY=10`) and attach the full output. Cause: converting <bound method Conv.call of <tensorflow.python.layers.convolutional.Conv2D object at 0x7f80f9963150>>: AssertionError: Bad argument number for Name: 3, expecting 4\n",
      "WARNING:tensorflow:Entity <bound method Conv.call of <tensorflow.python.layers.convolutional.Conv2D object at 0x7f80fa6beb50>> could not be transformed and will be executed as-is. Please report this to the AutgoGraph team. When filing the bug, set the verbosity to 10 (on Linux, `export AUTOGRAPH_VERBOSITY=10`) and attach the full output. Cause: converting <bound method Conv.call of <tensorflow.python.layers.convolutional.Conv2D object at 0x7f80fa6beb50>>: AssertionError: Bad argument number for Name: 3, expecting 4\n",
      "W0319 21:01:15.502970 140193590601472 ag_logging.py:145] Entity <bound method Conv.call of <tensorflow.python.layers.convolutional.Conv2D object at 0x7f80fa6beb50>> could not be transformed and will be executed as-is. Please report this to the AutgoGraph team. When filing the bug, set the verbosity to 10 (on Linux, `export AUTOGRAPH_VERBOSITY=10`) and attach the full output. Cause: converting <bound method Conv.call of <tensorflow.python.layers.convolutional.Conv2D object at 0x7f80fa6beb50>>: AssertionError: Bad argument number for Name: 3, expecting 4\n",
      "WARNING:tensorflow:Entity <bound method Conv.call of <tensorflow.python.layers.convolutional.Conv2D object at 0x7f80f964af50>> could not be transformed and will be executed as-is. Please report this to the AutgoGraph team. When filing the bug, set the verbosity to 10 (on Linux, `export AUTOGRAPH_VERBOSITY=10`) and attach the full output. Cause: converting <bound method Conv.call of <tensorflow.python.layers.convolutional.Conv2D object at 0x7f80f964af50>>: AssertionError: Bad argument number for Name: 3, expecting 4\n",
      "W0319 21:01:15.579569 140193590601472 ag_logging.py:145] Entity <bound method Conv.call of <tensorflow.python.layers.convolutional.Conv2D object at 0x7f80f964af50>> could not be transformed and will be executed as-is. Please report this to the AutgoGraph team. When filing the bug, set the verbosity to 10 (on Linux, `export AUTOGRAPH_VERBOSITY=10`) and attach the full output. Cause: converting <bound method Conv.call of <tensorflow.python.layers.convolutional.Conv2D object at 0x7f80f964af50>>: AssertionError: Bad argument number for Name: 3, expecting 4\n",
      "WARNING:tensorflow:Entity <bound method Conv.call of <tensorflow.python.layers.convolutional.Conv2D object at 0x7f80f9544fd0>> could not be transformed and will be executed as-is. Please report this to the AutgoGraph team. When filing the bug, set the verbosity to 10 (on Linux, `export AUTOGRAPH_VERBOSITY=10`) and attach the full output. Cause: converting <bound method Conv.call of <tensorflow.python.layers.convolutional.Conv2D object at 0x7f80f9544fd0>>: AssertionError: Bad argument number for Name: 3, expecting 4\n",
      "W0319 21:01:15.626546 140193590601472 ag_logging.py:145] Entity <bound method Conv.call of <tensorflow.python.layers.convolutional.Conv2D object at 0x7f80f9544fd0>> could not be transformed and will be executed as-is. Please report this to the AutgoGraph team. When filing the bug, set the verbosity to 10 (on Linux, `export AUTOGRAPH_VERBOSITY=10`) and attach the full output. Cause: converting <bound method Conv.call of <tensorflow.python.layers.convolutional.Conv2D object at 0x7f80f9544fd0>>: AssertionError: Bad argument number for Name: 3, expecting 4\n",
      "WARNING:tensorflow:Entity <bound method Conv.call of <tensorflow.python.layers.convolutional.Conv2D object at 0x7f80f96c6a10>> could not be transformed and will be executed as-is. Please report this to the AutgoGraph team. When filing the bug, set the verbosity to 10 (on Linux, `export AUTOGRAPH_VERBOSITY=10`) and attach the full output. Cause: converting <bound method Conv.call of <tensorflow.python.layers.convolutional.Conv2D object at 0x7f80f96c6a10>>: AssertionError: Bad argument number for Name: 3, expecting 4\n",
      "W0319 21:01:15.673272 140193590601472 ag_logging.py:145] Entity <bound method Conv.call of <tensorflow.python.layers.convolutional.Conv2D object at 0x7f80f96c6a10>> could not be transformed and will be executed as-is. Please report this to the AutgoGraph team. When filing the bug, set the verbosity to 10 (on Linux, `export AUTOGRAPH_VERBOSITY=10`) and attach the full output. Cause: converting <bound method Conv.call of <tensorflow.python.layers.convolutional.Conv2D object at 0x7f80f96c6a10>>: AssertionError: Bad argument number for Name: 3, expecting 4\n",
      "WARNING:tensorflow:Entity <bound method Conv.call of <tensorflow.python.layers.convolutional.Conv2D object at 0x7f80f977f110>> could not be transformed and will be executed as-is. Please report this to the AutgoGraph team. When filing the bug, set the verbosity to 10 (on Linux, `export AUTOGRAPH_VERBOSITY=10`) and attach the full output. Cause: converting <bound method Conv.call of <tensorflow.python.layers.convolutional.Conv2D object at 0x7f80f977f110>>: AssertionError: Bad argument number for Name: 3, expecting 4\n",
      "W0319 21:01:15.728305 140193590601472 ag_logging.py:145] Entity <bound method Conv.call of <tensorflow.python.layers.convolutional.Conv2D object at 0x7f80f977f110>> could not be transformed and will be executed as-is. Please report this to the AutgoGraph team. When filing the bug, set the verbosity to 10 (on Linux, `export AUTOGRAPH_VERBOSITY=10`) and attach the full output. Cause: converting <bound method Conv.call of <tensorflow.python.layers.convolutional.Conv2D object at 0x7f80f977f110>>: AssertionError: Bad argument number for Name: 3, expecting 4\n",
      "WARNING:tensorflow:Entity <bound method Conv.call of <tensorflow.python.layers.convolutional.Conv2D object at 0x7f80faf21d50>> could not be transformed and will be executed as-is. Please report this to the AutgoGraph team. When filing the bug, set the verbosity to 10 (on Linux, `export AUTOGRAPH_VERBOSITY=10`) and attach the full output. Cause: converting <bound method Conv.call of <tensorflow.python.layers.convolutional.Conv2D object at 0x7f80faf21d50>>: AssertionError: Bad argument number for Name: 3, expecting 4\n",
      "W0319 21:01:15.788218 140193590601472 ag_logging.py:145] Entity <bound method Conv.call of <tensorflow.python.layers.convolutional.Conv2D object at 0x7f80faf21d50>> could not be transformed and will be executed as-is. Please report this to the AutgoGraph team. When filing the bug, set the verbosity to 10 (on Linux, `export AUTOGRAPH_VERBOSITY=10`) and attach the full output. Cause: converting <bound method Conv.call of <tensorflow.python.layers.convolutional.Conv2D object at 0x7f80faf21d50>>: AssertionError: Bad argument number for Name: 3, expecting 4\n",
      "WARNING:tensorflow:Entity <bound method Conv.call of <tensorflow.python.layers.convolutional.Conv2D object at 0x7f80f946f050>> could not be transformed and will be executed as-is. Please report this to the AutgoGraph team. When filing the bug, set the verbosity to 10 (on Linux, `export AUTOGRAPH_VERBOSITY=10`) and attach the full output. Cause: converting <bound method Conv.call of <tensorflow.python.layers.convolutional.Conv2D object at 0x7f80f946f050>>: AssertionError: Bad argument number for Name: 3, expecting 4\n",
      "W0319 21:01:15.858047 140193590601472 ag_logging.py:145] Entity <bound method Conv.call of <tensorflow.python.layers.convolutional.Conv2D object at 0x7f80f946f050>> could not be transformed and will be executed as-is. Please report this to the AutgoGraph team. When filing the bug, set the verbosity to 10 (on Linux, `export AUTOGRAPH_VERBOSITY=10`) and attach the full output. Cause: converting <bound method Conv.call of <tensorflow.python.layers.convolutional.Conv2D object at 0x7f80f946f050>>: AssertionError: Bad argument number for Name: 3, expecting 4\n",
      "WARNING:tensorflow:Entity <bound method Conv.call of <tensorflow.python.layers.convolutional.Conv2D object at 0x7f80f94c0110>> could not be transformed and will be executed as-is. Please report this to the AutgoGraph team. When filing the bug, set the verbosity to 10 (on Linux, `export AUTOGRAPH_VERBOSITY=10`) and attach the full output. Cause: converting <bound method Conv.call of <tensorflow.python.layers.convolutional.Conv2D object at 0x7f80f94c0110>>: AssertionError: Bad argument number for Name: 3, expecting 4\n",
      "W0319 21:01:15.911631 140193590601472 ag_logging.py:145] Entity <bound method Conv.call of <tensorflow.python.layers.convolutional.Conv2D object at 0x7f80f94c0110>> could not be transformed and will be executed as-is. Please report this to the AutgoGraph team. When filing the bug, set the verbosity to 10 (on Linux, `export AUTOGRAPH_VERBOSITY=10`) and attach the full output. Cause: converting <bound method Conv.call of <tensorflow.python.layers.convolutional.Conv2D object at 0x7f80f94c0110>>: AssertionError: Bad argument number for Name: 3, expecting 4\n",
      "WARNING:tensorflow:Entity <bound method Conv.call of <tensorflow.python.layers.convolutional.Conv2D object at 0x7f80f93b5e90>> could not be transformed and will be executed as-is. Please report this to the AutgoGraph team. When filing the bug, set the verbosity to 10 (on Linux, `export AUTOGRAPH_VERBOSITY=10`) and attach the full output. Cause: converting <bound method Conv.call of <tensorflow.python.layers.convolutional.Conv2D object at 0x7f80f93b5e90>>: AssertionError: Bad argument number for Name: 3, expecting 4\n",
      "W0319 21:01:15.981175 140193590601472 ag_logging.py:145] Entity <bound method Conv.call of <tensorflow.python.layers.convolutional.Conv2D object at 0x7f80f93b5e90>> could not be transformed and will be executed as-is. Please report this to the AutgoGraph team. When filing the bug, set the verbosity to 10 (on Linux, `export AUTOGRAPH_VERBOSITY=10`) and attach the full output. Cause: converting <bound method Conv.call of <tensorflow.python.layers.convolutional.Conv2D object at 0x7f80f93b5e90>>: AssertionError: Bad argument number for Name: 3, expecting 4\n",
      "WARNING:tensorflow:Entity <bound method Conv.call of <tensorflow.python.layers.convolutional.Conv2D object at 0x7f80f925e710>> could not be transformed and will be executed as-is. Please report this to the AutgoGraph team. When filing the bug, set the verbosity to 10 (on Linux, `export AUTOGRAPH_VERBOSITY=10`) and attach the full output. Cause: converting <bound method Conv.call of <tensorflow.python.layers.convolutional.Conv2D object at 0x7f80f925e710>>: AssertionError: Bad argument number for Name: 3, expecting 4\n",
      "W0319 21:01:16.034464 140193590601472 ag_logging.py:145] Entity <bound method Conv.call of <tensorflow.python.layers.convolutional.Conv2D object at 0x7f80f925e710>> could not be transformed and will be executed as-is. Please report this to the AutgoGraph team. When filing the bug, set the verbosity to 10 (on Linux, `export AUTOGRAPH_VERBOSITY=10`) and attach the full output. Cause: converting <bound method Conv.call of <tensorflow.python.layers.convolutional.Conv2D object at 0x7f80f925e710>>: AssertionError: Bad argument number for Name: 3, expecting 4\n",
      "WARNING:tensorflow:Entity <bound method Conv.call of <tensorflow.python.layers.convolutional.Conv2D object at 0x7f80f9378710>> could not be transformed and will be executed as-is. Please report this to the AutgoGraph team. When filing the bug, set the verbosity to 10 (on Linux, `export AUTOGRAPH_VERBOSITY=10`) and attach the full output. Cause: converting <bound method Conv.call of <tensorflow.python.layers.convolutional.Conv2D object at 0x7f80f9378710>>: AssertionError: Bad argument number for Name: 3, expecting 4\n",
      "W0319 21:01:16.104501 140193590601472 ag_logging.py:145] Entity <bound method Conv.call of <tensorflow.python.layers.convolutional.Conv2D object at 0x7f80f9378710>> could not be transformed and will be executed as-is. Please report this to the AutgoGraph team. When filing the bug, set the verbosity to 10 (on Linux, `export AUTOGRAPH_VERBOSITY=10`) and attach the full output. Cause: converting <bound method Conv.call of <tensorflow.python.layers.convolutional.Conv2D object at 0x7f80f9378710>>: AssertionError: Bad argument number for Name: 3, expecting 4\n",
      "WARNING:tensorflow:Entity <bound method Conv.call of <tensorflow.python.layers.convolutional.Conv2D object at 0x7f80f92f7090>> could not be transformed and will be executed as-is. Please report this to the AutgoGraph team. When filing the bug, set the verbosity to 10 (on Linux, `export AUTOGRAPH_VERBOSITY=10`) and attach the full output. Cause: converting <bound method Conv.call of <tensorflow.python.layers.convolutional.Conv2D object at 0x7f80f92f7090>>: AssertionError: Bad argument number for Name: 3, expecting 4\n",
      "W0319 21:01:16.158191 140193590601472 ag_logging.py:145] Entity <bound method Conv.call of <tensorflow.python.layers.convolutional.Conv2D object at 0x7f80f92f7090>> could not be transformed and will be executed as-is. Please report this to the AutgoGraph team. When filing the bug, set the verbosity to 10 (on Linux, `export AUTOGRAPH_VERBOSITY=10`) and attach the full output. Cause: converting <bound method Conv.call of <tensorflow.python.layers.convolutional.Conv2D object at 0x7f80f92f7090>>: AssertionError: Bad argument number for Name: 3, expecting 4\n",
      "WARNING:tensorflow:Entity <bound method Conv.call of <tensorflow.python.layers.convolutional.Conv2D object at 0x7f80fa4151d0>> could not be transformed and will be executed as-is. Please report this to the AutgoGraph team. When filing the bug, set the verbosity to 10 (on Linux, `export AUTOGRAPH_VERBOSITY=10`) and attach the full output. Cause: converting <bound method Conv.call of <tensorflow.python.layers.convolutional.Conv2D object at 0x7f80fa4151d0>>: AssertionError: Bad argument number for Name: 3, expecting 4\n",
      "W0319 21:01:16.228409 140193590601472 ag_logging.py:145] Entity <bound method Conv.call of <tensorflow.python.layers.convolutional.Conv2D object at 0x7f80fa4151d0>> could not be transformed and will be executed as-is. Please report this to the AutgoGraph team. When filing the bug, set the verbosity to 10 (on Linux, `export AUTOGRAPH_VERBOSITY=10`) and attach the full output. Cause: converting <bound method Conv.call of <tensorflow.python.layers.convolutional.Conv2D object at 0x7f80fa4151d0>>: AssertionError: Bad argument number for Name: 3, expecting 4\n",
      "WARNING:tensorflow:From /opt/agazade/data_science/training/code/mobile_detection/ssd_mobilenet/ssd_mobilenet/object_detection/core/anchor_generator.py:171: The name tf.assert_equal is deprecated. Please use tf.compat.v1.assert_equal instead.\n",
      "\n",
      "W0319 21:01:16.662975 140193590601472 deprecation_wrapper.py:119] From /opt/agazade/data_science/training/code/mobile_detection/ssd_mobilenet/ssd_mobilenet/object_detection/core/anchor_generator.py:171: The name tf.assert_equal is deprecated. Please use tf.compat.v1.assert_equal instead.\n",
      "\n",
      "WARNING:tensorflow:From /opt/agazade/data_science/training/code/mobile_detection/ssd_mobilenet/ssd_mobilenet/object_detection/predictors/convolutional_box_predictor.py:150: The name tf.logging.info is deprecated. Please use tf.compat.v1.logging.info instead.\n",
      "\n",
      "W0319 21:01:16.670651 140193590601472 deprecation_wrapper.py:119] From /opt/agazade/data_science/training/code/mobile_detection/ssd_mobilenet/ssd_mobilenet/object_detection/predictors/convolutional_box_predictor.py:150: The name tf.logging.info is deprecated. Please use tf.compat.v1.logging.info instead.\n",
      "\n",
      "INFO:tensorflow:depth of additional conv before box predictor: 0\n",
      "I0319 21:01:16.670748 140193590601472 convolutional_box_predictor.py:151] depth of additional conv before box predictor: 0\n",
      "WARNING:tensorflow:Entity <bound method Conv.call of <tensorflow.python.layers.convolutional.Conv2D object at 0x7f80f8bb8210>> could not be transformed and will be executed as-is. Please report this to the AutgoGraph team. When filing the bug, set the verbosity to 10 (on Linux, `export AUTOGRAPH_VERBOSITY=10`) and attach the full output. Cause: converting <bound method Conv.call of <tensorflow.python.layers.convolutional.Conv2D object at 0x7f80f8bb8210>>: AssertionError: Bad argument number for Name: 3, expecting 4\n",
      "W0319 21:01:16.732560 140193590601472 ag_logging.py:145] Entity <bound method Conv.call of <tensorflow.python.layers.convolutional.Conv2D object at 0x7f80f8bb8210>> could not be transformed and will be executed as-is. Please report this to the AutgoGraph team. When filing the bug, set the verbosity to 10 (on Linux, `export AUTOGRAPH_VERBOSITY=10`) and attach the full output. Cause: converting <bound method Conv.call of <tensorflow.python.layers.convolutional.Conv2D object at 0x7f80f8bb8210>>: AssertionError: Bad argument number for Name: 3, expecting 4\n",
      "WARNING:tensorflow:Entity <bound method Conv.call of <tensorflow.python.layers.convolutional.Conv2D object at 0x7f80f8bd2150>> could not be transformed and will be executed as-is. Please report this to the AutgoGraph team. When filing the bug, set the verbosity to 10 (on Linux, `export AUTOGRAPH_VERBOSITY=10`) and attach the full output. Cause: converting <bound method Conv.call of <tensorflow.python.layers.convolutional.Conv2D object at 0x7f80f8bd2150>>: AssertionError: Bad argument number for Name: 3, expecting 4\n",
      "W0319 21:01:16.795808 140193590601472 ag_logging.py:145] Entity <bound method Conv.call of <tensorflow.python.layers.convolutional.Conv2D object at 0x7f80f8bd2150>> could not be transformed and will be executed as-is. Please report this to the AutgoGraph team. When filing the bug, set the verbosity to 10 (on Linux, `export AUTOGRAPH_VERBOSITY=10`) and attach the full output. Cause: converting <bound method Conv.call of <tensorflow.python.layers.convolutional.Conv2D object at 0x7f80f8bd2150>>: AssertionError: Bad argument number for Name: 3, expecting 4\n",
      "INFO:tensorflow:depth of additional conv before box predictor: 0\n",
      "I0319 21:01:16.797973 140193590601472 convolutional_box_predictor.py:151] depth of additional conv before box predictor: 0\n",
      "WARNING:tensorflow:Entity <bound method Conv.call of <tensorflow.python.layers.convolutional.Conv2D object at 0x7f80f8bb8190>> could not be transformed and will be executed as-is. Please report this to the AutgoGraph team. When filing the bug, set the verbosity to 10 (on Linux, `export AUTOGRAPH_VERBOSITY=10`) and attach the full output. Cause: converting <bound method Conv.call of <tensorflow.python.layers.convolutional.Conv2D object at 0x7f80f8bb8190>>: AssertionError: Bad argument number for Name: 3, expecting 4\n",
      "W0319 21:01:16.859578 140193590601472 ag_logging.py:145] Entity <bound method Conv.call of <tensorflow.python.layers.convolutional.Conv2D object at 0x7f80f8bb8190>> could not be transformed and will be executed as-is. Please report this to the AutgoGraph team. When filing the bug, set the verbosity to 10 (on Linux, `export AUTOGRAPH_VERBOSITY=10`) and attach the full output. Cause: converting <bound method Conv.call of <tensorflow.python.layers.convolutional.Conv2D object at 0x7f80f8bb8190>>: AssertionError: Bad argument number for Name: 3, expecting 4\n",
      "WARNING:tensorflow:Entity <bound method Conv.call of <tensorflow.python.layers.convolutional.Conv2D object at 0x7f80f8bb8190>> could not be transformed and will be executed as-is. Please report this to the AutgoGraph team. When filing the bug, set the verbosity to 10 (on Linux, `export AUTOGRAPH_VERBOSITY=10`) and attach the full output. Cause: converting <bound method Conv.call of <tensorflow.python.layers.convolutional.Conv2D object at 0x7f80f8bb8190>>: AssertionError: Bad argument number for Name: 3, expecting 4\n",
      "W0319 21:01:16.923036 140193590601472 ag_logging.py:145] Entity <bound method Conv.call of <tensorflow.python.layers.convolutional.Conv2D object at 0x7f80f8bb8190>> could not be transformed and will be executed as-is. Please report this to the AutgoGraph team. When filing the bug, set the verbosity to 10 (on Linux, `export AUTOGRAPH_VERBOSITY=10`) and attach the full output. Cause: converting <bound method Conv.call of <tensorflow.python.layers.convolutional.Conv2D object at 0x7f80f8bb8190>>: AssertionError: Bad argument number for Name: 3, expecting 4\n",
      "INFO:tensorflow:depth of additional conv before box predictor: 0\n",
      "I0319 21:01:16.925328 140193590601472 convolutional_box_predictor.py:151] depth of additional conv before box predictor: 0\n",
      "WARNING:tensorflow:Entity <bound method Conv.call of <tensorflow.python.layers.convolutional.Conv2D object at 0x7f80f8ade590>> could not be transformed and will be executed as-is. Please report this to the AutgoGraph team. When filing the bug, set the verbosity to 10 (on Linux, `export AUTOGRAPH_VERBOSITY=10`) and attach the full output. Cause: converting <bound method Conv.call of <tensorflow.python.layers.convolutional.Conv2D object at 0x7f80f8ade590>>: AssertionError: Bad argument number for Name: 3, expecting 4\n",
      "W0319 21:01:16.987158 140193590601472 ag_logging.py:145] Entity <bound method Conv.call of <tensorflow.python.layers.convolutional.Conv2D object at 0x7f80f8ade590>> could not be transformed and will be executed as-is. Please report this to the AutgoGraph team. When filing the bug, set the verbosity to 10 (on Linux, `export AUTOGRAPH_VERBOSITY=10`) and attach the full output. Cause: converting <bound method Conv.call of <tensorflow.python.layers.convolutional.Conv2D object at 0x7f80f8ade590>>: AssertionError: Bad argument number for Name: 3, expecting 4\n",
      "WARNING:tensorflow:Entity <bound method Conv.call of <tensorflow.python.layers.convolutional.Conv2D object at 0x7f80f8b1d750>> could not be transformed and will be executed as-is. Please report this to the AutgoGraph team. When filing the bug, set the verbosity to 10 (on Linux, `export AUTOGRAPH_VERBOSITY=10`) and attach the full output. Cause: converting <bound method Conv.call of <tensorflow.python.layers.convolutional.Conv2D object at 0x7f80f8b1d750>>: AssertionError: Bad argument number for Name: 3, expecting 4\n",
      "W0319 21:01:17.051415 140193590601472 ag_logging.py:145] Entity <bound method Conv.call of <tensorflow.python.layers.convolutional.Conv2D object at 0x7f80f8b1d750>> could not be transformed and will be executed as-is. Please report this to the AutgoGraph team. When filing the bug, set the verbosity to 10 (on Linux, `export AUTOGRAPH_VERBOSITY=10`) and attach the full output. Cause: converting <bound method Conv.call of <tensorflow.python.layers.convolutional.Conv2D object at 0x7f80f8b1d750>>: AssertionError: Bad argument number for Name: 3, expecting 4\n",
      "INFO:tensorflow:depth of additional conv before box predictor: 0\n",
      "I0319 21:01:17.053650 140193590601472 convolutional_box_predictor.py:151] depth of additional conv before box predictor: 0\n",
      "WARNING:tensorflow:Entity <bound method Conv.call of <tensorflow.python.layers.convolutional.Conv2D object at 0x7f80f8a204d0>> could not be transformed and will be executed as-is. Please report this to the AutgoGraph team. When filing the bug, set the verbosity to 10 (on Linux, `export AUTOGRAPH_VERBOSITY=10`) and attach the full output. Cause: converting <bound method Conv.call of <tensorflow.python.layers.convolutional.Conv2D object at 0x7f80f8a204d0>>: AssertionError: Bad argument number for Name: 3, expecting 4\n",
      "W0319 21:01:17.115365 140193590601472 ag_logging.py:145] Entity <bound method Conv.call of <tensorflow.python.layers.convolutional.Conv2D object at 0x7f80f8a204d0>> could not be transformed and will be executed as-is. Please report this to the AutgoGraph team. When filing the bug, set the verbosity to 10 (on Linux, `export AUTOGRAPH_VERBOSITY=10`) and attach the full output. Cause: converting <bound method Conv.call of <tensorflow.python.layers.convolutional.Conv2D object at 0x7f80f8a204d0>>: AssertionError: Bad argument number for Name: 3, expecting 4\n",
      "WARNING:tensorflow:Entity <bound method Conv.call of <tensorflow.python.layers.convolutional.Conv2D object at 0x7f80f8a4f850>> could not be transformed and will be executed as-is. Please report this to the AutgoGraph team. When filing the bug, set the verbosity to 10 (on Linux, `export AUTOGRAPH_VERBOSITY=10`) and attach the full output. Cause: converting <bound method Conv.call of <tensorflow.python.layers.convolutional.Conv2D object at 0x7f80f8a4f850>>: AssertionError: Bad argument number for Name: 3, expecting 4\n",
      "W0319 21:01:17.178952 140193590601472 ag_logging.py:145] Entity <bound method Conv.call of <tensorflow.python.layers.convolutional.Conv2D object at 0x7f80f8a4f850>> could not be transformed and will be executed as-is. Please report this to the AutgoGraph team. When filing the bug, set the verbosity to 10 (on Linux, `export AUTOGRAPH_VERBOSITY=10`) and attach the full output. Cause: converting <bound method Conv.call of <tensorflow.python.layers.convolutional.Conv2D object at 0x7f80f8a4f850>>: AssertionError: Bad argument number for Name: 3, expecting 4\n",
      "INFO:tensorflow:depth of additional conv before box predictor: 0\n",
      "I0319 21:01:17.181273 140193590601472 convolutional_box_predictor.py:151] depth of additional conv before box predictor: 0\n",
      "WARNING:tensorflow:Entity <bound method Conv.call of <tensorflow.python.layers.convolutional.Conv2D object at 0x7f80f8894710>> could not be transformed and will be executed as-is. Please report this to the AutgoGraph team. When filing the bug, set the verbosity to 10 (on Linux, `export AUTOGRAPH_VERBOSITY=10`) and attach the full output. Cause: converting <bound method Conv.call of <tensorflow.python.layers.convolutional.Conv2D object at 0x7f80f8894710>>: AssertionError: Bad argument number for Name: 3, expecting 4\n",
      "W0319 21:01:17.242339 140193590601472 ag_logging.py:145] Entity <bound method Conv.call of <tensorflow.python.layers.convolutional.Conv2D object at 0x7f80f8894710>> could not be transformed and will be executed as-is. Please report this to the AutgoGraph team. When filing the bug, set the verbosity to 10 (on Linux, `export AUTOGRAPH_VERBOSITY=10`) and attach the full output. Cause: converting <bound method Conv.call of <tensorflow.python.layers.convolutional.Conv2D object at 0x7f80f8894710>>: AssertionError: Bad argument number for Name: 3, expecting 4\n",
      "WARNING:tensorflow:Entity <bound method Conv.call of <tensorflow.python.layers.convolutional.Conv2D object at 0x7f80f9fc7750>> could not be transformed and will be executed as-is. Please report this to the AutgoGraph team. When filing the bug, set the verbosity to 10 (on Linux, `export AUTOGRAPH_VERBOSITY=10`) and attach the full output. Cause: converting <bound method Conv.call of <tensorflow.python.layers.convolutional.Conv2D object at 0x7f80f9fc7750>>: AssertionError: Bad argument number for Name: 3, expecting 4\n",
      "W0319 21:01:17.305683 140193590601472 ag_logging.py:145] Entity <bound method Conv.call of <tensorflow.python.layers.convolutional.Conv2D object at 0x7f80f9fc7750>> could not be transformed and will be executed as-is. Please report this to the AutgoGraph team. When filing the bug, set the verbosity to 10 (on Linux, `export AUTOGRAPH_VERBOSITY=10`) and attach the full output. Cause: converting <bound method Conv.call of <tensorflow.python.layers.convolutional.Conv2D object at 0x7f80f9fc7750>>: AssertionError: Bad argument number for Name: 3, expecting 4\n",
      "INFO:tensorflow:depth of additional conv before box predictor: 0\n",
      "I0319 21:01:17.307899 140193590601472 convolutional_box_predictor.py:151] depth of additional conv before box predictor: 0\n",
      "WARNING:tensorflow:Entity <bound method Conv.call of <tensorflow.python.layers.convolutional.Conv2D object at 0x7f80f8894850>> could not be transformed and will be executed as-is. Please report this to the AutgoGraph team. When filing the bug, set the verbosity to 10 (on Linux, `export AUTOGRAPH_VERBOSITY=10`) and attach the full output. Cause: converting <bound method Conv.call of <tensorflow.python.layers.convolutional.Conv2D object at 0x7f80f8894850>>: AssertionError: Bad argument number for Name: 3, expecting 4\n",
      "W0319 21:01:17.368810 140193590601472 ag_logging.py:145] Entity <bound method Conv.call of <tensorflow.python.layers.convolutional.Conv2D object at 0x7f80f8894850>> could not be transformed and will be executed as-is. Please report this to the AutgoGraph team. When filing the bug, set the verbosity to 10 (on Linux, `export AUTOGRAPH_VERBOSITY=10`) and attach the full output. Cause: converting <bound method Conv.call of <tensorflow.python.layers.convolutional.Conv2D object at 0x7f80f8894850>>: AssertionError: Bad argument number for Name: 3, expecting 4\n",
      "WARNING:tensorflow:Entity <bound method Conv.call of <tensorflow.python.layers.convolutional.Conv2D object at 0x7f80f87f5110>> could not be transformed and will be executed as-is. Please report this to the AutgoGraph team. When filing the bug, set the verbosity to 10 (on Linux, `export AUTOGRAPH_VERBOSITY=10`) and attach the full output. Cause: converting <bound method Conv.call of <tensorflow.python.layers.convolutional.Conv2D object at 0x7f80f87f5110>>: AssertionError: Bad argument number for Name: 3, expecting 4\n",
      "W0319 21:01:17.432182 140193590601472 ag_logging.py:145] Entity <bound method Conv.call of <tensorflow.python.layers.convolutional.Conv2D object at 0x7f80f87f5110>> could not be transformed and will be executed as-is. Please report this to the AutgoGraph team. When filing the bug, set the verbosity to 10 (on Linux, `export AUTOGRAPH_VERBOSITY=10`) and attach the full output. Cause: converting <bound method Conv.call of <tensorflow.python.layers.convolutional.Conv2D object at 0x7f80f87f5110>>: AssertionError: Bad argument number for Name: 3, expecting 4\n",
      "WARNING:tensorflow:From /opt/agazade/data_science/training/code/mobile_detection/ssd_mobilenet/ssd_mobilenet/object_detection/export_tflite_ssd_graph_lib.py:52: The name tf.Session is deprecated. Please use tf.compat.v1.Session instead.\n",
      "\n",
      "W0319 21:01:17.442658 140193590601472 deprecation_wrapper.py:119] From /opt/agazade/data_science/training/code/mobile_detection/ssd_mobilenet/ssd_mobilenet/object_detection/export_tflite_ssd_graph_lib.py:52: The name tf.Session is deprecated. Please use tf.compat.v1.Session instead.\n",
      "\n",
      "2020-03-19 21:01:17.443464: I tensorflow/stream_executor/platform/default/dso_loader.cc:42] Successfully opened dynamic library libcuda.so.1\n",
      "2020-03-19 21:01:17.733302: E tensorflow/stream_executor/cuda/cuda_driver.cc:318] failed call to cuInit: CUDA_ERROR_NO_DEVICE: no CUDA-capable device is detected\n",
      "2020-03-19 21:01:17.733343: I tensorflow/stream_executor/cuda/cuda_diagnostics.cc:169] retrieving CUDA diagnostic information for host: g001.metahouse.ru\n",
      "2020-03-19 21:01:17.733351: I tensorflow/stream_executor/cuda/cuda_diagnostics.cc:176] hostname: g001.metahouse.ru\n",
      "2020-03-19 21:01:17.733441: I tensorflow/stream_executor/cuda/cuda_diagnostics.cc:200] libcuda reported version is: 418.87.1\n",
      "2020-03-19 21:01:17.733463: I tensorflow/stream_executor/cuda/cuda_diagnostics.cc:204] kernel reported version is: 418.87.1\n",
      "2020-03-19 21:01:17.733469: I tensorflow/stream_executor/cuda/cuda_diagnostics.cc:310] kernel version seems to match DSO: 418.87.1\n",
      "2020-03-19 21:01:17.733654: I tensorflow/core/platform/cpu_feature_guard.cc:142] Your CPU supports instructions that this TensorFlow binary was not compiled to use: SSE4.1 SSE4.2 AVX AVX2 FMA\n",
      "2020-03-19 21:01:17.760680: I tensorflow/core/platform/profile_utils/cpu_utils.cc:94] CPU Frequency: 3600000000 Hz\n",
      "2020-03-19 21:01:17.761152: I tensorflow/compiler/xla/service/service.cc:168] XLA service 0x5576de49be20 executing computations on platform Host. Devices:\n",
      "2020-03-19 21:01:17.761172: I tensorflow/compiler/xla/service/service.cc:175]   StreamExecutor device (0): <undefined>, <undefined>\n",
      "2020-03-19 21:01:17.868016: W tensorflow/compiler/jit/mark_for_compilation_pass.cc:1412] (One-time warning): Not using XLA:CPU for cluster because envvar TF_XLA_FLAGS=--tf_xla_cpu_global_jit was not set.  If you want XLA:CPU, either set that envvar, or use experimental_jit_scope to enable XLA:CPU.  To confirm that XLA is active, pass --vmodule=xla_compilation_cache=1 (as a proper command-line flag, not via TF_XLA_FLAGS) or set the envvar XLA_FLAGS=--xla_hlo_profile.\n",
      "WARNING:tensorflow:From /opt/agazade/data_science/training/code/mobile_detection/ssd_mobilenet/ssd_mobilenet/object_detection/export_tflite_ssd_graph_lib.py:269: The name tf.train.get_or_create_global_step is deprecated. Please use tf.compat.v1.train.get_or_create_global_step instead.\n",
      "\n",
      "W0319 21:01:17.878837 140193590601472 deprecation_wrapper.py:119] From /opt/agazade/data_science/training/code/mobile_detection/ssd_mobilenet/ssd_mobilenet/object_detection/export_tflite_ssd_graph_lib.py:269: The name tf.train.get_or_create_global_step is deprecated. Please use tf.compat.v1.train.get_or_create_global_step instead.\n",
      "\n",
      "WARNING:tensorflow:From /opt/agazade/data_science/training/code/mobile_detection/ssd_mobilenet/ssd_mobilenet/object_detection/export_tflite_ssd_graph_lib.py:294: The name tf.train.Saver is deprecated. Please use tf.compat.v1.train.Saver instead.\n",
      "\n",
      "W0319 21:01:17.881118 140193590601472 deprecation_wrapper.py:119] From /opt/agazade/data_science/training/code/mobile_detection/ssd_mobilenet/ssd_mobilenet/object_detection/export_tflite_ssd_graph_lib.py:294: The name tf.train.Saver is deprecated. Please use tf.compat.v1.train.Saver instead.\n",
      "\n",
      "WARNING:tensorflow:From /opt/agazade/data_science/training/code/mobile_detection/ssd_mobilenet/ssd_mobilenet/object_detection/export_tflite_ssd_graph_lib.py:297: The name tf.get_default_graph is deprecated. Please use tf.compat.v1.get_default_graph instead.\n",
      "\n",
      "W0319 21:01:18.082657 140193590601472 deprecation_wrapper.py:119] From /opt/agazade/data_science/training/code/mobile_detection/ssd_mobilenet/ssd_mobilenet/object_detection/export_tflite_ssd_graph_lib.py:297: The name tf.get_default_graph is deprecated. Please use tf.compat.v1.get_default_graph instead.\n",
      "\n",
      "WARNING:tensorflow:From /home/agazade/.conda/envs/main/lib/python3.7/site-packages/tensorflow/python/tools/freeze_graph.py:127: checkpoint_exists (from tensorflow.python.training.checkpoint_management) is deprecated and will be removed in a future version.\n",
      "Instructions for updating:\n",
      "Use standard file APIs to check for files with this prefix.\n",
      "W0319 21:01:18.105132 140193590601472 deprecation.py:323] From /home/agazade/.conda/envs/main/lib/python3.7/site-packages/tensorflow/python/tools/freeze_graph.py:127: checkpoint_exists (from tensorflow.python.training.checkpoint_management) is deprecated and will be removed in a future version.\n",
      "Instructions for updating:\n",
      "Use standard file APIs to check for files with this prefix.\n",
      "INFO:tensorflow:Restoring parameters from /srv/data_science/training/checkpoints/mobile_detection/model3/pretrain_model1/model.ckpt-399296\n",
      "I0319 21:01:18.562147 140193590601472 saver.py:1280] Restoring parameters from /srv/data_science/training/checkpoints/mobile_detection/model3/pretrain_model1/model.ckpt-399296\n",
      "WARNING:tensorflow:From /home/agazade/.conda/envs/main/lib/python3.7/site-packages/tensorflow/python/tools/freeze_graph.py:233: convert_variables_to_constants (from tensorflow.python.framework.graph_util_impl) is deprecated and will be removed in a future version.\n",
      "Instructions for updating:\n",
      "Use `tf.compat.v1.graph_util.convert_variables_to_constants`\n",
      "W0319 21:01:19.030605 140193590601472 deprecation.py:323] From /home/agazade/.conda/envs/main/lib/python3.7/site-packages/tensorflow/python/tools/freeze_graph.py:233: convert_variables_to_constants (from tensorflow.python.framework.graph_util_impl) is deprecated and will be removed in a future version.\n",
      "Instructions for updating:\n",
      "Use `tf.compat.v1.graph_util.convert_variables_to_constants`\n",
      "WARNING:tensorflow:From /home/agazade/.conda/envs/main/lib/python3.7/site-packages/tensorflow/python/framework/graph_util_impl.py:270: extract_sub_graph (from tensorflow.python.framework.graph_util_impl) is deprecated and will be removed in a future version.\n",
      "Instructions for updating:\n",
      "Use `tf.compat.v1.graph_util.extract_sub_graph`\n",
      "W0319 21:01:19.030744 140193590601472 deprecation.py:323] From /home/agazade/.conda/envs/main/lib/python3.7/site-packages/tensorflow/python/framework/graph_util_impl.py:270: extract_sub_graph (from tensorflow.python.framework.graph_util_impl) is deprecated and will be removed in a future version.\n",
      "Instructions for updating:\n",
      "Use `tf.compat.v1.graph_util.extract_sub_graph`\n",
      "INFO:tensorflow:Froze 406 variables.\n",
      "I0319 21:01:19.247205 140193590601472 graph_util_impl.py:311] Froze 406 variables.\n",
      "INFO:tensorflow:Converted 406 variables to const ops.\n",
      "I0319 21:01:19.282947 140193590601472 graph_util_impl.py:364] Converted 406 variables to const ops.\n",
      "2020-03-19 21:01:19.331889: I tensorflow/tools/graph_transforms/transform_graph.cc:317] Applying strip_unused_nodes\n"
     ]
    }
   ],
   "source": [
    "!python ssd_mobilenet/object_detection/export_tflite_ssd_graph.py --pipeline_config_path $config --trained_checkpoint_prefix $trained_checkpoint --output_directory $output_directory --nooptimize"
   ]
  },
  {
   "cell_type": "code",
   "execution_count": null,
   "metadata": {},
   "outputs": [],
   "source": [
    "!python ssd_mobilenet/object_detection/export_tflite_ssd_graph.py --helpfull"
   ]
  },
  {
   "cell_type": "code",
   "execution_count": 8,
   "metadata": {},
   "outputs": [],
   "source": [
    "# mobilenet_saved_model = str(model_dir_p / 'inf_graph179874.pb/saved_model.pb')\n",
    "mobilenet_saved_model = str(model_dir_p / 'inf_graph.pb/saved_model.pb')\n",
    "# mobilenet_saved_model = str(model_dir_p / 'inf_graph_noopt.pb/saved_model.pb')\n",
    "output_file = str(model_dir_p / 'tag_detector_optimized.tflite')\n",
    "# output_file = str(model_dir_p / 'tag_detector_quantized.tflite')\n",
    "\n",
    "input_shapes=\"1,320,320,3\"\n",
    "output_arrays = \"TFLite_Detection_PostProcess,TFLite_Detection_PostProcess:1,TFLite_Detection_PostProcess:2,TFLite_Detection_PostProcess:3\"\n",
    "input_arrays = \"normalized_input_image_tensor\"\n",
    "inference_type = 'FLOAT'\n",
    "# inference_type = 'QUANTIZED_UINT8'\n",
    "# std_dev, mean = 128, 128"
   ]
  },
  {
   "cell_type": "code",
   "execution_count": 10,
   "metadata": {},
   "outputs": [
    {
     "name": "stdout",
     "output_type": "stream",
     "text": [
      "/home/agazade/.conda/envs/main/lib/python3.7/site-packages/tensorflow/python/framework/dtypes.py:516: FutureWarning: Passing (type, 1) or '1type' as a synonym of type is deprecated; in a future version of numpy, it will be understood as (type, (1,)) / '(1,)type'.\n",
      "  _np_qint8 = np.dtype([(\"qint8\", np.int8, 1)])\n",
      "/home/agazade/.conda/envs/main/lib/python3.7/site-packages/tensorflow/python/framework/dtypes.py:517: FutureWarning: Passing (type, 1) or '1type' as a synonym of type is deprecated; in a future version of numpy, it will be understood as (type, (1,)) / '(1,)type'.\n",
      "  _np_quint8 = np.dtype([(\"quint8\", np.uint8, 1)])\n",
      "/home/agazade/.conda/envs/main/lib/python3.7/site-packages/tensorflow/python/framework/dtypes.py:518: FutureWarning: Passing (type, 1) or '1type' as a synonym of type is deprecated; in a future version of numpy, it will be understood as (type, (1,)) / '(1,)type'.\n",
      "  _np_qint16 = np.dtype([(\"qint16\", np.int16, 1)])\n",
      "/home/agazade/.conda/envs/main/lib/python3.7/site-packages/tensorflow/python/framework/dtypes.py:519: FutureWarning: Passing (type, 1) or '1type' as a synonym of type is deprecated; in a future version of numpy, it will be understood as (type, (1,)) / '(1,)type'.\n",
      "  _np_quint16 = np.dtype([(\"quint16\", np.uint16, 1)])\n",
      "/home/agazade/.conda/envs/main/lib/python3.7/site-packages/tensorflow/python/framework/dtypes.py:520: FutureWarning: Passing (type, 1) or '1type' as a synonym of type is deprecated; in a future version of numpy, it will be understood as (type, (1,)) / '(1,)type'.\n",
      "  _np_qint32 = np.dtype([(\"qint32\", np.int32, 1)])\n",
      "/home/agazade/.conda/envs/main/lib/python3.7/site-packages/tensorflow/python/framework/dtypes.py:525: FutureWarning: Passing (type, 1) or '1type' as a synonym of type is deprecated; in a future version of numpy, it will be understood as (type, (1,)) / '(1,)type'.\n",
      "  np_resource = np.dtype([(\"resource\", np.ubyte, 1)])\n",
      "/home/agazade/.conda/envs/main/lib/python3.7/site-packages/tensorboard/compat/tensorflow_stub/dtypes.py:541: FutureWarning: Passing (type, 1) or '1type' as a synonym of type is deprecated; in a future version of numpy, it will be understood as (type, (1,)) / '(1,)type'.\n",
      "  _np_qint8 = np.dtype([(\"qint8\", np.int8, 1)])\n",
      "/home/agazade/.conda/envs/main/lib/python3.7/site-packages/tensorboard/compat/tensorflow_stub/dtypes.py:542: FutureWarning: Passing (type, 1) or '1type' as a synonym of type is deprecated; in a future version of numpy, it will be understood as (type, (1,)) / '(1,)type'.\n",
      "  _np_quint8 = np.dtype([(\"quint8\", np.uint8, 1)])\n",
      "/home/agazade/.conda/envs/main/lib/python3.7/site-packages/tensorboard/compat/tensorflow_stub/dtypes.py:543: FutureWarning: Passing (type, 1) or '1type' as a synonym of type is deprecated; in a future version of numpy, it will be understood as (type, (1,)) / '(1,)type'.\n",
      "  _np_qint16 = np.dtype([(\"qint16\", np.int16, 1)])\n",
      "/home/agazade/.conda/envs/main/lib/python3.7/site-packages/tensorboard/compat/tensorflow_stub/dtypes.py:544: FutureWarning: Passing (type, 1) or '1type' as a synonym of type is deprecated; in a future version of numpy, it will be understood as (type, (1,)) / '(1,)type'.\n",
      "  _np_quint16 = np.dtype([(\"quint16\", np.uint16, 1)])\n",
      "/home/agazade/.conda/envs/main/lib/python3.7/site-packages/tensorboard/compat/tensorflow_stub/dtypes.py:545: FutureWarning: Passing (type, 1) or '1type' as a synonym of type is deprecated; in a future version of numpy, it will be understood as (type, (1,)) / '(1,)type'.\n",
      "  _np_qint32 = np.dtype([(\"qint32\", np.int32, 1)])\n",
      "/home/agazade/.conda/envs/main/lib/python3.7/site-packages/tensorboard/compat/tensorflow_stub/dtypes.py:550: FutureWarning: Passing (type, 1) or '1type' as a synonym of type is deprecated; in a future version of numpy, it will be understood as (type, (1,)) / '(1,)type'.\n",
      "  np_resource = np.dtype([(\"resource\", np.ubyte, 1)])\n",
      "2020-03-19 21:02:41.214347: I tensorflow/stream_executor/platform/default/dso_loader.cc:42] Successfully opened dynamic library libcuda.so.1\n",
      "2020-03-19 21:02:41.500566: E tensorflow/stream_executor/cuda/cuda_driver.cc:318] failed call to cuInit: CUDA_ERROR_NO_DEVICE: no CUDA-capable device is detected\n",
      "2020-03-19 21:02:41.500602: I tensorflow/stream_executor/cuda/cuda_diagnostics.cc:169] retrieving CUDA diagnostic information for host: g001.metahouse.ru\n",
      "2020-03-19 21:02:41.500610: I tensorflow/stream_executor/cuda/cuda_diagnostics.cc:176] hostname: g001.metahouse.ru\n",
      "2020-03-19 21:02:41.500681: I tensorflow/stream_executor/cuda/cuda_diagnostics.cc:200] libcuda reported version is: 418.87.1\n",
      "2020-03-19 21:02:41.500719: I tensorflow/stream_executor/cuda/cuda_diagnostics.cc:204] kernel reported version is: 418.87.1\n",
      "2020-03-19 21:02:41.500726: I tensorflow/stream_executor/cuda/cuda_diagnostics.cc:310] kernel version seems to match DSO: 418.87.1\n",
      "2020-03-19 21:02:41.500933: I tensorflow/core/platform/cpu_feature_guard.cc:142] Your CPU supports instructions that this TensorFlow binary was not compiled to use: SSE4.1 SSE4.2 AVX AVX2 FMA\n",
      "2020-03-19 21:02:41.524853: I tensorflow/core/platform/profile_utils/cpu_utils.cc:94] CPU Frequency: 3600000000 Hz\n",
      "2020-03-19 21:02:41.525398: I tensorflow/compiler/xla/service/service.cc:168] XLA service 0x555da5779ab0 executing computations on platform Host. Devices:\n",
      "2020-03-19 21:02:41.525440: I tensorflow/compiler/xla/service/service.cc:175]   StreamExecutor device (0): <undefined>, <undefined>\n"
     ]
    }
   ],
   "source": [
    "!tflite_convert --graph_def_file=$mobilenet_saved_model --output_file=$output_file --input_arrays=$input_arrays --output_arrays=$output_arrays --input_shapes=$input_shapes --allow_custom_ops --inference_type $inference_type"
   ]
  },
  {
   "cell_type": "code",
   "execution_count": 13,
   "metadata": {},
   "outputs": [
    {
     "name": "stdout",
     "output_type": "stream",
     "text": [
      "/home/agazade/.conda/envs/main/lib/python3.7/site-packages/tensorflow/python/framework/dtypes.py:516: FutureWarning: Passing (type, 1) or '1type' as a synonym of type is deprecated; in a future version of numpy, it will be understood as (type, (1,)) / '(1,)type'.\n",
      "  _np_qint8 = np.dtype([(\"qint8\", np.int8, 1)])\n",
      "/home/agazade/.conda/envs/main/lib/python3.7/site-packages/tensorflow/python/framework/dtypes.py:517: FutureWarning: Passing (type, 1) or '1type' as a synonym of type is deprecated; in a future version of numpy, it will be understood as (type, (1,)) / '(1,)type'.\n",
      "  _np_quint8 = np.dtype([(\"quint8\", np.uint8, 1)])\n",
      "/home/agazade/.conda/envs/main/lib/python3.7/site-packages/tensorflow/python/framework/dtypes.py:518: FutureWarning: Passing (type, 1) or '1type' as a synonym of type is deprecated; in a future version of numpy, it will be understood as (type, (1,)) / '(1,)type'.\n",
      "  _np_qint16 = np.dtype([(\"qint16\", np.int16, 1)])\n",
      "/home/agazade/.conda/envs/main/lib/python3.7/site-packages/tensorflow/python/framework/dtypes.py:519: FutureWarning: Passing (type, 1) or '1type' as a synonym of type is deprecated; in a future version of numpy, it will be understood as (type, (1,)) / '(1,)type'.\n",
      "  _np_quint16 = np.dtype([(\"quint16\", np.uint16, 1)])\n",
      "/home/agazade/.conda/envs/main/lib/python3.7/site-packages/tensorflow/python/framework/dtypes.py:520: FutureWarning: Passing (type, 1) or '1type' as a synonym of type is deprecated; in a future version of numpy, it will be understood as (type, (1,)) / '(1,)type'.\n",
      "  _np_qint32 = np.dtype([(\"qint32\", np.int32, 1)])\n",
      "/home/agazade/.conda/envs/main/lib/python3.7/site-packages/tensorflow/python/framework/dtypes.py:525: FutureWarning: Passing (type, 1) or '1type' as a synonym of type is deprecated; in a future version of numpy, it will be understood as (type, (1,)) / '(1,)type'.\n",
      "  np_resource = np.dtype([(\"resource\", np.ubyte, 1)])\n",
      "/home/agazade/.conda/envs/main/lib/python3.7/site-packages/tensorboard/compat/tensorflow_stub/dtypes.py:541: FutureWarning: Passing (type, 1) or '1type' as a synonym of type is deprecated; in a future version of numpy, it will be understood as (type, (1,)) / '(1,)type'.\n",
      "  _np_qint8 = np.dtype([(\"qint8\", np.int8, 1)])\n",
      "/home/agazade/.conda/envs/main/lib/python3.7/site-packages/tensorboard/compat/tensorflow_stub/dtypes.py:542: FutureWarning: Passing (type, 1) or '1type' as a synonym of type is deprecated; in a future version of numpy, it will be understood as (type, (1,)) / '(1,)type'.\n",
      "  _np_quint8 = np.dtype([(\"quint8\", np.uint8, 1)])\n",
      "/home/agazade/.conda/envs/main/lib/python3.7/site-packages/tensorboard/compat/tensorflow_stub/dtypes.py:543: FutureWarning: Passing (type, 1) or '1type' as a synonym of type is deprecated; in a future version of numpy, it will be understood as (type, (1,)) / '(1,)type'.\n",
      "  _np_qint16 = np.dtype([(\"qint16\", np.int16, 1)])\n",
      "/home/agazade/.conda/envs/main/lib/python3.7/site-packages/tensorboard/compat/tensorflow_stub/dtypes.py:544: FutureWarning: Passing (type, 1) or '1type' as a synonym of type is deprecated; in a future version of numpy, it will be understood as (type, (1,)) / '(1,)type'.\n",
      "  _np_quint16 = np.dtype([(\"quint16\", np.uint16, 1)])\n",
      "/home/agazade/.conda/envs/main/lib/python3.7/site-packages/tensorboard/compat/tensorflow_stub/dtypes.py:545: FutureWarning: Passing (type, 1) or '1type' as a synonym of type is deprecated; in a future version of numpy, it will be understood as (type, (1,)) / '(1,)type'.\n",
      "  _np_qint32 = np.dtype([(\"qint32\", np.int32, 1)])\n",
      "/home/agazade/.conda/envs/main/lib/python3.7/site-packages/tensorboard/compat/tensorflow_stub/dtypes.py:550: FutureWarning: Passing (type, 1) or '1type' as a synonym of type is deprecated; in a future version of numpy, it will be understood as (type, (1,)) / '(1,)type'.\n",
      "  np_resource = np.dtype([(\"resource\", np.ubyte, 1)])\n",
      "usage: tflite_convert [-h] --output_file OUTPUT_FILE\n",
      "                      (--graph_def_file GRAPH_DEF_FILE | --saved_model_dir SAVED_MODEL_DIR | --keras_model_file KERAS_MODEL_FILE)\n",
      "                      [--output_format {TFLITE,GRAPHVIZ_DOT}]\n",
      "                      [--inference_type {FLOAT,QUANTIZED_UINT8}]\n",
      "                      [--inference_input_type {FLOAT,QUANTIZED_UINT8}]\n",
      "                      [--input_arrays INPUT_ARRAYS]\n",
      "                      [--input_shapes INPUT_SHAPES]\n",
      "                      [--output_arrays OUTPUT_ARRAYS]\n",
      "                      [--saved_model_tag_set SAVED_MODEL_TAG_SET]\n",
      "                      [--saved_model_signature_key SAVED_MODEL_SIGNATURE_KEY]\n",
      "                      [--std_dev_values STD_DEV_VALUES]\n",
      "                      [--mean_values MEAN_VALUES]\n",
      "                      [--default_ranges_min DEFAULT_RANGES_MIN]\n",
      "                      [--default_ranges_max DEFAULT_RANGES_MAX]\n",
      "                      [--post_training_quantize] [--drop_control_dependency]\n",
      "                      [--reorder_across_fake_quant]\n",
      "                      [--change_concat_input_ranges {TRUE,FALSE}]\n",
      "                      [--allow_custom_ops] [--target_ops TARGET_OPS]\n",
      "                      [--dump_graphviz_dir DUMP_GRAPHVIZ_DIR]\n",
      "                      [--dump_graphviz_video]\n",
      "\n",
      "Command line tool to run TensorFlow Lite Converter.\n",
      "\n",
      "optional arguments:\n",
      "  -h, --help            show this help message and exit\n",
      "  --output_file OUTPUT_FILE\n",
      "                        Full filepath of the output file.\n",
      "  --graph_def_file GRAPH_DEF_FILE\n",
      "                        Full filepath of file containing frozen TensorFlow\n",
      "                        GraphDef.\n",
      "  --saved_model_dir SAVED_MODEL_DIR\n",
      "                        Full filepath of directory containing the SavedModel.\n",
      "  --keras_model_file KERAS_MODEL_FILE\n",
      "                        Full filepath of HDF5 file containing tf.Keras model.\n",
      "  --output_format {TFLITE,GRAPHVIZ_DOT}\n",
      "                        Output file format.\n",
      "  --inference_type {FLOAT,QUANTIZED_UINT8}\n",
      "                        Target data type of real-number arrays in the output\n",
      "                        file.\n",
      "  --inference_input_type {FLOAT,QUANTIZED_UINT8}\n",
      "                        Target data type of real-number input arrays. Allows\n",
      "                        for a different type for input arrays in the case of\n",
      "                        quantization.\n",
      "  --input_arrays INPUT_ARRAYS\n",
      "                        Names of the input arrays, comma-separated.\n",
      "  --input_shapes INPUT_SHAPES\n",
      "                        Shapes corresponding to --input_arrays, colon-\n",
      "                        separated.\n",
      "  --output_arrays OUTPUT_ARRAYS\n",
      "                        Names of the output arrays, comma-separated.\n",
      "  --saved_model_tag_set SAVED_MODEL_TAG_SET\n",
      "                        Comma-separated set of tags identifying the\n",
      "                        MetaGraphDef within the SavedModel to analyze. All\n",
      "                        tags must be present. In order to pass in an empty tag\n",
      "                        set, pass in \"\". (default \"serve\")\n",
      "  --saved_model_signature_key SAVED_MODEL_SIGNATURE_KEY\n",
      "                        Key identifying the SignatureDef containing inputs and\n",
      "                        outputs. (default DEFAULT_SERVING_SIGNATURE_DEF_KEY)\n",
      "  --std_dev_values STD_DEV_VALUES\n",
      "                        Standard deviation of training data for each input\n",
      "                        tensor, comma-separated floats. Used for quantized\n",
      "                        input tensors. (default None)\n",
      "  --mean_values MEAN_VALUES\n",
      "                        Mean of training data for each input tensor, comma-\n",
      "                        separated floats. Used for quantized input tensors.\n",
      "                        (default None)\n",
      "  --default_ranges_min DEFAULT_RANGES_MIN\n",
      "                        Default value for min bound of min/max range values\n",
      "                        used for all arrays without a specified range,\n",
      "                        Intended for experimenting with quantization via\n",
      "                        \"dummy quantization\". (default None)\n",
      "  --default_ranges_max DEFAULT_RANGES_MAX\n",
      "                        Default value for max bound of min/max range values\n",
      "                        used for all arrays without a specified range,\n",
      "                        Intended for experimenting with quantization via\n",
      "                        \"dummy quantization\". (default None)\n",
      "  --post_training_quantize\n",
      "                        Boolean indicating whether to quantize the weights of\n",
      "                        the converted float model. Model size will be reduced\n",
      "                        and there will be latency improvements (at the cost of\n",
      "                        accuracy). (default False)\n",
      "  --drop_control_dependency\n",
      "                        Boolean indicating whether to drop control\n",
      "                        dependencies silently. This is due to TensorFlow not\n",
      "                        supporting control dependencies. (default True)\n",
      "  --reorder_across_fake_quant\n",
      "                        Boolean indicating whether to reorder FakeQuant nodes\n",
      "                        in unexpected locations. Used when the location of the\n",
      "                        FakeQuant nodes is preventing graph transformations\n",
      "                        necessary to convert the graph. Results in a graph\n",
      "                        that differs from the quantized training graph,\n",
      "                        potentially causing differing arithmetic behavior.\n",
      "                        (default False)\n",
      "  --change_concat_input_ranges {TRUE,FALSE}\n",
      "                        Boolean to change behavior of min/max ranges for\n",
      "                        inputs and outputs of the concat operator for\n",
      "                        quantized models. Changes the ranges of concat\n",
      "                        operator overlap when true. (default False)\n",
      "  --allow_custom_ops    Boolean indicating whether to allow custom operations.\n",
      "                        When false any unknown operation is an error. When\n",
      "                        true, custom ops are created for any op that is\n",
      "                        unknown. The developer will need to provide these to\n",
      "                        the TensorFlow Lite runtime with a custom resolver.\n",
      "                        (default False)\n",
      "  --target_ops TARGET_OPS\n",
      "                        Experimental flag, subject to change. Set of OpsSet\n",
      "                        options indicating which converter to use. Options:\n",
      "                        TFLITE_BUILTINS,SELECT_TF_OPS,TFLITE_BUILTINS_INT8.\n",
      "                        One or more option may be specified. (default\n",
      "                        set([OpsSet.TFLITE_BUILTINS]))\n",
      "  --dump_graphviz_dir DUMP_GRAPHVIZ_DIR\n",
      "                        Full filepath of folder to dump the graphs at various\n",
      "                        stages of processing GraphViz .dot files. Preferred\n",
      "                        over --output_format=GRAPHVIZ_DOT in order to keep the\n",
      "                        requirements of the output file.\n",
      "  --dump_graphviz_video\n",
      "                        Boolean indicating whether to dump the graph after\n",
      "                        every graph transformation\n"
     ]
    }
   ],
   "source": [
    "!tflite_convert --help"
   ]
  },
  {
   "cell_type": "code",
   "execution_count": null,
   "metadata": {},
   "outputs": [],
   "source": []
  }
 ],
 "metadata": {
  "kernelspec": {
   "display_name": "Python 3",
   "language": "python",
   "name": "python3"
  },
  "language_info": {
   "codemirror_mode": {
    "name": "ipython",
    "version": 3
   },
   "file_extension": ".py",
   "mimetype": "text/x-python",
   "name": "python",
   "nbconvert_exporter": "python",
   "pygments_lexer": "ipython3",
   "version": "3.7.6"
  }
 },
 "nbformat": 4,
 "nbformat_minor": 4
}
